Workbook
Name 급식국: 급식_국!$C$2:$C$38
Name 급식밥: 급식_밥!$C$2:$C$13
Name 김치: 급식_반찬!$C$27:$C$28
Name 반찬1: 온라인_반찬!$C$122:$C$279
Name 반찬2: 온라인_반찬!$C$280:$C$376
Name 반찬3: 온라인_반찬!$C$361:$C$409
Name 반찬4: 온라인_반찬!$C$328:$C$473
Name 온라인국: 온라인_반찬!$C$2:$C$87

Sheet 식단표 (알레르기표기) (2)
A2: 요일 | B2: 월 | D2: 화 | F2: 수 | H2: 목 | J2: 금
A3: 날짜 | P3: 레몬크림탕수육
A4: 주차 | B4: 메뉴 | C4: 알레르기표기 | D4: 메뉴 | E4: 알레르기표기 | F4: 메뉴 | G4: 알레르기표기 | H4: 메뉴 | I4: 알레르기표기 | J4: 메뉴 | K4: 알레르기표기 | L4: 메뉴 | M4: 알레르기표기 | P4: 칠리탕수육
A5: 1주 | C5: =IFERROR(INDEX(온라인_반찬!$C$2:$I$587,MATCH($B5,온라인_반찬!$C$2:$C$587,0),7),"") | E5: =IFERROR(INDEX(온라인_반찬!$C$2:$I$587,MATCH($D5,온라인_반찬!$C$2:$C$587,0),7),"") | G5: =IFERROR(INDEX(온라인_반찬!$C$2:$I$587,MATCH($F5,온라인_반찬!$C$2:$C$587,0),7),"") | I5: =IFERROR(INDEX(온라인_반찬!$C$2:$I$587,MATCH($H5,온라인_반찬!$C$2:$C$587,0),7),"") | K5: =IFERROR(INDEX(온라인_반찬!$C$2:$I$587,MATCH($J5,온라인_반찬!$C$2:$C$587,0),7),"") | P5: 돈사태양념찜
C6: =IFERROR(INDEX(온라인_반찬!$C$2:$I$587,MATCH($B6,온라인_반찬!$C$2:$C$587,0),7),"") | E6: =IFERROR(INDEX(온라인_반찬!$C$2:$I$587,MATCH($D6,온라인_반찬!$C$2:$C$587,0),7),"") | G6: =IFERROR(INDEX(온라인_반찬!$C$2:$I$587,MATCH($F6,온라인_반찬!$C$2:$C$587,0),7),"") | I6: =IFERROR(INDEX(온라인_반찬!$C$2:$I$587,MATCH($H6,온라인_반찬!$C$2:$C$587,0),7),"") | K6: =IFERROR(INDEX(온라인_반찬!$C$2:$I$587,MATCH($J6,온라인_반찬!$C$2:$C$587,0),7),"") | P6: 등갈비찜
C7: =IFERROR(INDEX(온라인_반찬!$C$2:$I$587,MATCH($B7,온라인_반찬!$C$2:$C$587,0),7),"") | E7: =IFERROR(INDEX(온라인_반찬!$C$2:$I$587,MATCH($D7,온라인_반찬!$C$2:$C$587,0),7),"") | G7: =IFERROR(INDEX(온라인_반찬!$C$2:$I$587,MATCH($F7,온라인_반찬!$C$2:$C$587,0),7),"") | I7: =IFERROR(INDEX(온라인_반찬!$C$2:$I$587,MATCH($H7,온라인_반찬!$C$2:$C$587,0),7),"") | K7: =IFERROR(INDEX(온라인_반찬!$C$2:$I$587,MATCH($J7,온라인_반찬!$C$2:$C$587,0),7),"") | P7: 로제순살치킨떡볶이
C8: =IFERROR(INDEX(온라인_반찬!$C$2:$I$587,MATCH($B8,온라인_반찬!$C$2:$C$587,0),7),"") | E8: =IFERROR(INDEX(온라인_반찬!$C$2:$I$587,MATCH($D8,온라인_반찬!$C$2:$C$587,0),7),"") | G8: =IFERROR(INDEX(온라인_반찬!$C$2:$I$587,MATCH($F8,온라인_반찬!$C$2:$C$587,0),7),"") | I8: =IFERROR(INDEX(온라인_반찬!$C$2:$I$587,MATCH($H8,온라인_반찬!$C$2:$C$587,0),7),"") | K8: =IFERROR(INDEX(온라인_반찬!$C$2:$I$587,MATCH($J8,온라인_반찬!$C$2:$C$587,0),7),"") | P8: 양념치킨
C9: =IFERROR(INDEX(온라인_반찬!$C$2:$I$587,MATCH($B9,온라인_반찬!$C$2:$C$587,0),7),"") | E9: =IFERROR(INDEX(온라인_반찬!$C$2:$I$587,MATCH($D9,온라인_반찬!$C$2:$C$587,0),7),"") | G9: =IFERROR(INDEX(온라인_반찬!$C$2:$I$587,MATCH($F9,온라인_반찬!$C$2:$C$587,0),7),"") | I9: =IFERROR(INDEX(온라인_반찬!$C$2:$I$587,MATCH($H9,온라인_반찬!$C$2:$C$587,0),7),"") | K9: =IFERROR(INDEX(온라인_반찬!$C$2:$I$587,MATCH($J9,온라인_반찬!$C$2:$C$587,0),7),"") | P9: 프리미엄떡갈비
C10: =IFERROR(INDEX(온라인_반찬!$C$2:$I$587,MATCH($B10,온라인_반찬!$C$2:$C$587,0),7),"") | E10: =IFERROR(INDEX(온라인_반찬!$C$2:$I$587,MATCH($D10,온라인_반찬!$C$2:$C$587,0),7),"") | G10: =IFERROR(INDEX(온라인_반찬!$C$2:$I$587,MATCH($F10,온라인_반찬!$C$2:$C$587,0),7),"") | I10: =IFERROR(INDEX(온라인_반찬!$C$2:$I$587,MATCH($H10,온라인_반찬!$C$2:$C$587,0),7),"") | K10: =IFERROR(INDEX(온라인_반찬!$C$2:$I$587,MATCH($J10,온라인_반찬!$C$2:$C$587,0),7),"") | P10: 부채살채소찜
C11: =IFERROR(INDEX(온라인_반찬!$C$2:$I$587,MATCH($B11,온라인_반찬!$C$2:$C$587,0),7),"") | E11: =IFERROR(INDEX(온라인_반찬!$C$2:$I$587,MATCH($D11,온라인_반찬!$C$2:$C$587,0),7),"") | G11: =IFERROR(INDEX(온라인_반찬!$C$2:$I$587,MATCH($F11,온라인_반찬!$C$2:$C$587,0),7),"") | I11: =IFERROR(INDEX(온라인_반찬!$C$2:$I$587,MATCH($H11,온라인_반찬!$C$2:$C$587,0),7),"") | K11: =IFERROR(INDEX(온라인_반찬!$C$2:$I$587,MATCH($J11,온라인_반찬!$C$2:$C$587,0),7),"") | P11: 크리스피쌀핫도그
C12: =IFERROR(INDEX(온라인_반찬!$C$2:$I$587,MATCH($B12,온라인_반찬!$C$2:$C$587,0),7),"") | D12: 과일 | G12: =IFERROR(INDEX(온라인_반찬!$C$2:$I$587,MATCH($F12,온라인_반찬!$C$2:$C$587,0),7),"") | H12: 과일 | J12: 뿌링클치킨 | K12: =IFERROR(INDEX(온라인_반찬!$C$2:$I$587,MATCH($J12,온라인_반찬!$C$2:$C$587,0),7),"") -> .1.2.5.6.15. | P12: 국물떡볶이
A13: 날짜 | P13: 전복버터구이
A14: 주차 | B14: 메뉴 | C14: 알레르기표기 | D14: 메뉴 | E14: 알레르기표기 | F14: 메뉴 | G14: 알레르기표기 | H14: 메뉴 | I14: 알레르기표기 | J14: 메뉴 | K14: 알레르기표기 | L14: 메뉴 | M14: 알레르기표기 | N14: 메뉴 | O14: 알레르기표기 | P14: 목살소금구이
A15: 2주 | C15: =IFERROR(INDEX(온라인_반찬!$C$2:$I$587,MATCH($B15,온라인_반찬!$C$2:$C$587,0),7),"") | E15: =IFERROR(INDEX(온라인_반찬!$C$2:$I$587,MATCH($D15,온라인_반찬!$C$2:$C$587,0),7),"") | G15: =IFERROR(INDEX(온라인_반찬!$C$2:$I$587,MATCH($F15,온라인_반찬!$C$2:$C$587,0),7),"") | I15: =IFERROR(INDEX(온라인_반찬!$C$2:$I$587,MATCH($H15,온라인_반찬!$C$2:$C$587,0),7),"") | K15: =IFERROR(INDEX(온라인_반찬!$C$2:$I$587,MATCH($J15,온라인_반찬!$C$2:$C$587,0),7),"") | P15: 왕새우튀김
C16: =IFERROR(INDEX(온라인_반찬!$C$2:$I$587,MATCH($B16,온라인_반찬!$C$2:$C$587,0),7),"") | E16: =IFERROR(INDEX(온라인_반찬!$C$2:$I$587,MATCH($D16,온라인_반찬!$C$2:$C$587,0),7),"") | G16: =IFERROR(INDEX(온라인_반찬!$C$2:$I$587,MATCH($F16,온라인_반찬!$C$2:$C$587,0),7),"") | I16: =IFERROR(INDEX(온라인_반찬!$C$2:$I$587,MATCH($H16,온라인_반찬!$C$2:$C$587,0),7),"") | K16: =IFERROR(INDEX(온라인_반찬!$C$2:$I$587,MATCH($J16,온라인_반찬!$C$2:$C$587,0),7),"") | P16: 불고기피자
C17: =IFERROR(INDEX(온라인_반찬!$C$2:$I$587,MATCH($B17,온라인_반찬!$C$2:$C$587,0),7),"") | E17: =IFERROR(INDEX(온라인_반찬!$C$2:$I$587,MATCH($D17,온라인_반찬!$C$2:$C$587,0),7),"") | G17: =IFERROR(INDEX(온라인_반찬!$C$2:$I$587,MATCH($F17,온라인_반찬!$C$2:$C$587,0),7),"") | I17: =IFERROR(INDEX(온라인_반찬!$C$2:$I$587,MATCH($H17,온라인_반찬!$C$2:$C$587,0),7),"") | K17: =IFERROR(INDEX(온라인_반찬!$C$2:$I$587,MATCH($J17,온라인_반찬!$C$2:$C$587,0),7),"") | P17: 닭날개오븐구이
C18: =IFERROR(INDEX(온라인_반찬!$C$2:$I$587,MATCH($B18,온라인_반찬!$C$2:$C$587,0),7),"") | E18: =IFERROR(INDEX(온라인_반찬!$C$2:$I$587,MATCH($D18,온라인_반찬!$C$2:$C$587,0),7),"") | G18: =IFERROR(INDEX(온라인_반찬!$C$2:$I$587,MATCH($F18,온라인_반찬!$C$2:$C$587,0),7),"") | I18: =IFERROR(INDEX(온라인_반찬!$C$2:$I$587,MATCH($H18,온라인_반찬!$C$2:$C$587,0),7),"") | K18: =IFERROR(INDEX(온라인_반찬!$C$2:$I$587,MATCH($J18,온라인_반찬!$C$2:$C$587,0),7),"") | P18: 족발부추무침
C19: =IFERROR(INDEX(온라인_반찬!$C$2:$I$587,MATCH($B19,온라인_반찬!$C$2:$C$587,0),7),"") | E19: =IFERROR(INDEX(온라인_반찬!$C$2:$I$587,MATCH($D19,온라인_반찬!$C$2:$C$587,0),7),"") | G19: =IFERROR(INDEX(온라인_반찬!$C$2:$I$587,MATCH($F19,온라인_반찬!$C$2:$C$587,0),7),"") | I19: =IFERROR(INDEX(온라인_반찬!$C$2:$I$587,MATCH($H19,온라인_반찬!$C$2:$C$587,0),7),"") | K19: =IFERROR(INDEX(온라인_반찬!$C$2:$I$587,MATCH($J19,온라인_반찬!$C$2:$C$587,0),7),"") | P19: 비프찹스테이크
C20: =IFERROR(INDEX(온라인_반찬!$C$2:$I$587,MATCH($B20,온라인_반찬!$C$2:$C$587,0),7),"") | E20: =IFERROR(INDEX(온라인_반찬!$C$2:$I$587,MATCH($D20,온라인_반찬!$C$2:$C$587,0),7),"") | G20: =IFERROR(INDEX(온라인_반찬!$C$2:$I$587,MATCH($F20,온라인_반찬!$C$2:$C$587,0),7),"") | I20: =IFERROR(INDEX(온라인_반찬!$C$2:$I$587,MATCH($H20,온라인_반찬!$C$2:$C$587,0),7),"") | K20: =IFERROR(INDEX(온라인_반찬!$C$2:$I$587,MATCH($J20,온라인_반찬!$C$2:$C$587,0),7),"") | P20: 훈제닭다리살
C21: =IFERROR(INDEX(온라인_반찬!$C$2:$I$587,MATCH($B21,온라인_반찬!$C$2:$C$587,0),7),"") | E21: =IFERROR(INDEX(온라인_반찬!$C$2:$I$587,MATCH($D21,온라인_반찬!$C$2:$C$587,0),7),"") | G21: =IFERROR(INDEX(온라인_반찬!$C$2:$I$587,MATCH($F21,온라인_반찬!$C$2:$C$587,0),7),"") | I21: =IFERROR(INDEX(온라인_반찬!$C$2:$I$587,MATCH($H21,온라인_반찬!$C$2:$C$587,0),7),"") | K21: =IFERROR(INDEX(온라인_반찬!$C$2:$I$587,MATCH($J21,온라인_반찬!$C$2:$C$587,0),7),"") | P21: 돈육강정
B22: 훈제오리볶음 | C22: =IFERROR(INDEX(온라인_반찬!$C$2:$I$587,MATCH($B22,온라인_반찬!$C$2:$C$587,0),7),"") -> .1.5.6.10.18.21. | D22: 과일 | G22: =IFERROR(INDEX(온라인_반찬!$C$2:$I$587,MATCH($F22,온라인_반찬!$C$2:$C$587,0),7),"") | H22: 과일 | J22: 등갈비김치찜 | K22: =IFERROR(INDEX(온라인_반찬!$C$2:$I$587,MATCH($J22,온라인_반찬!$C$2:$C$587,0),7),"") -> .5.10.19.21. | P22: 뿌링클치킨
A23: 날짜 | P23: 훈제오리볶음
A24: 주차 | B24: 메뉴 | C24: 알레르기표기 | D24: 메뉴 | E24: 알레르기표기 | F24: 메뉴 | G24: 알레르기표기 | H24: 메뉴 | I24: 알레르기표기 | J24: 메뉴 | K24: 알레르기표기 | P24: 레몬크림새우
A25: 3주 | C25: =IFERROR(INDEX(온라인_반찬!$C$2:$I$587,MATCH($B25,온라인_반찬!$C$2:$C$587,0),7),"") | E25: =IFERROR(INDEX(온라인_반찬!$C$2:$I$587,MATCH($D25,온라인_반찬!$C$2:$C$587,0),7),"") | G25: =IFERROR(INDEX(온라인_반찬!$C$2:$I$587,MATCH($F25,온라인_반찬!$C$2:$C$587,0),7),"") | I25: =IFERROR(INDEX(온라인_반찬!$C$2:$I$587,MATCH($H25,온라인_반찬!$C$2:$C$587,0),7),"") | K25: =IFERROR(INDEX(온라인_반찬!$C$2:$I$587,MATCH($J25,온라인_반찬!$C$2:$C$587,0),7),"") | P25: 등갈비김치찜
C26: =IFERROR(INDEX(온라인_반찬!$C$2:$I$587,MATCH($B26,온라인_반찬!$C$2:$C$587,0),7),"") | E26: =IFERROR(INDEX(온라인_반찬!$C$2:$I$587,MATCH($D26,온라인_반찬!$C$2:$C$587,0),7),"") | G26: =IFERROR(INDEX(온라인_반찬!$C$2:$I$587,MATCH($F26,온라인_반찬!$C$2:$C$587,0),7),"") | I26: =IFERROR(INDEX(온라인_반찬!$C$2:$I$587,MATCH($H26,온라인_반찬!$C$2:$C$587,0),7),"") | K26: =IFERROR(INDEX(온라인_반찬!$C$2:$I$587,MATCH($J26,온라인_반찬!$C$2:$C$587,0),7),"") | P26: 우삼겹떡볶이
C27: =IFERROR(INDEX(온라인_반찬!$C$2:$I$587,MATCH($B27,온라인_반찬!$C$2:$C$587,0),7),"") | E27: =IFERROR(INDEX(온라인_반찬!$C$2:$I$587,MATCH($D27,온라인_반찬!$C$2:$C$587,0),7),"") | G27: =IFERROR(INDEX(온라인_반찬!$C$2:$I$587,MATCH($F27,온라인_반찬!$C$2:$C$587,0),7),"") | I27: =IFERROR(INDEX(온라인_반찬!$C$2:$I$587,MATCH($H27,온라인_반찬!$C$2:$C$587,0),7),"") | K27: =IFERROR(INDEX(온라인_반찬!$C$2:$I$587,MATCH($J27,온라인_반찬!$C$2:$C$587,0),7),"") | P27: 모짜렐라치즈볼
C28: =IFERROR(INDEX(온라인_반찬!$C$2:$I$587,MATCH($B28,온라인_반찬!$C$2:$C$587,0),7),"") | E28: =IFERROR(INDEX(온라인_반찬!$C$2:$I$587,MATCH($D28,온라인_반찬!$C$2:$C$587,0),7),"") | G28: =IFERROR(INDEX(온라인_반찬!$C$2:$I$587,MATCH($F28,온라인_반찬!$C$2:$C$587,0),7),"") | I28: =IFERROR(INDEX(온라인_반찬!$C$2:$I$587,MATCH($H28,온라인_반찬!$C$2:$C$587,0),7),"") | K28: =IFERROR(INDEX(온라인_반찬!$C$2:$I$587,MATCH($J28,온라인_반찬!$C$2:$C$587,0),7),"") | P28: 크로와상샌드위치
C29: =IFERROR(INDEX(온라인_반찬!$C$2:$I$587,MATCH($B29,온라인_반찬!$C$2:$C$587,0),7),"") | E29: =IFERROR(INDEX(온라인_반찬!$C$2:$I$587,MATCH($D29,온라인_반찬!$C$2:$C$587,0),7),"") | G29: =IFERROR(INDEX(온라인_반찬!$C$2:$I$587,MATCH($F29,온라인_반찬!$C$2:$C$587,0),7),"") | I29: =IFERROR(INDEX(온라인_반찬!$C$2:$I$587,MATCH($H29,온라인_반찬!$C$2:$C$587,0),7),"") | K29: =IFERROR(INDEX(온라인_반찬!$C$2:$I$587,MATCH($J29,온라인_반찬!$C$2:$C$587,0),7),"") | P29: 닭다리오븐구이
C30: =IFERROR(INDEX(온라인_반찬!$C$2:$I$587,MATCH($B30,온라인_반찬!$C$2:$C$587,0),7),"") | E30: =IFERROR(INDEX(온라인_반찬!$C$2:$I$587,MATCH($D30,온라인_반찬!$C$2:$C$587,0),7),"") | G30: =IFERROR(INDEX(온라인_반찬!$C$2:$I$587,MATCH($F30,온라인_반찬!$C$2:$C$587,0),7),"") | I30: =IFERROR(INDEX(온라인_반찬!$C$2:$I$587,MATCH($H30,온라인_반찬!$C$2:$C$587,0),7),"") | K30: =IFERROR(INDEX(온라인_반찬!$C$2:$I$587,MATCH($J30,온라인_반찬!$C$2:$C$587,0),7),"") | M30: 0 | P30: 새우감바스&바게트
C31: =IFERROR(INDEX(온라인_반찬!$C$2:$I$587,MATCH($B31,온라인_반찬!$C$2:$C$587,0),7),"") | E31: =IFERROR(INDEX(온라인_반찬!$C$2:$I$587,MATCH($D31,온라인_반찬!$C$2:$C$587,0),7),"") | G31: =IFERROR(INDEX(온라인_반찬!$C$2:$I$587,MATCH($F31,온라인_반찬!$C$2:$C$587,0),7),"") | I31: =IFERROR(INDEX(온라인_반찬!$C$2:$I$587,MATCH($H31,온라인_반찬!$C$2:$C$587,0),7),"") | K31: =IFERROR(INDEX(온라인_반찬!$C$2:$I$587,MATCH($J31,온라인_반찬!$C$2:$C$587,0),7),"") | P31: 삼겹살소금구이
B32: 우삼겹떡볶이 | C32: =IFERROR(INDEX(온라인_반찬!$C$2:$I$587,MATCH($B32,온라인_반찬!$C$2:$C$587,0),7),"") -> .1.5.6.10.16. | D32: 과일 | G32: =IFERROR(INDEX(온라인_반찬!$C$2:$I$587,MATCH($F32,온라인_반찬!$C$2:$C$587,0),7),"") | H32: 과일 | K32: =IFERROR(INDEX(온라인_반찬!$C$2:$I$587,MATCH($J32,온라인_반찬!$C$2:$C$587,0),7),"") | P32: 보쌈수육
A33: 날짜 | P33: 오리엔탈파닭
A34: 주차 | B34: 메뉴 | C34: 알레르기표기 | D34: 메뉴 | E34: 알레르기표기 | F34: 메뉴 | G34: 알레르기표기 | H34: 메뉴 | I34: 알레르기표기 | J34: 메뉴 | K34: 알레르기표기 | P34: 차돌숙주볶음
A35: 4주 | C35: =IFERROR(INDEX(온라인_반찬!$C$2:$I$587,MATCH($B35,온라인_반찬!$C$2:$C$587,0),7),"") | E35: =IFERROR(INDEX(온라인_반찬!$C$2:$I$587,MATCH($D35,온라인_반찬!$C$2:$C$587,0),7),"") | G35: =IFERROR(INDEX(온라인_반찬!$C$2:$I$587,MATCH($F35,온라인_반찬!$C$2:$C$587,0),7),"") | I35: =IFERROR(INDEX(온라인_반찬!$C$2:$I$587,MATCH($H35,온라인_반찬!$C$2:$C$587,0),7),"") | K35: =IFERROR(INDEX(온라인_반찬!$C$2:$I$587,MATCH($J35,온라인_반찬!$C$2:$C$587,0),7),"")
C36: =IFERROR(INDEX(온라인_반찬!$C$2:$I$587,MATCH($B36,온라인_반찬!$C$2:$C$587,0),7),"") | E36: =IFERROR(INDEX(온라인_반찬!$C$2:$I$587,MATCH($D36,온라인_반찬!$C$2:$C$587,0),7),"") | G36: =IFERROR(INDEX(온라인_반찬!$C$2:$I$587,MATCH($F36,온라인_반찬!$C$2:$C$587,0),7),"") | I36: =IFERROR(INDEX(온라인_반찬!$C$2:$I$587,MATCH($H36,온라인_반찬!$C$2:$C$587,0),7),"") | K36: =IFERROR(INDEX(온라인_반찬!$C$2:$I$587,MATCH($J36,온라인_반찬!$C$2:$C$587,0),7),"")
C37: =IFERROR(INDEX(온라인_반찬!$C$2:$I$587,MATCH($B37,온라인_반찬!$C$2:$C$587,0),7),"") | E37: =IFERROR(INDEX(온라인_반찬!$C$2:$I$587,MATCH($D37,온라인_반찬!$C$2:$C$587,0),7),"") | G37: =IFERROR(INDEX(온라인_반찬!$C$2:$I$587,MATCH($F37,온라인_반찬!$C$2:$C$587,0),7),"") | I37: =IFERROR(INDEX(온라인_반찬!$C$2:$I$587,MATCH($H37,온라인_반찬!$C$2:$C$587,0),7),"") | K37: =IFERROR(INDEX(온라인_반찬!$C$2:$I$587,MATCH($J37,온라인_반찬!$C$2:$C$587,0),7),"")
C38: =IFERROR(INDEX(온라인_반찬!$C$2:$I$587,MATCH($B38,온라인_반찬!$C$2:$C$587,0),7),"") | E38: =IFERROR(INDEX(온라인_반찬!$C$2:$I$587,MATCH($D38,온라인_반찬!$C$2:$C$587,0),7),"") | G38: =IFERROR(INDEX(온라인_반찬!$C$2:$I$587,MATCH($F38,온라인_반찬!$C$2:$C$587,0),7),"") | I38: =IFERROR(INDEX(온라인_반찬!$C$2:$I$587,MATCH($H38,온라인_반찬!$C$2:$C$587,0),7),"") | K38: =IFERROR(INDEX(온라인_반찬!$C$2:$I$587,MATCH($J38,온라인_반찬!$C$2:$C$587,0),7),"")
C39: =IFERROR(INDEX(온라인_반찬!$C$2:$I$587,MATCH($B39,온라인_반찬!$C$2:$C$587,0),7),"") | E39: =IFERROR(INDEX(온라인_반찬!$C$2:$I$587,MATCH($D39,온라인_반찬!$C$2:$C$587,0),7),"") | G39: =IFERROR(INDEX(온라인_반찬!$C$2:$I$587,MATCH($F39,온라인_반찬!$C$2:$C$587,0),7),"") | I39: =IFERROR(INDEX(온라인_반찬!$C$2:$I$587,MATCH($H39,온라인_반찬!$C$2:$C$587,0),7),"") | K39: =IFERROR(INDEX(온라인_반찬!$C$2:$I$587,MATCH($J39,온라인_반찬!$C$2:$C$587,0),7),"")
C40: =IFERROR(INDEX(온라인_반찬!$C$2:$I$587,MATCH($B40,온라인_반찬!$C$2:$C$587,0),7),"") | E40: =IFERROR(INDEX(온라인_반찬!$C$2:$I$587,MATCH($D40,온라인_반찬!$C$2:$C$587,0),7),"") | G40: =IFERROR(INDEX(온라인_반찬!$C$2:$I$587,MATCH($F40,온라인_반찬!$C$2:$C$587,0),7),"") | I40: =IFERROR(INDEX(온라인_반찬!$C$2:$I$587,MATCH($H40,온라인_반찬!$C$2:$C$587,0),7),"") | K40: =IFERROR(INDEX(온라인_반찬!$C$2:$I$587,MATCH($J40,온라인_반찬!$C$2:$C$587,0),7),"")
C41: =IFERROR(INDEX(온라인_반찬!$C$2:$I$587,MATCH($B41,온라인_반찬!$C$2:$C$587,0),7),"") | E41: =IFERROR(INDEX(온라인_반찬!$C$2:$I$587,MATCH($D41,온라인_반찬!$C$2:$C$587,0),7),"") | G41: =IFERROR(INDEX(온라인_반찬!$C$2:$I$587,MATCH($F41,온라인_반찬!$C$2:$C$587,0),7),"") | I41: =IFERROR(INDEX(온라인_반찬!$C$2:$I$587,MATCH($H41,온라인_반찬!$C$2:$C$587,0),7),"") | K41: =IFERROR(INDEX(온라인_반찬!$C$2:$I$587,MATCH($J41,온라인_반찬!$C$2:$C$587,0),7),"")
...

Sheet 식단표 (알레르기표기)
A1: 01월 식단표
A2: 요일 | B2: 월 | D2: 화 | F2: 수 | H2: 목 | J2: 금
A3: 날짜
A4: 주차 | B4: 메뉴 | C4: 알레르기표기 | D4: 메뉴 | E4: 알레르기표기 | F4: 메뉴 | G4: 알레르기표기 | H4: 메뉴 | I4: 알레르기표기 | J4: 메뉴 | K4: 알레르기표기 | L4: 메뉴 | M4: 알레르기표기
A5: 1주 | C5: =IFERROR(INDEX(온라인_반찬!$C$2:$I$587,MATCH($B5,온라인_반찬!$C$2:$C$587,0),7),"") | E5: =IFERROR(INDEX(온라인_반찬!$C$2:$I$587,MATCH($D5,온라인_반찬!$C$2:$C$587,0),7),"") | G5: =IFERROR(INDEX(온라인_반찬!$C$2:$I$587,MATCH($F5,온라인_반찬!$C$2:$C$587,0),7),"") | H5: ♣새해♣ | J5: 친환경찰보리쌀밥 | K5: =IFERROR(INDEX(온라인_반찬!$C$2:$I$587,MATCH($J5,온라인_반찬!$C$2:$C$587,0),7),"") -> 0
C6: =IFERROR(INDEX(온라인_반찬!$C$2:$I$587,MATCH($B6,온라인_반찬!$C$2:$C$587,0),7),"") | E6: =IFERROR(INDEX(온라인_반찬!$C$2:$I$587,MATCH($D6,온라인_반찬!$C$2:$C$587,0),7),"") | G6: =IFERROR(INDEX(온라인_반찬!$C$2:$I$587,MATCH($F6,온라인_반찬!$C$2:$C$587,0),7),"") | J6: 소고기계란덮밥소스 | K6: =IFERROR(INDEX(온라인_반찬!$C$2:$I$587,MATCH($J6,온라인_반찬!$C$2:$C$587,0),7),"") -> .1.2.5.6.16.
C7: =IFERROR(INDEX(온라인_반찬!$C$2:$I$587,MATCH($B7,온라인_반찬!$C$2:$C$587,0),7),"") | E7: =IFERROR(INDEX(온라인_반찬!$C$2:$I$587,MATCH($D7,온라인_반찬!$C$2:$C$587,0),7),"") | G7: =IFERROR(INDEX(온라인_반찬!$C$2:$I$587,MATCH($F7,온라인_반찬!$C$2:$C$587,0),7),"") | J7: 갈비만두찜 | K7: =IFERROR(INDEX(온라인_반찬!$C$2:$I$587,MATCH($J7,온라인_반찬!$C$2:$C$587,0),7),"") -> .2.5.6.10.16.21.
C8: =IFERROR(INDEX(온라인_반찬!$C$2:$I$587,MATCH($B8,온라인_반찬!$C$2:$C$587,0),7),"") | E8: =IFERROR(INDEX(온라인_반찬!$C$2:$I$587,MATCH($D8,온라인_반찬!$C$2:$C$587,0),7),"") | G8: =IFERROR(INDEX(온라인_반찬!$C$2:$I$587,MATCH($F8,온라인_반찬!$C$2:$C$587,0),7),"") | J8: 오이부추무침 | K8: =IFERROR(INDEX(온라인_반찬!$C$2:$I$587,MATCH($J8,온라인_반찬!$C$2:$C$587,0),7),"") -> .5.21.
C9: =IFERROR(INDEX(온라인_반찬!$C$2:$I$587,MATCH($B9,온라인_반찬!$C$2:$C$587,0),7),"") | E9: =IFERROR(INDEX(온라인_반찬!$C$2:$I$587,MATCH($D9,온라인_반찬!$C$2:$C$587,0),7),"") | G9: =IFERROR(INDEX(온라인_반찬!$C$2:$I$587,MATCH($F9,온라인_반찬!$C$2:$C$587,0),7),"") | J9: 배추김치 | K9: =IFERROR(INDEX(온라인_반찬!$C$2:$I$587,MATCH($J9,온라인_반찬!$C$2:$C$587,0),7),"") -> .9.12.
C10: =IFERROR(INDEX(온라인_반찬!$C$2:$I$587,MATCH($B10,온라인_반찬!$C$2:$C$587,0),7),"") | E10: =IFERROR(INDEX(온라인_반찬!$C$2:$I$587,MATCH($D10,온라인_반찬!$C$2:$C$587,0),7),"") | G10: =IFERROR(INDEX(온라인_반찬!$C$2:$I$587,MATCH($F10,온라인_반찬!$C$2:$C$587,0),7),"") | J10: 볼어묵국 | K10: =IFERROR(INDEX(온라인_반찬!$C$2:$I$587,MATCH($J10,온라인_반찬!$C$2:$C$587,0),7),"") -> .5.6.
C11: =IFERROR(INDEX(온라인_반찬!$C$2:$I$587,MATCH($B11,온라인_반찬!$C$2:$C$587,0),7),"") | E11: =IFERROR(INDEX(온라인_반찬!$C$2:$I$587,MATCH($D11,온라인_반찬!$C$2:$C$587,0),7),"") | G11: =IFERROR(INDEX(온라인_반찬!$C$2:$I$587,MATCH($F11,온라인_반찬!$C$2:$C$587,0),7),"") | K11: =IFERROR(INDEX(온라인_반찬!$C$2:$I$587,MATCH($J11,온라인_반찬!$C$2:$C$587,0),7),"")
C12: =IFERROR(INDEX(온라인_반찬!$C$2:$I$587,MATCH($B12,온라인_반찬!$C$2:$C$587,0),7),"") | G12: =IFERROR(INDEX(온라인_반찬!$C$2:$I$587,MATCH($F12,온라인_반찬!$C$2:$C$587,0),7),"") | K12: =IFERROR(INDEX(온라인_반찬!$C$2:$I$587,MATCH($J12,온라인_반찬!$C$2:$C$587,0),7),"")
A13: 날짜
A14: 주차 | B14: 메뉴 | C14: 알레르기표기 | D14: 메뉴 | E14: 알레르기표기 | F14: 메뉴 | G14: 알레르기표기 | H14: 메뉴 | I14: 알레르기표기 | J14: 메뉴 | K14: 알레르기표기 | L14: 메뉴 | M14: 알레르기표기 | N14: 메뉴 | O14: 알레르기표기
A15: 2주 | B15: 친환경현미쌀밥 | C15: =IFERROR(INDEX(온라인_반찬!$C$2:$I$587,MATCH($B15,온라인_반찬!$C$2:$C$587,0),7),"") -> 0 | D15: 친환경귀리쌀밥 | E15: =IFERROR(INDEX(온라인_반찬!$C$2:$I$587,MATCH($D15,온라인_반찬!$C$2:$C$587,0),7),"") -> 0 | F15: 친환경찰흑미쌀밥 | G15: =IFERROR(INDEX(온라인_반찬!$C$2:$I$587,MATCH($F15,온라인_반찬!$C$2:$C$587,0),7),"") -> 0 | H15: 흰쌀밥 | I15: =IFERROR(INDEX(온라인_반찬!$C$2:$I$587,MATCH($H15,온라인_반찬!$C$2:$C$587,0),7),"") -> 0 | J15: 친환경찰보리쌀밥 | K15: =IFERROR(INDEX(온라인_반찬!$C$2:$I$587,MATCH($J15,온라인_반찬!$C$2:$C$587,0),7),"") -> 0
B16: 생선까스 | C16: =IFERROR(INDEX(온라인_반찬!$C$2:$I$587,MATCH($B16,온라인_반찬!$C$2:$C$587,0),7),"") -> 1.5. | D16: 안동찜닭 | E16: =IFERROR(INDEX(온라인_반찬!$C$2:$I$587,MATCH($D16,온라인_반찬!$C$2:$C$587,0),7),"") -> .1.5.6.10.21. | F16: 황금팽이소불고기 | G16: =IFERROR(INDEX(온라인_반찬!$C$2:$I$587,MATCH($F16,온라인_반찬!$C$2:$C$587,0),7),"") -> .5.16.21. | H16: 로제닭볶음 | I16: =IFERROR(INDEX(온라인_반찬!$C$2:$I$587,MATCH($H16,온라인_반찬!$C$2:$C$587,0),7),"") -> .2.5.6.12.15. | J16: 제육쌈장두루치기 | K16: =IFERROR(INDEX(온라인_반찬!$C$2:$I$587,MATCH($J16,온라인_반찬!$C$2:$C$587,0),7),"") -> .5.10.21.
B17: & 타르타르소스 | C17: =IFERROR(INDEX(온라인_반찬!$C$2:$I$587,MATCH($B17,온라인_반찬!$C$2:$C$587,0),7),"") -> .1.5.19. | D17: 세멸치엿장조림 | E17: =IFERROR(INDEX(온라인_반찬!$C$2:$I$587,MATCH($D17,온라인_반찬!$C$2:$C$587,0),7),"") -> .5.21. | F17: 스크램블에그 | G17: =IFERROR(INDEX(온라인_반찬!$C$2:$I$587,MATCH($F17,온라인_반찬!$C$2:$C$587,0),7),"") -> .1.2.5. | H17: 미트볼조림 | I17: =IFERROR(INDEX(온라인_반찬!$C$2:$I$587,MATCH($H17,온라인_반찬!$C$2:$C$587,0),7),"") -> .1.2.5.6.10.16. | J17: 참치마요 | K17: =IFERROR(INDEX(온라인_반찬!$C$2:$I$587,MATCH($J17,온라인_반찬!$C$2:$C$587,0),7),"") -> .1.5.
B18: 라구숏파스타 | C18: =IFERROR(INDEX(온라인_반찬!$C$2:$I$587,MATCH($B18,온라인_반찬!$C$2:$C$587,0),7),"") -> .5.6.10.12.15.16. | D18: 삼색콩나물무침 | E18: =IFERROR(INDEX(온라인_반찬!$C$2:$I$587,MATCH($D18,온라인_반찬!$C$2:$C$587,0),7),"") -> .5.21. | F18: 미역무채무침 | G18: =IFERROR(INDEX(온라인_반찬!$C$2:$I$587,MATCH($F18,온라인_반찬!$C$2:$C$587,0),7),"") -> .5.21. | H18: 배추된장나물 | I18: =IFERROR(INDEX(온라인_반찬!$C$2:$I$587,MATCH($H18,온라인_반찬!$C$2:$C$587,0),7),"") -> .5.21. | J18: 도시락김 | K18: =IFERROR(INDEX(온라인_반찬!$C$2:$I$587,MATCH($J18,온라인_반찬!$C$2:$C$587,0),7),"") -> .21.
B19: 단호박샐러드 | C19: =IFERROR(INDEX(온라인_반찬!$C$2:$I$587,MATCH($B19,온라인_반찬!$C$2:$C$587,0),7),"") -> .1.5. | D19: 깍두기 | E19: =IFERROR(INDEX(온라인_반찬!$C$2:$I$587,MATCH($D19,온라인_반찬!$C$2:$C$587,0),7),"") -> .6.9. | F19: 백김치 | G19: =IFERROR(INDEX(온라인_반찬!$C$2:$I$587,MATCH($F19,온라인_반찬!$C$2:$C$587,0),7),"") -> 0 | H19: 깍두기 | I19: =IFERROR(INDEX(온라인_반찬!$C$2:$I$587,MATCH($H19,온라인_반찬!$C$2:$C$587,0),7),"") -> .6.9. | J19: 배추김치 | K19: =IFERROR(INDEX(온라인_반찬!$C$2:$I$587,MATCH($J19,온라인_반찬!$C$2:$C$587,0),7),"") -> .9.12.
B20: 배추김치 | C20: =IFERROR(INDEX(온라인_반찬!$C$2:$I$587,MATCH($B20,온라인_반찬!$C$2:$C$587,0),7),"") -> .9.12. | D20: 황태계란국 | E20: =IFERROR(INDEX(온라인_반찬!$C$2:$I$587,MATCH($D20,온라인_반찬!$C$2:$C$587,0),7),"") -> .1.5.21. | F20: 모둠채소된장국 | G20: =IFERROR(INDEX(온라인_반찬!$C$2:$I$587,MATCH($F20,온라인_반찬!$C$2:$C$587,0),7),"") -> .5.9. | H20: 올갱이미역국 | I20: =IFERROR(INDEX(온라인_반찬!$C$2:$I$587,MATCH($H20,온라인_반찬!$C$2:$C$587,0),7),"") -> .5.9. | J20: 순두부된장찌개 | K20: =IFERROR(INDEX(온라인_반찬!$C$2:$I$587,MATCH($J20,온라인_반찬!$C$2:$C$587,0),7),"") -> .5.
B21: 소고기무국 | C21: =IFERROR(INDEX(온라인_반찬!$C$2:$I$587,MATCH($B21,온라인_반찬!$C$2:$C$587,0),7),"") -> .5.16. | E21: =IFERROR(INDEX(온라인_반찬!$C$2:$I$587,MATCH($D21,온라인_반찬!$C$2:$C$587,0),7),"") | G21: =IFERROR(INDEX(온라인_반찬!$C$2:$I$587,MATCH($F21,온라인_반찬!$C$2:$C$587,0),7),"") | I21: =IFERROR(INDEX(온라인_반찬!$C$2:$I$587,MATCH($H21,온라인_반찬!$C$2:$C$587,0),7),"") | K21: =IFERROR(INDEX(온라인_반찬!$C$2:$I$587,MATCH($J21,온라인_반찬!$C$2:$C$587,0),7),"")
C22: =IFERROR(INDEX(온라인_반찬!$C$2:$I$587,MATCH($B22,온라인_반찬!$C$2:$C$587,0),7),"") | G22: =IFERROR(INDEX(온라인_반찬!$C$2:$I$587,MATCH($F22,온라인_반찬!$C$2:$C$587,0),7),"") | K22: =IFERROR(INDEX(온라인_반찬!$C$2:$I$587,MATCH($J22,온라인_반찬!$C$2:$C$587,0),7),"")
A23: 날짜
A24: 주차 | B24: 메뉴 | C24: 알레르기표기 | D24: 메뉴 | E24: 알레르기표기 | F24: 메뉴 | G24: 알레르기표기 | H24: 메뉴 | I24: 알레르기표기 | J24: 메뉴 | K24: 알레르기표기
A25: 3주 | B25: 친환경현미쌀밥 | C25: =IFERROR(INDEX(온라인_반찬!$C$2:$I$587,MATCH($B25,온라인_반찬!$C$2:$C$587,0),7),"") -> 0 | D25: 친환경귀리쌀밥 | E25: =IFERROR(INDEX(온라인_반찬!$C$2:$I$587,MATCH($D25,온라인_반찬!$C$2:$C$587,0),7),"") -> 0 | F25: 친환경찰흑미쌀밥 | G25: =IFERROR(INDEX(온라인_반찬!$C$2:$I$587,MATCH($F25,온라인_반찬!$C$2:$C$587,0),7),"") -> 0 | H25: 흰쌀밥 | I25: =IFERROR(INDEX(온라인_반찬!$C$2:$I$587,MATCH($H25,온라인_반찬!$C$2:$C$587,0),7),"") -> 0 | J25: 친환경찰보리쌀밥 | K25: =IFERROR(INDEX(온라인_반찬!$C$2:$I$587,MATCH($J25,온라인_반찬!$C$2:$C$587,0),7),"") -> 0
B26: 골든커리덮밥소스 | C26: =IFERROR(INDEX(온라인_반찬!$C$2:$I$587,MATCH($B26,온라인_반찬!$C$2:$C$587,0),7),"") -> .2.5.6.12.15.16.18. | D26: 춘장닭볶음 | E26: =IFERROR(INDEX(온라인_반찬!$C$2:$I$587,MATCH($D26,온라인_반찬!$C$2:$C$587,0),7),"") -> .5.15.21. | F26: 비프찹스테이크 | G26: =IFERROR(INDEX(온라인_반찬!$C$2:$I$587,MATCH($F26,온라인_반찬!$C$2:$C$587,0),7),"") -> .2.5.6.12.16.18.21. | H26: 돈채모닝글로리볶음 | I26: =IFERROR(INDEX(온라인_반찬!$C$2:$I$587,MATCH($H26,온라인_반찬!$C$2:$C$587,0),7),"") -> .5.6.10.21. | J26: 용가리치킨너겟 | K26: =IFERROR(INDEX(온라인_반찬!$C$2:$I$587,MATCH($J26,온라인_반찬!$C$2:$C$587,0),7),"") -> .1.2.5.6.15.16.
B27: 새우튀김 | C27: =IFERROR(INDEX(온라인_반찬!$C$2:$I$587,MATCH($B27,온라인_반찬!$C$2:$C$587,0),7),"") -> .1.5.6.9. | D27: 베이컨감자전 | E27: =IFERROR(INDEX(온라인_반찬!$C$2:$I$587,MATCH($D27,온라인_반찬!$C$2:$C$587,0),7),"") -> .5.6.10. | F27: 진미채 | G27: =IFERROR(INDEX(온라인_반찬!$C$2:$I$587,MATCH($F27,온라인_반찬!$C$2:$C$587,0),7),"") -> .1.5.21. | H27: 계란말이 | I27: =IFERROR(INDEX(온라인_반찬!$C$2:$I$587,MATCH($H27,온라인_반찬!$C$2:$C$587,0),7),"") -> .1.2.5.6.16.18. | J27: 문어모양소떡소떡 | K27: =IFERROR(INDEX(온라인_반찬!$C$2:$I$587,MATCH($J27,온라인_반찬!$C$2:$C$587,0),7),"") -> .5.6.10.12.15.16.21.
B28: 무나물 | C28: =IFERROR(INDEX(온라인_반찬!$C$2:$I$587,MATCH($B28,온라인_반찬!$C$2:$C$587,0),7),"") -> .5.21. | D28: 우엉조림 | E28: =IFERROR(INDEX(온라인_반찬!$C$2:$I$587,MATCH($D28,온라인_반찬!$C$2:$C$587,0),7),"") -> .5.21. | F28: 오이깨소스무침 | G28: =IFERROR(INDEX(온라인_반찬!$C$2:$I$587,MATCH($F28,온라인_반찬!$C$2:$C$587,0),7),"") -> .21. | H28: 김자반 | I28: =IFERROR(INDEX(온라인_반찬!$C$2:$I$587,MATCH($H28,온라인_반찬!$C$2:$C$587,0),7),"") -> .5.21.22. | J28: 카프레제SD | K28: =IFERROR(INDEX(온라인_반찬!$C$2:$I$587,MATCH($J28,온라인_반찬!$C$2:$C$587,0),7),"") -> .2.5.6.12.
B29: 배추김치 | C29: =IFERROR(INDEX(온라인_반찬!$C$2:$I$587,MATCH($B29,온라인_반찬!$C$2:$C$587,0),7),"") -> .9.12. | D29: 깍두기 | E29: =IFERROR(INDEX(온라인_반찬!$C$2:$I$587,MATCH($D29,온라인_반찬!$C$2:$C$587,0),7),"") -> .6.9. | F29: 백김치 | G29: =IFERROR(INDEX(온라인_반찬!$C$2:$I$587,MATCH($F29,온라인_반찬!$C$2:$C$587,0),7),"") -> 0 | H29: 깍두기 | I29: =IFERROR(INDEX(온라인_반찬!$C$2:$I$587,MATCH($H29,온라인_반찬!$C$2:$C$587,0),7),"") -> .6.9. | J29: 배추김치 | K29: =IFERROR(INDEX(온라인_반찬!$C$2:$I$587,MATCH($J29,온라인_반찬!$C$2:$C$587,0),7),"") -> .9.12.
B30: 콩나물된장국 | C30: =IFERROR(INDEX(온라인_반찬!$C$2:$I$587,MATCH($B30,온라인_반찬!$C$2:$C$587,0),7),"") -> .5. | D30: 모둠어묵국 | E30: =IFERROR(INDEX(온라인_반찬!$C$2:$I$587,MATCH($D30,온라인_반찬!$C$2:$C$587,0),7),"") -> .5.6. | F30: 시래기된장국 | G30: =IFERROR(INDEX(온라인_반찬!$C$2:$I$587,MATCH($F30,온라인_반찬!$C$2:$C$587,0),7),"") -> .5. | H30: 닭봉삼계탕 | I30: =IFERROR(INDEX(온라인_반찬!$C$2:$I$587,MATCH($H30,온라인_반찬!$C$2:$C$587,0),7),"") -> .5.16. | J30: 소고기미역국 | K30: =IFERROR(INDEX(온라인_반찬!$C$2:$I$587,MATCH($J30,온라인_반찬!$C$2:$C$587,0),7),"") -> .5.9.16. | M30: 0
C31: =IFERROR(INDEX(온라인_반찬!$C$2:$I$587,MATCH($B31,온라인_반찬!$C$2:$C$587,0),7),"") | E31: =IFERROR(INDEX(온라인_반찬!$C$2:$I$587,MATCH($D31,온라인_반찬!$C$2:$C$587,0),7),"") | G31: =IFERROR(INDEX(온라인_반찬!$C$2:$I$587,MATCH($F31,온라인_반찬!$C$2:$C$587,0),7),"") | I31: =IFERROR(INDEX(온라인_반찬!$C$2:$I$587,MATCH($H31,온라인_반찬!$C$2:$C$587,0),7),"") | K31: =IFERROR(INDEX(온라인_반찬!$C$2:$I$587,MATCH($J31,온라인_반찬!$C$2:$C$587,0),7),"")
C32: =IFERROR(INDEX(온라인_반찬!$C$2:$I$587,MATCH($B32,온라인_반찬!$C$2:$C$587,0),7),"") | G32: =IFERROR(INDEX(온라인_반찬!$C$2:$I$587,MATCH($F32,온라인_반찬!$C$2:$C$587,0),7),"") | K32: =IFERROR(INDEX(온라인_반찬!$C$2:$I$587,MATCH($J32,온라인_반찬!$C$2:$C$587,0),7),"")
A33: 날짜
A34: 주차 | B34: 메뉴 | C34: 알레르기표기 | D34: 메뉴 | E34: 알레르기표기 | F34: 메뉴 | G34: 알레르기표기 | H34: 메뉴 | I34: 알레르기표기 | J34: 메뉴 | K34: 알레르기표기
A35: 4주 | B35: 친환경현미쌀밥 | C35: =IFERROR(INDEX(온라인_반찬!$C$2:$I$587,MATCH($B35,온라인_반찬!$C$2:$C$587,0),7),"") -> 0 | D35: 친환경귀리쌀밥 | E35: =IFERROR(INDEX(온라인_반찬!$C$2:$I$587,MATCH($D35,온라인_반찬!$C$2:$C$587,0),7),"") -> 0 | F35: 친환경찰흑미쌀밥 | G35: =IFERROR(INDEX(온라인_반찬!$C$2:$I$587,MATCH($F35,온라인_반찬!$C$2:$C$587,0),7),"") -> 0 | H35: 흰쌀밥 | I35: =IFERROR(INDEX(온라인_반찬!$C$2:$I$587,MATCH($H35,온라인_반찬!$C$2:$C$587,0),7),"") -> 0 | J35: 친환경찰보리쌀밥 | K35: =IFERROR(INDEX(온라인_반찬!$C$2:$I$587,MATCH($J35,온라인_반찬!$C$2:$C$587,0),7),"") -> 0
B36: 목화솜탕수육 | C36: =IFERROR(INDEX(온라인_반찬!$C$2:$I$587,MATCH($B36,온라인_반찬!$C$2:$C$587,0),7),"") -> .1.5.6.10. | D36: 브로콜리닭볶음 | E36: =IFERROR(INDEX(온라인_반찬!$C$2:$I$587,MATCH($D36,온라인_반찬!$C$2:$C$587,0),7),"") -> .5.15.21. | F36: 광양식소불고기 | G36: =IFERROR(INDEX(온라인_반찬!$C$2:$I$587,MATCH($F36,온라인_반찬!$C$2:$C$587,0),7),"") -> .5.16.21. | H36: 돈사태찜 | I36: =IFERROR(INDEX(온라인_반찬!$C$2:$I$587,MATCH($H36,온라인_반찬!$C$2:$C$587,0),7),"") -> .5.6.10.18.19.21. | J36: 닭감자조림 | K36: =IFERROR(INDEX(온라인_반찬!$C$2:$I$587,MATCH($J36,온라인_반찬!$C$2:$C$587,0),7),"") -> .5.15.18.21.
B37: & 탕수소스 | C37: =IFERROR(INDEX(온라인_반찬!$C$2:$I$587,MATCH($B37,온라인_반찬!$C$2:$C$587,0),7),"") -> .5. | D37: 미니떡갈비 | E37: =IFERROR(INDEX(온라인_반찬!$C$2:$I$587,MATCH($D37,온라인_반찬!$C$2:$C$587,0),7),"") -> .5.6.10.16. | F37: 스팸케찹볶음 | G37: =IFERROR(INDEX(온라인_반찬!$C$2:$I$587,MATCH($F37,온라인_반찬!$C$2:$C$587,0),7),"") -> .5.10.12.21. | H37: 어묵채소볶음 | I37: =IFERROR(INDEX(온라인_반찬!$C$2:$I$587,MATCH($H37,온라인_반찬!$C$2:$C$587,0),7),"") -> .5.6.18.21. | J37: 저염표고강정 | K37: =IFERROR(INDEX(온라인_반찬!$C$2:$I$587,MATCH($J37,온라인_반찬!$C$2:$C$587,0),7),"") -> .1.5.6.18.21.
B38: 메추리알짜장볶이 | C38: =IFERROR(INDEX(온라인_반찬!$C$2:$I$587,MATCH($B38,온라인_반찬!$C$2:$C$587,0),7),"") -> .1.5.6.10.15.16. | D38: 덩근숙주나물 | E38: =IFERROR(INDEX(온라인_반찬!$C$2:$I$587,MATCH($D38,온라인_반찬!$C$2:$C$587,0),7),"") | F38: 연두부 | G38: =IFERROR(INDEX(온라인_반찬!$C$2:$I$587,MATCH($F38,온라인_반찬!$C$2:$C$587,0),7),"") -> .5. | H38: 크래미양배추SD | I38: =IFERROR(INDEX(온라인_반찬!$C$2:$I$587,MATCH($H38,온라인_반찬!$C$2:$C$587,0),7),"") -> .1.8.12. | J38: 소고기가지나물 | K38: =IFERROR(INDEX(온라인_반찬!$C$2:$I$587,MATCH($J38,온라인_반찬!$C$2:$C$587,0),7),"") -> .5.16.21.
B39: 감자채볶음 | C39: =IFERROR(INDEX(온라인_반찬!$C$2:$I$587,MATCH($B39,온라인_반찬!$C$2:$C$587,0),7),"") -> .5.21. | D39: 깍두기 | E39: =IFERROR(INDEX(온라인_반찬!$C$2:$I$587,MATCH($D39,온라인_반찬!$C$2:$C$587,0),7),"") -> .6.9. | F39: & 양념장 | G39: =IFERROR(INDEX(온라인_반찬!$C$2:$I$587,MATCH($F39,온라인_반찬!$C$2:$C$587,0),7),"") -> .5.21. | H39: 깍두기 | I39: =IFERROR(INDEX(온라인_반찬!$C$2:$I$587,MATCH($H39,온라인_반찬!$C$2:$C$587,0),7),"") -> .6.9. | J39: 배추김치 | K39: =IFERROR(INDEX(온라인_반찬!$C$2:$I$587,MATCH($J39,온라인_반찬!$C$2:$C$587,0),7),"") -> .9.12.
B40: 배추김치 | C40: =IFERROR(INDEX(온라인_반찬!$C$2:$I$587,MATCH($B40,온라인_반찬!$C$2:$C$587,0),7),"") -> .9.12. | D40: 소고기탕국 | E40: =IFERROR(INDEX(온라인_반찬!$C$2:$I$587,MATCH($D40,온라인_반찬!$C$2:$C$587,0),7),"") -> .5.16. | F40: 백김치 | G40: =IFERROR(INDEX(온라인_반찬!$C$2:$I$587,MATCH($F40,온라인_반찬!$C$2:$C$587,0),7),"") -> 0 | H40: 닭고기버섯국 | I40: =IFERROR(INDEX(온라인_반찬!$C$2:$I$587,MATCH($H40,온라인_반찬!$C$2:$C$587,0),7),"") -> .5.15. | J40: 전복소라미역국 | K40: =IFERROR(INDEX(온라인_반찬!$C$2:$I$587,MATCH($J40,온라인_반찬!$C$2:$C$587,0),7),"") -> .5.9.18.21.
...

Sheet 온라인_반찬
A1: No. | B1: 품목 | C1: 품명 | D1: 온라인(g) | E1: 급식(g) | F1: 온라인 중/대(EA) | G1: 급식(EA) | H1: 자재사용내역 | I1: 알러지표기 | K1: 상품코드 | L1: 출고량 (g 또는 수량) | M1: 로스율 (5%) | N1: 총생산량 (g 또는 수량) | O1: 급식 (g) | P1: 중 (g) | Q1: 대 (g) | R1: 단위 | S1: 급식 (EA) | T1: 중 (EA) | U1: 대 (EA) | V1: 단위 | W1: 상품코드 | X1: 상품명 M10 | Y1: 구매단위 (g) | Z1: 구매단위 (EA) | AA1: 발주 1인량 | AB1: (중) 1인량 | AC1: (대) 1인량 | AD1: 자재 Mix% | AE1: 상품코드 | AF1: 상품명 S10 | AG1: 발주 1인량 | AH1: (중) 1인량 | AI1: (대) 1인량 | AJ1: 자재 Mix% | AK1: 상품코드 | AL1: 상품명 S20 | AM1: 발주 1인량 | AN1: (중) 1인량 | AO1: (대) 1인량 | AP1: 자재 Mix%
A2: 1 | C2: 유부다시국 | H2: 유부[(대두:캐나다, 호주, 미국등), 대두유(대두:미국,프바질, 파라과이등)]21%, 건더기스프{볶음참께(인도산), 정제염(국산), 김조각(국산), 가쓰오브시(필리핀산)등]5%, 정제수, 마늘, 가스오우동소스, 소금 | I2: .5.21. | J2: 가스오우동소스(면사랑), 유부(이츠웰 슬라이스유부)
A3: 2 | C3: 올갱이미역국 | H3: 불린미역(국산)21%, 다슬기(국내산)2%, 마늘, 정제수, 국간장, 참치액, 소금 | I3: .5.9. | J3: 25g/30g
A4: 3 | C4: 북어콩나물국 | H4: 콩나물(콩:외국산)16% , 북어채(러시아산)5%, 두부(콩:미국,호주,캐나다등), 대파, 마늘, 참기름, 정제수, 소금 | I4: .5. | L4: 23450 | M4: 1172.5 | N4: 24622.5 | O4: =E4 -> 0 | P4: =D4 -> 0 | Q4: =D4 -> 0 | R4: g | S4: =E4 -> 0 | T4: =D4 -> 0 | U4: =D4 -> 0 | W4: 192872 | X4: =IFERROR(INDEX([1]Sheet1!$A$2:$X$1948,MATCH($W$2:$W$258,[1]Sheet1!$G$2:$G$1948,0),8),"") -> 소이원 콩나물(곱슬이_단채 4Kg/BOX) | Y4: 4000 | AA4: 25 | AB4: =T4*AD4 -> #DIV/0! | AC4: =U4*AD4 -> #DIV/0! | AD4: =AA4/E4 -> #DIV/0! | AE4: 313570 | AF4: =IFERROR(INDEX([1]Sheet1!$A$2:$X$1948,MATCH($AE$2:$AE$258,[1]Sheet1!$G$2:$G$1948,0),8),"") -> 프레시웨이 북어채(1Kg/EA) | AG4: 5 | AH4: =P4*AJ4 -> #DIV/0! | AI4: =Q4*AJ4 -> #DIV/0! | AJ4: =AG4/$E4 -> #DIV/0! | AL4: =IFERROR(INDEX([1]Sheet1!$A$2:$X$1948,MATCH($AK$2:$AK$258,[1]Sheet1!$G$2:$G$1948,0),8),"") -> 0 | AM4: 5 | AN4: =P4*AP4 -> #DIV/0! | AO4: =Q4*AP4 -> #DIV/0! | AP4: =AM4/$E4 -> #DIV/0!
A5: 4 | C5: 모둠어묵국 | H5: 무(국산)15%, 모둠어묵(어육:수입산)10%, 파, 마늘, 국간장, 멸치육수농축액, 정제수, 소금 | I5: .5.6. | J5: 종합어묵(사조대림)
A6: 5 | C6: 근대된장국 | H6: 근대(국산)22.8%, 양파(국산), 정제수, 된장, 대파, 마늘, 멸치육수농축액, 소금 | I6: .5. | J6: 40g / 55g | L6: 21960 | M6: 1098 | N6: 23058 | O6: =E6 -> 0 | P6: =D6 -> 0 | Q6: =D6 -> 0 | R6: g | S6: =E6 -> 0 | T6: =D6 -> 0 | U6: =D6 -> 0 | W6: 223306 | X6: =IFERROR(INDEX([1]Sheet1!$A$2:$X$1948,MATCH($W$2:$W$258,[1]Sheet1!$G$2:$G$1948,0),8),"") -> 냉동근대(IQF 1Kg/EA) | Y6: 1000 | AA6: 35 | AB6: =T6*AD6 -> #DIV/0! | AC6: =U6*AD6 -> #DIV/0! | AD6: =AA6/E6 -> #DIV/0! | AE6: 138570 | AF6: =IFERROR(INDEX([1]Sheet1!$A$2:$X$1948,MATCH($AE$2:$AE$258,[1]Sheet1!$G$2:$G$1948,0),8),"") -> 면사랑 멸치육수(1.8L_보급형 1.8Kg/EA) | AH6: =P6*AJ6 -> #DIV/0! | AI6: =Q6*AJ6 -> #DIV/0! | AJ6: =AG6/$E6 -> #DIV/0! | AL6: =IFERROR(INDEX([1]Sheet1!$A$2:$X$1948,MATCH($AK$2:$AK$258,[1]Sheet1!$G$2:$G$1948,0),8),"") -> 0
A7: 6 | C7: 오징어무국 | H7: 무(국산)20%, 오징어(미국산, 국산)5%, 양파, 대파, 마늘, 정제수, 멸치육수농축액, 국간장, 소금 | I7: .5.17.
A8: 7 | C8: 얼큰오징어무국 | H8: 무(국산)20%, 오징어(미국산, 국산)5%, 양파, 대파, 마늘, 정제수, 멸치육수농축액, 국간장, 고춧가루, 소금 | I8: .5.17.
A9: 8 | C9: 소고기샤브국 | H9: 소고기(호주산)12%, 알배추(국산)7%, 느타리(국산), 청경채(국산), 대파, 마늘, 간장, 정제수, 소금 | I9: .5.16.
A10: 9 | C10: 우삼겹된장찌개 | H10: 모둠채소(호박, 양파, 새송이:국산)20%, 두부(콩:미국,호주,캐나다등)8%, 우삼겹(미국산)3%, 파, 마늘, 된장, 멸치육수농축액, 정제수, 소금 | I10: .5.16. | O10: =E10 -> 0 | P10: =D10 -> 0 | Q10: =D10 -> 0 | R10: g | S10: =E10 -> 0 | T10: =D10 -> 0 | U10: =D10 -> 0 | W10: 204623 | X10: =IFERROR(INDEX([1]Sheet1!$A$2:$X$1948,MATCH($W$2:$W$258,[1]Sheet1!$G$2:$G$1948,0),8),"") -> 애호박(특품 인큐베이터 KG) | Y10: 1000 | AA10: 30 | AB10: =T10*AD10 -> #DIV/0! | AC10: =U10*AD10 -> #DIV/0! | AD10: =AA10/E10 -> #DIV/0! | AE10: 168257 | AF10: =IFERROR(INDEX([1]Sheet1!$A$2:$X$1948,MATCH($AE$2:$AE$258,[1]Sheet1!$G$2:$G$1948,0),8),"") -> 명품 판두부(찌개용 3Kg/EA) | AG10: 15 | AH10: =P10*AJ10 -> #DIV/0! | AI10: =Q10*AJ10 -> #DIV/0! | AJ10: =AG10/$E10 -> #DIV/0! | AL10: =IFERROR(INDEX([1]Sheet1!$A$2:$X$1948,MATCH($AK$2:$AK$258,[1]Sheet1!$G$2:$G$1948,0),8),"") -> 0
A11: 10 | C11: 부추계란국 | H11: 계란(국산)13%, 채소[양파, 당근, 부추:국산]10%, 정제수, 멸치육수농축액, 대파, 마늘, 소금 | I11: .1.5. | L11: 600 | M11: 30 | N11: 630 | O11: =E11 -> 0 | P11: =D11 -> 0 | Q11: =D11 -> 0 | R11: g | S11: =E11 -> 0 | T11: =D11 -> 0 | U11: =D11 -> 0 | W11: 193090 | X11: =IFERROR(INDEX([1]Sheet1!$A$2:$X$1948,MATCH($W$2:$W$258,[1]Sheet1!$G$2:$G$1948,0),8),"") -> 냉동감자(절단_3~4cm 1Kg/EA) | Y11: 1000 | AA11: 22 | AB11: =T11*AD11 -> #DIV/0! | AC11: =U11*AD11 -> #DIV/0! | AD11: =AA11/E11 -> #DIV/0! | AE11: 204623 | AF11: =IFERROR(INDEX([1]Sheet1!$A$2:$X$1948,MATCH($AE$2:$AE$258,[1]Sheet1!$G$2:$G$1948,0),8),"") -> 애호박(특품 인큐베이터 KG) | AH11: =P11*AJ11 -> #DIV/0! | AI11: =Q11*AJ11 -> #DIV/0! | AJ11: =AG11/$E11 -> #DIV/0! | AK11: 420010 | AL11: =IFERROR(INDEX([1]Sheet1!$A$2:$X$1948,MATCH($AK$2:$AK$258,[1]Sheet1!$G$2:$G$1948,0),8),"") -> 알로팜 계란(왕란_무항생제_68g*30입 2.04Kg/EA)
A12: 11 | C12: 순살동태국 | H12: 순살동태(러시아산)7.2%, 무(국산)13%,콩나물, 쑥갓, 양파, 대파, 마늘, 멸치육수농축액, 국간장, 소금 | I12: .5.9.10. | J12: 40g/50g
A13: 12 | C13: 소고기미역국 | H13: 불린미역(미역:국산)18.3%, 소고기(호주산)5%, 마늘, 정제수, 밥새우, 멸치육수농축액, 소금, 국간장 | I13: .5.9.16. | J13: 40g/50g 멸치육수농축액(면사랑)
A14: 13 | C14: 소고기무국 | H14: 무(국산)18.3%, 소고기(호주산)10.7%, 양파, 대파, 마늘, 정제수, 소금, 멸치육수농축액, 국간장, 후추 | I14: .5.16. | L14: 16590 | M14: 829.5 | N14: 17419.5 | O14: =E14 -> 0 | P14: =D14 -> 0 | Q14: =D14 -> 0 | R14: g | S14: =E14 -> 0 | T14: =D14 -> 0 | U14: =D14 -> 0 | W14: 145349 | X14: =IFERROR(INDEX([1]Sheet1!$A$2:$X$1948,MATCH($W$2:$W$258,[1]Sheet1!$G$2:$G$1948,0),8),"") -> 이츠웰 사골엑기스(1Kg/EA) | Y14: 1000 | AB14: =T14*AD14 -> #DIV/0! | AC14: =U14*AD14 -> #DIV/0! | AD14: =AA14/E14 -> #DIV/0! | AE14: 424285 | AF14: =IFERROR(INDEX([1]Sheet1!$A$2:$X$1948,MATCH($AE$2:$AE$258,[1]Sheet1!$G$2:$G$1948,0),8),"") -> 소양지(3*2*0.3cm_저지방 키즈용_국거리용 KG) | AH14: =P14*AJ14 -> #DIV/0! | AI14: =Q14*AJ14 -> #DIV/0! | AJ14: =AG14/$E14 -> #DIV/0! | AK14: 204418 | AL14: =IFERROR(INDEX([1]Sheet1!$A$2:$X$1948,MATCH($AK$2:$AK$258,[1]Sheet1!$G$2:$G$1948,0),8),"") -> 무우(특품 9~12개입 18Kg/BOX)
A15: 14 | C15: 얼큰소고기무국 | H15: 무(국산)18.3%, 소고기(호주산)10.7%, 양파, 대파, 마늘, 정제수, 소금, 고춧가루, 멸치육수농축액, 국간장, 후추 | I15: .5.16.
A16: 15 | C16: 맑은순두부국 | H16: 순두부(대두:수입산)15%, 호박, 파, 마늘, 새우젓(새우,소금:국산), 멸치육수농축액, 정제수, 소금 | I16: .5.9.
A17: 16 | C17: 소고기장국 | H17: 열갈이(국산)10%, 소고기(호주산)7%, 무(국산)5%, 콩나물(원료수입산)5%, 정제수, 된장, 대파, 마늘, 국간장, 멸치육수농축액, 소금 | I17: .5.16. | J17: 멸치육수농축액(면사랑)
A18: 17 | C18: 두부탕국 | H18: 두부(원료수입산)18%, 무(국산)10%,, 파, 마늘, 정제수, 멸치육수농축액, 국간장, 소금 | I18: .5. | J18: 멸치육수농축액(면사랑), 판두부(이츠웰)
A19: 18 | C19: 맑은미역국 | H19: 불린미역(국산)23%, 정제수, 참기름, 국간장, 밥새우, 멸치육수농축액, 마늘, 소금 | I19: .5.9. | L19: 2565 | M19: 128.25 | N19: 2693.25 | O19: =E19 -> 0 | P19: =D19 -> 0 | Q19: =D19 -> 0 | R19: g | S19: =E19 -> 0 | T19: =D19 -> 0 | U19: =D19 -> 0 | W19: 206631 | X19: =IFERROR(INDEX([1]Sheet1!$A$2:$X$1948,MATCH($W$2:$W$258,[1]Sheet1!$G$2:$G$1948,0),8),"") -> 냉동아욱(상품 1Kg/PAC) | Y19: 1000 | AA19: 32 | AB19: =T19*AD19 -> #DIV/0! | AC19: =U19*AD19 -> #DIV/0! | AD19: =AA19/E19 -> #DIV/0! | AE19: 313633 | AF19: =IFERROR(INDEX([1]Sheet1!$A$2:$X$1948,MATCH($AE$2:$AE$258,[1]Sheet1!$G$2:$G$1948,0),8),"") -> 현대푸드 두절건새우(중 1Kg/EA) | AH19: =P19*AJ19 -> #DIV/0! | AI19: =Q19*AJ19 -> #DIV/0! | AJ19: =AG19/$E19 -> #DIV/0! | AL19: =IFERROR(INDEX([1]Sheet1!$A$2:$X$1948,MATCH($AK$2:$AK$258,[1]Sheet1!$G$2:$G$1948,0),8),"") -> 0
A20: 19 | C20: 미소장국 | H20: 두부(콩:미국,호주,캐나다등)18%, 팽이버섯(국산)5%, 실파(국산), 정제수, 미소된장(국산), 멸치육수농축액, 소금 | I20: .5. | J20: 멸치육수농축액(면사랑)
A21: 20 | C21: 맑은콩나물국 | H21: 콩나물(콩:외국산)25%, 정제수, 국간장, 마늘, 대파, 멸치육수농축액, 소금 | I21: .5. | J21: 25g/35g
A22: 21 | C22: 하얀짬뽕국 | H22: 숙주(원료수입산)12%, 해산물(대왕오징어:페루산, 홍합.바지락.새우살:중국산)7%, 양파, 청경채, 파, 마늘, 정제수, 치킨스톡, 소금 | I22: .5.9.15.17.18. | L22: 1200 | M22: 60 | N22: 1260 | O22: =E22 -> 0 | P22: =D22 -> 0 | Q22: =D22 -> 0 | R22: g | S22: =E22 -> 0 | T22: =D22 -> 0 | U22: =D22 -> 0 | W22: 192872 | X22: =IFERROR(INDEX([1]Sheet1!$A$2:$X$1948,MATCH($W$2:$W$258,[1]Sheet1!$G$2:$G$1948,0),8),"") -> 소이원 콩나물(곱슬이_단채 4Kg/BOX) | AB22: =T22*AD22 -> #DIV/0! | AC22: =U22*AD22 -> #DIV/0! | AD22: =AA22/E22 -> #DIV/0! | AE22: 168257 | AF22: =IFERROR(INDEX([1]Sheet1!$A$2:$X$1948,MATCH($AE$2:$AE$258,[1]Sheet1!$G$2:$G$1948,0),8),"") -> 명품 판두부(찌개용 3Kg/EA) | AH22: =P22*AJ22 -> #DIV/0! | AI22: =Q22*AJ22 -> #DIV/0! | AJ22: =AG22/$E22 -> #DIV/0! | AL22: =IFERROR(INDEX([1]Sheet1!$A$2:$X$1948,MATCH($AK$2:$AK$258,[1]Sheet1!$G$2:$G$1948,0),8),"") -> 0
A23: 22 | C23: 짬뽕국 | H23: 숙주(원료수입산)12%, 해산물(대왕오징어:페루산, 홍합.바지락.새우살:중국산)7%, 양파, 청경채, 파, 마늘, 정제수, 고춧가루, 고추기름, 치킨스톡, 소금 | I23: .5.9.15.17.18.
A24: 23 | C24: 감자된장국 | H24: 감자(국산)20%, 양파, 파, 마늘, 멸치육수농축액, 된장, 정제수, 소금 | I24: .5.6.9.
A25: 24 | C25: 설렁탕 | H25: 소고기(호주산)14.3%, 사골육수 [잡뼈(한우), 사골(한우), 사골액기스 {정제수, 사골농축액17% (사골:호주산) 천일염}, 정제수], 생대파(국산), 후추, 소금 | I25: .5.16. | O25: =E25 -> 0 | P25: =D25 -> 0 | Q25: =D25 -> 0 | R25: g | S25: =E25 -> 0 | T25: =D25 -> 0 | U25: =D25 -> 0 | W25: 223307 | X25: =IFERROR(INDEX([1]Sheet1!$A$2:$X$1948,MATCH($W$2:$W$258,[1]Sheet1!$G$2:$G$1948,0),8),"") -> 냉동얼갈이(IQF 1Kg/EA) | Y25: 1000 | AA25: 42 | AB25: =T25*AD25 -> #DIV/0! | AC25: =U25*AD25 -> #DIV/0! | AD25: =AA25/E25 -> #DIV/0! | AE25: 145349 | AF25: =IFERROR(INDEX([1]Sheet1!$A$2:$X$1948,MATCH($AE$2:$AE$258,[1]Sheet1!$G$2:$G$1948,0),8),"") -> 이츠웰 사골엑기스(1Kg/EA) | AH25: =P25*AJ25 -> #DIV/0! | AI25: =Q25*AJ25 -> #DIV/0! | AJ25: =AG25/$E25 -> #DIV/0! | AL25: =IFERROR(INDEX([1]Sheet1!$A$2:$X$1948,MATCH($AK$2:$AK$258,[1]Sheet1!$G$2:$G$1948,0),8),"") -> 0
A26: 25 | C26: 유부미소국 | H26: 유부(원료수입산)10%, 팽이버섯(국산)2%, 미소된장(국내산), 정제수, 멸치육수농축액, 실파, 마늘, 소금 | I26: .5.
A27: 26 | C27: 전복소라미역국 | H27: 불린미역(국산)20%, 전복소라다이스[피뿔고동살(불가리아,터키,루마니아등)50%, 논우렁살(베트남산)30%, 전복살(말레이시아,인도네시아,중국 등)20%]5%, 정제수, 밥새우, 멸치육수농축액, 국간장, 참기름, 마늘, 소금 | I27: .5.9.18.21.
A28: 27 | C28: 조랭이떡국 | H28: 조랭이떡(쌀:수입산)25%, 소고기(호주산)3.5%, 계란지단(국산)1%, 양파, 대파, 마늘, 국간장, 정제수, 소금 | I28: .1.5.16. | O28: =E28 -> 0 | P28: =D28 -> 0 | Q28: =D28 -> 0 | R28: g | S28: =E28 -> 0 | T28: =D28 -> 0 | U28: =D28 -> 0 | W28: 192918 | X28: =IFERROR(INDEX([1]Sheet1!$A$2:$X$1948,MATCH($W$2:$W$258,[1]Sheet1!$G$2:$G$1948,0),8),"") -> 양배추(겉잎제거 KG) | Y28: 1000 | AA28: 35 | AB28: =T28*AD28 -> #DIV/0! | AC28: =U28*AD28 -> #DIV/0! | AD28: =AA28/E28 -> #DIV/0! | AE28: 424285 | AF28: =IFERROR(INDEX([1]Sheet1!$A$2:$X$1948,MATCH($AE$2:$AE$258,[1]Sheet1!$G$2:$G$1948,0),8),"") -> 소양지(3*2*0.3cm_저지방 키즈용_국거리용 KG) | AG28: 16 | AH28: =P28*AJ28 -> #DIV/0! | AI28: =Q28*AJ28 -> #DIV/0! | AJ28: =AG28/$E28 -> #DIV/0! | AL28: =IFERROR(INDEX([1]Sheet1!$A$2:$X$1948,MATCH($AK$2:$AK$258,[1]Sheet1!$G$2:$G$1948,0),8),"") -> 0
A29: 28 | C29: 소고기탕국 | H29: 무(국산)15%, 소고기(호주산)8%, 두부(원료수입산)5%, 양파, 대파, 마늘, 정제수, 멸치육수농축액, 국간장, 소금 | I29: .5.16. | J29: 40g/60g
A30: 29 | C30: 북어국 | H30: 북어채(러시아산)5%, 두부(원료수입산)12%, 무8%, 양파, 정제수, 대파, 마늘, 참기름, 국간장, 소금 | I30: .5.21. | L30: 2535 | M30: 126.75 | N30: 2661.75 | O30: =E30 -> 0 | P30: =D30 -> 0 | Q30: =D30 -> 0 | R30: g | S30: =E30 -> 0 | T30: =D30 -> 0 | U30: =D30 -> 0 | W30: 211037 | X30: =IFERROR(INDEX([1]Sheet1!$A$2:$X$1948,MATCH($W$2:$W$258,[1]Sheet1!$G$2:$G$1948,0),8),"") -> 느타리버섯(실속 균상 2Kg/EA) | Y30: 2000 | AA30: 23 | AB30: =T30*AD30 -> #DIV/0! | AC30: =U30*AD30 -> #DIV/0! | AD30: =AA30/E30 -> #DIV/0! | AE30: 205745 | AF30: =IFERROR(INDEX([1]Sheet1!$A$2:$X$1948,MATCH($AE$2:$AE$258,[1]Sheet1!$G$2:$G$1948,0),8),"") -> 총알새송이버섯(실속 2Kg/BOX) | AG30: 11 | AH30: =P30*AJ30 -> #DIV/0! | AI30: =Q30*AJ30 -> #DIV/0! | AJ30: =AG30/$E30 -> #DIV/0! | AL30: =IFERROR(INDEX([1]Sheet1!$A$2:$X$1948,MATCH($AK$2:$AK$258,[1]Sheet1!$G$2:$G$1948,0),8),"") -> 0
A31: 30 | C31: 순두부된장국 | H31: 순두부(콩:미국,캐나다,호주등)25%, 된장(국산), 파, 마늘, 정제수, 멸치육수농축액, 소금 | I31: .5. | O31: =E31 -> 0 | P31: =D31 -> 0 | Q31: =D31 -> 0 | R31: g | S31: =E31 -> 0 | T31: =D31 -> 0 | U31: =D31 -> 0 | W31: 193090 | X31: =IFERROR(INDEX([1]Sheet1!$A$2:$X$1948,MATCH($W$2:$W$258,[1]Sheet1!$G$2:$G$1948,0),8),"") -> 냉동감자(절단_3~4cm 1Kg/EA) | Y31: 1000 | AA31: 30 | AB31: =T31*AD31 -> #DIV/0! | AC31: =U31*AD31 -> #DIV/0! | AD31: =AA31/E31 -> #DIV/0! | AE31: 204964 | AF31: =IFERROR(INDEX([1]Sheet1!$A$2:$X$1948,MATCH($AE$2:$AE$258,[1]Sheet1!$G$2:$G$1948,0),8),"") -> 냉동표고버섯(슬라이스 1Kg/PAC) | AG31: 13 | AH31: =P31*AJ31 -> #DIV/0! | AI31: =Q31*AJ31 -> #DIV/0! | AJ31: =AG31/$E31 -> #DIV/0! | AL31: =IFERROR(INDEX([1]Sheet1!$A$2:$X$1948,MATCH($AK$2:$AK$258,[1]Sheet1!$G$2:$G$1948,0),8),"") -> 0 | AN31: =P31*AP31 -> #DIV/0! | AO31: =Q31*AP31 -> #DIV/0! | AP31: =AM31/$E31 -> #DIV/0!
A32: 31 | C32: 맑은닭곰탕 | H32: 닭고기(국산)12%, 무(국산)10%, 정제수, 파, 마늘, 소금 | I32: .5.16. | J32: 40g / 50g
A33: 32 | C33: 우거지된장국 | H33: 우거지(국산)17%, 두부(원료수입산)10.7%, 양파, 대파, 마늘, 된장, 정제수, 멸치육수농축액, 소금 | I33: .5.
A34: 33 | C34: 대파계란탕 | H34: 계란(국산)20%, 대파(국산)2%, 마늘, 멸치육수농축액, 정제수, 소금 | I34: .1.5. | J34: 멸치육수농축액(면사랑)
A35: 34 | C35: 게살계란탕 | H35: 계란(국산)18.7%, 게살(국산)3.5%, 팽이버섯, 파, 마늘, 멸치육수농축액, 정제수, 녹말가루, 소금, 참기름 | I35: .1.8.
A36: 35 | C36: 논우렁살된장찌개 | H36: 논우렁살(우렁:베트남산), 모둠채소(호박, 양파, 감자:국산)25%, 두부(콩:미국,호주,캐나다등)8%, 파, 마늘, 된장, 멸치육수농축액, 정제수, 소금 | I36: .5.
A37: 36 | C37: 순두부된장찌개 | H37: 모둠채소(호박, 양파, 감자:국산)20%, 순두부(콩:미국,호주,캐나다등)12%, 파, 마늘, 된장, 멸치육수농축액, 정제수, 소금 | I37: .5.
A38: 37 | C38: 호박잎된장찌개 | H38: 호박잎(국내산)5%, 모둠채소(호박, 양파, 감자:국산)20%, 두부(콩:미국,호주,캐나다등)8%, 파, 마늘, 된장, 멸치육수농축액, 정제수, 소금 | I38: .5.
C39: 꽃게된장찌개 | H39: 꽃게(중국산)18%, 모듬채소(호박,양파,감자:국산)12%, 두부(대두:외국산), 마늘, 된장, 멸치육수농축액, 정제수, 국간장, 소금 | I39: .5.8.
A40: 38 | C40: 콩나물된장국 | H40: 콩나물(콩:수입산)20%, 두부(콩:수입산)8%, 양파, 파, 마늘, 정제수, 된장, 소금 | I40: .5. | O40: =E40 -> 0 | P40: 120 | R40: g | S40: 2 | T40: 6 | U40: 10 | V40: 개 | W40: 127359 | X40: =IFERROR(INDEX([1]Sheet1!$A$2:$X$1948,MATCH($W$2:$W$258,[1]Sheet1!$G$2:$G$1948,0),8),"") -> 사조대림 사각잡채군만두(32±1개입 800g/EA) | Y40: 800 | Z40: 32 | AA40: 2 | AB40: =T40 -> 6 | AC40: =U40 -> 10 | AF40: =IFERROR(INDEX([1]Sheet1!$A$2:$X$1948,MATCH($AE$2:$AE$258,[1]Sheet1!$G$2:$G$1948,0),8),"") -> 0 | AH40: =P40*AJ40 -> #DIV/0! | AI40: =Q40*AJ40 -> #DIV/0! | AJ40: =AG40/$E40 -> #DIV/0! | AL40: =IFERROR(INDEX([1]Sheet1!$A$2:$X$1948,MATCH($AK$2:$AK$258,[1]Sheet1!$G$2:$G$1948,0),8),"") -> 0 | AN40: =P40*AP40 -> #DIV/0! | AO40: =Q40*AP40 -> #DIV/0! | AP40: =AM40/$E40 -> #DIV/0!
...

Sheet 01-02
B1: 2026-01-02(금) | M1: *한입해쉬브라운 : 9g(개당) | P1: *양송이떡갈비 : 1.5ea, 1.75, 2 | S1: *양배추당근라페 : 20g / 30g
B2: 출고일 | C2: 구분 | D2: 품명 | E2: 중량(g) | F2: 수량(장) | G2: 자재사용내역 | H2: 알러지 표기 | I2: 배송시점 | J2: 제공인원 | K2: 총생산량(Kg) | L2: 메 모 | M2: *샐러드 채소 : 15g, 20g ,25g | P2: *야채고기말이 : 1.1, 1.5, 1.5 | S2: *고구마튀김35g / 45g
B3: 중식 | C3: 밥 | D3: 친환경찰보리쌀밥 | E3: 140 | G3: =IFERROR(INDEX(온라인_반찬!$C$2:$H$594,MATCH($D3,온라인_반찬!$C$2:$C$594,0),6),"") -> 쌀(국산)90%, 찰보리(국산.친환경)5%, 정제수 | H3: =IFERROR(INDEX(온라인_반찬!$D$2:$J$587,MATCH($D3,온라인_반찬!$C$2:$C$587,0),6),"") -> 0 | I3: 2026-01-02 09:30~ | J3: 917 | K3: 132620 | L3: =IFERROR(INDEX(온라인_반찬!$C$2:$J$587,MATCH($D3,온라인_반찬!$C$2:$C$587,0),8),"") -> 0 | M3: *웨지감자 : 25g / 30g | O3: *어묵채구이:12g / 15g | S3: 한입새우튀김 : 30g / 35g / 45g (소스15g)
C4: 국 | D4: 볼어묵국 | E4: 150 | G4: =IFERROR(INDEX(온라인_반찬!$C$2:$H$594,MATCH($D4,온라인_반찬!$C$2:$C$594,0),6),"") -> 볼어묵[연육(:중국산, 베트남산)53.29%, 설탕, 밀가루(밀:미국산, 호주산), 정제소금(국산)]18%, 무(국산)7%, 양파, 대파, 마늘, 정제수, 국간장, 소금 | H4: =IFERROR(INDEX(온라인_반찬!$D$2:$J$587,MATCH($D4,온라인_반찬!$C$2:$C$587,0),6),"") -> .5.6. | I4: 2026-01-02 09:30~ | J4: 917 | K4: 133270 | L4: =IFERROR(INDEX(온라인_반찬!$C$2:$J$587,MATCH($D4,온라인_반찬!$C$2:$C$587,0),8),"") -> 볼어묵(이츠웰) | M4: *꼬마돈까스: 25g, 중구청 35g | P4: *족발:45g / 55g | S4: *갈비만두 : 성분표기 인당1개 / 식수 인당1.5개
C5: 메인 | D5: 소고기계란덮밥소스 | E5: 110 | G5: =IFERROR(INDEX(온라인_반찬!$C$2:$H$594,MATCH($D5,온라인_반찬!$C$2:$C$594,0),6),"") -> 소고기(미국산.호주산)45%, 계란(국내산)10%, 표고버섯(중국산)5%, 양파, 돈부리소스, 쯔유, 정제수, 소금, 전분 | H5: =IFERROR(INDEX(온라인_반찬!$D$2:$J$587,MATCH($D5,온라인_반찬!$C$2:$C$587,0),6),"") -> .1.2.5.6.16. | I5: 2026-01-02 09:30~ | J5: 917 | K5: 111030 | L5: =IFERROR(INDEX(온라인_반찬!$C$2:$J$587,MATCH($D5,온라인_반찬!$C$2:$C$587,0),8),"") -> 돈부리소스(가토코), 쯔유(이엔푸드) | M5: *오징어볼탕수 : 35g / 45g/ 70g 소스 : 20g | S5: *생선통살탕수 : 40g / 50g / 교사 70g, 소스 25g 개당 12g
C6: 반찬1 | D6: 갈비만두찜 | F6: 1 | G6: =IFERROR(INDEX(온라인_반찬!$C$2:$H$594,MATCH($D6,온라인_반찬!$C$2:$C$594,0),6),"") -> 돼지고기(국산)36.53%, 밀가루(밀:미국산.호주산), 양파(국산), 건무, 부추, 곤약, 돼지갈비살(국산)2.09%, 설탕, 갅방, 물엿, 마늘, 생강, 참기름, 후추, 대파 등 | H6: =IFERROR(INDEX(온라인_반찬!$D$2:$J$587,MATCH($D6,온라인_반찬!$C$2:$C$587,0),6),"") -> .2.5.6.10.16.21. | I6: 2026-01-02 09:30~ | J6: 917 | K6: 1363.8 | L6: =IFERROR(INDEX(온라인_반찬!$C$2:$J$587,MATCH($D6,온라인_반찬!$C$2:$C$587,0),8),"") -> 달콤한갈비만두(한만두) 개당25g | M6: *표고강정 : 30g(35g) | P6: *훈제오리 : 40g / 50g | S6: *해물전:1000680205(삼성웰스토리)
C7: 반찬2 | D7: 오이부추무침 | E7: 25 | G7: =IFERROR(INDEX(온라인_반찬!$C$2:$H$594,MATCH($D7,온라인_반찬!$C$2:$C$594,0),6),"") -> 오이(국산)87%, 부추(국산)3%, 파, 마늘, 고추가루, 소금, 설탕, 식초, 참깨 | H7: =IFERROR(INDEX(온라인_반찬!$D$2:$J$587,MATCH($D7,온라인_반찬!$C$2:$C$587,0),6),"") -> .5.21. | I7: 2026-01-02 09:30~ | J7: 917 | K7: 26195 | L7: =IFERROR(INDEX(온라인_반찬!$C$2:$J$587,MATCH($D7,온라인_반찬!$C$2:$C$587,0),8),"") -> 0 | M7: *탕수육40g(중구청50g) ,소스25g | P7: *마카로니.콘샐러드 : 30g | S7: *통등심돈까스:50g / 소스 25g
C8: 반찬3 | D8: 배추김치 | E8: 25 | G8: =IFERROR(INDEX(온라인_반찬!$C$2:$H$594,MATCH($D8,온라인_반찬!$C$2:$C$594,0),6),"") -> 절임배추64.0%[배추(국산),무(국산),종가김치전용풀(쌀:국산)], 토마토페이스트(토마토:미국산)2.7%,[멸치액젓, 양파,다시마농축액,고춧가루,마늘,대파,새우액젓,김치유산균발효액,생강양념,호화쌀혼합분말]국산 | H8: =IFERROR(INDEX(온라인_반찬!$D$2:$J$587,MATCH($D8,온라인_반찬!$C$2:$C$587,0),6),"") -> .9.12. | I8: 2026-01-02 09:30~ | J8: 917 | K8: 23132.5 | L8: =IFERROR(INDEX(온라인_반찬!$C$2:$J$587,MATCH($D8,온라인_반찬!$C$2:$C$587,0),8),"") -> 토마토김치(종가집) | M8: *건두부무침 : 25g / 35g | P8: *파르펠레냉파스타:30g | S8: *족발부추무침 : 45g, 55g
C9: 보존식 | G9: 서빙고초 병설 : 도시락김 ( 6명 / 6봉) 포도클럽 : 백김치 ( 62명 / 1,813g ) | J9: 1 | K9: 0.25 | M9: 132620 | N9: 133270 | O9: 111030 | P9: 1363.8 | Q9: 26195 | R9: 23132.5 | S9: 23132.5
B10: 강서폴리 소풍 | C10: 밥 | D10: 조미밥 | E10: 140 | G10: =IFERROR(INDEX(온라인_반찬!$C$2:$H$594,MATCH($D10,온라인_반찬!$C$2:$C$594,0),6),"") -> 밥(쌀:국산)95%, 후리카케[볶은참깨(참깨:인도산), 밀소맥볼(밀:미국,호주산),조각김(김:국산), 양조간장], 맛소금, 참기름 | H10: =IFERROR(INDEX(온라인_반찬!$D$2:$J$587,MATCH($D10,온라인_반찬!$C$2:$C$587,0),6),"") -> .5.21. | I10: 2026-01-02 09:30~ | J10: 99 | K10: 15620 | L10: =IFERROR(INDEX(온라인_반찬!$C$2:$J$587,MATCH($D10,온라인_반찬!$C$2:$C$587,0),8),"") -> 0
C11: 반찬1 | D11: 순살치킨 | E11: 60 | G11: =IFERROR(INDEX(온라인_반찬!$C$2:$H$594,MATCH($D11,온라인_반찬!$C$2:$C$594,0),6),"") -> 순살치킨[닭고기(닭다리살:브라질산)64.76%,밀가루(밀:호주산,미국산),옥수수전분(옥수수:외국산), 대두유] | H11: =IFERROR(INDEX(온라인_반찬!$D$2:$J$587,MATCH($D11,온라인_반찬!$C$2:$C$587,0),6),"") -> .1.2.5.6.15.16. | I11: 2026-01-02 09:30~ | J11: 99 | K11: 7305 | L11: =IFERROR(INDEX(온라인_반찬!$C$2:$J$587,MATCH($D11,온라인_반찬!$C$2:$C$587,0),8),"") -> 순살치킨가라아게(하림)
C12: 반찬2 | D12: 새우관자딤섬 | F12: 1 | G12: =IFERROR(INDEX(온라인_반찬!$C$2:$H$594,MATCH($D12,온라인_반찬!$C$2:$C$594,0),6),"") -> 딤섬[(새우살36.62%, 정제수, 밀전분 11.47%, 타피오카전분 7.94%, 관자 5.64%, 대두유)원산지: 베트남산] | H12: =IFERROR(INDEX(온라인_반찬!$D$2:$J$587,MATCH($D12,온라인_반찬!$C$2:$C$587,0),6),"") -> .5.6.9.18. | I12: 2026-01-02 09:30~ | J12: 111 | K12: 108 | L12: =IFERROR(INDEX(온라인_반찬!$C$2:$J$587,MATCH($D12,온라인_반찬!$C$2:$C$587,0),8),"") -> 관자쇼마이(세미원푸드)
C13: 반찬3 | D13: 미니츄러스 | F13: 2 | G13: 츄러스용믹스[밀가루(밀:호주산.미국산.캐나다산), 소맥전분(외국산), 콩기름(콩(외국산), 찹쌀가루 | H13: .1.5.6. | I13: 2026-01-02 09:30~ | J13: 99 | K13: 226 | L13: =IFERROR(INDEX(온라인_반찬!$C$2:$J$587,MATCH($D13,온라인_반찬!$C$2:$C$587,0),8),"")
C14: 반찬4 | D14: 과일 | E14: 30 | G14: 샤인머스켓(국내산) | H14: =IFERROR(INDEX(온라인_반찬!$D$2:$J$587,MATCH($D14,온라인_반찬!$C$2:$C$587,0),6),"") | I14: 2026-01-02 09:30~ | J14: 99 | K14: 3415 | L14: =IFERROR(INDEX(온라인_반찬!$C$2:$J$587,MATCH($D14,온라인_반찬!$C$2:$C$587,0),8),"")
C15: 보존식 | F15: 1 | J15: 1 | K15: 0.25
B16: 중구돌봄 석식 | C16: 밥 | D16: 친환경찰보리쌀밥 | E16: 150 | G16: =IFERROR(INDEX(온라인_반찬!$C$2:$H$594,MATCH($D16,온라인_반찬!$C$2:$C$594,0),6),"") -> 쌀(국산)90%, 찰보리(국산.친환경)5%, 정제수 | H16: =IFERROR(INDEX(온라인_반찬!$D$2:$J$587,MATCH($D16,온라인_반찬!$C$2:$C$587,0),6),"") -> 0 | I16: 2026-01-02 14:30~ | J16: 49 | K16: 7800 | L16: =IFERROR(INDEX(온라인_반찬!$C$2:$J$587,MATCH($D16,온라인_반찬!$C$2:$C$587,0),8),"") -> 0 | M16: *영양찜닭:85g / 95g | P16: *소고기가지볶음 : 30g | S16: *춘장닭불고기 : 70g / 80g
C17: 국 | D17: 볼어묵국 | E17: 160 | G17: =IFERROR(INDEX(온라인_반찬!$C$2:$H$594,MATCH($D17,온라인_반찬!$C$2:$C$594,0),6),"") -> 볼어묵[연육(:중국산, 베트남산)53.29%, 설탕, 밀가루(밀:미국산, 호주산), 정제소금(국산)]18%, 무(국산)7%, 양파, 대파, 마늘, 정제수, 국간장, 소금 | H17: =IFERROR(INDEX(온라인_반찬!$D$2:$J$587,MATCH($D17,온라인_반찬!$C$2:$C$587,0),6),"") -> .5.6. | I17: 2026-01-02 14:30~ | J17: 49 | K17: 8160 | L17: =IFERROR(INDEX(온라인_반찬!$C$2:$J$587,MATCH($D17,온라인_반찬!$C$2:$C$587,0),8),"") -> 볼어묵(이츠웰) | M17: *미트볼 : 개당10g | P17: *삼색소고기소보로 : 50g / 70g | S17: *훈제오리잡채 : 55g / 70g
C18: 메인 | D18: 소고기계란덮밥소스 | E18: 120 | G18: =IFERROR(INDEX(온라인_반찬!$C$2:$H$594,MATCH($D18,온라인_반찬!$C$2:$C$594,0),6),"") -> 소고기(미국산.호주산)45%, 계란(국내산)10%, 표고버섯(중국산)5%, 양파, 돈부리소스, 쯔유, 정제수, 소금, 전분 | H18: =IFERROR(INDEX(온라인_반찬!$D$2:$J$587,MATCH($D18,온라인_반찬!$C$2:$C$587,0),6),"") -> .1.2.5.6.16. | I18: 2026-01-02 14:30~ | J18: 49 | K18: 6370 | L18: =IFERROR(INDEX(온라인_반찬!$C$2:$J$587,MATCH($D18,온라인_반찬!$C$2:$C$587,0),8),"") -> 돈부리소스(가토코), 쯔유(이엔푸드)
C19: 반찬1 | D19: 갈비만두찜 | F19: 2 | G19: =IFERROR(INDEX(온라인_반찬!$C$2:$H$594,MATCH($D19,온라인_반찬!$C$2:$C$594,0),6),"") -> 돼지고기(국산)36.53%, 밀가루(밀:미국산.호주산), 양파(국산), 건무, 부추, 곤약, 돼지갈비살(국산)2.09%, 설탕, 갅방, 물엿, 마늘, 생강, 참기름, 후추, 대파 등 | H19: =IFERROR(INDEX(온라인_반찬!$D$2:$J$587,MATCH($D19,온라인_반찬!$C$2:$C$587,0),6),"") -> .2.5.6.10.16.21. | I19: 2026-01-02 14:30~ | J19: 49 | K19: 107.8 | L19: =IFERROR(INDEX(온라인_반찬!$C$2:$J$587,MATCH($D19,온라인_반찬!$C$2:$C$587,0),8),"") -> 달콤한갈비만두(한만두) 개당25g
C20: 반찬2 | D20: 오이부추무침 | E20: 35 | G20: =IFERROR(INDEX(온라인_반찬!$C$2:$H$594,MATCH($D20,온라인_반찬!$C$2:$C$594,0),6),"") -> 오이(국산)87%, 부추(국산)3%, 파, 마늘, 고추가루, 소금, 설탕, 식초, 참깨 | H20: =IFERROR(INDEX(온라인_반찬!$D$2:$J$587,MATCH($D20,온라인_반찬!$C$2:$C$587,0),6),"") -> .5.21. | I20: 2026-01-02 14:30~ | J20: 49 | K20: 1715 | L20: =IFERROR(INDEX(온라인_반찬!$C$2:$J$587,MATCH($D20,온라인_반찬!$C$2:$C$587,0),8),"") -> 0
C21: 반찬3 | D21: 배추김치 | E21: 35 | G21: =IFERROR(INDEX(온라인_반찬!$C$2:$H$594,MATCH($D21,온라인_반찬!$C$2:$C$594,0),6),"") -> 절임배추64.0%[배추(국산),무(국산),종가김치전용풀(쌀:국산)], 토마토페이스트(토마토:미국산)2.7%,[멸치액젓, 양파,다시마농축액,고춧가루,마늘,대파,새우액젓,김치유산균발효액,생강양념,호화쌀혼합분말]국산 | H21: =IFERROR(INDEX(온라인_반찬!$D$2:$J$587,MATCH($D21,온라인_반찬!$C$2:$C$587,0),6),"") -> .9.12. | I21: 2026-01-02 14:30~ | J21: 49 | K21: 1715 | L21: =IFERROR(INDEX(온라인_반찬!$C$2:$J$587,MATCH($D21,온라인_반찬!$C$2:$C$587,0),8),"") -> 토마토김치(종가집)
C22: 신당꿈 특식 | D22: 뿌링클치킨 | E22: 80 | G22: =IFERROR(INDEX(온라인_반찬!$C$2:$H$594,MATCH($D22,온라인_반찬!$C$2:$C$594,0),6),"") -> 순살치킨[닭고기(닭다리살:브라질산)64.76%,밀가루(밀:호주산,미국산),옥수수전분(옥수수:외국산), 대두유]95%, 치즈시즈닝[(치즈혼합분말:미국산,호주산)15.58%,(스트롱체다치즈분말:덴마크산)0.5%]5% | H22: =IFERROR(INDEX(온라인_반찬!$D$2:$J$587,MATCH($D22,온라인_반찬!$C$2:$C$587,0),6),"") -> .1.2.5.6.15. | I22: 2026-01-02 14:30~ | J22: 28 | K22: 2580 | L22: =IFERROR(INDEX(온라인_반찬!$C$2:$J$587,MATCH($D22,온라인_반찬!$C$2:$C$587,0),8),"") -> 치즈시즈닝(상상푸드)
C23: 보존식 | J23: 1 | K23: 0.25

Sheet 01-05
B1: 2026-01-05(월) | M1: *한입해쉬브라운 : 9g(개당) | P1: *양송이떡갈비 : 1.5ea, 1.75, 2 | S1: *양배추당근라페 : 20g / 30g
B2: 출고일 | C2: 구분 | D2: 품명 | E2: 중량(g) | F2: 수량(장) | G2: 자재사용내역 | H2: 알러지 표기 | I2: 배송시점 | J2: 제공인원 | K2: 총생산량(Kg) | L2: 메 모 | M2: *샐러드 채소 : 15g, 20g ,25g | P2: *야채고기말이 : 1.1, 1.5, 1.5 | S2: *고구마튀김35g / 45g
B3: 중식 | C3: 밥 | D3: 친환경현미쌀밥 | E3: 140 | G3: =IFERROR(INDEX(온라인_반찬!$C$2:$H$594,MATCH($D3,온라인_반찬!$C$2:$C$594,0),6),"") -> 쌀(국산)90%, 현미(국산.친환경)5%, 정제수 | H3: =IFERROR(INDEX(온라인_반찬!$D$2:$J$587,MATCH($D3,온라인_반찬!$C$2:$C$587,0),6),"") -> 0 | I3: 2026-01-05 09:30~ | J3: 2361 | K3: 354085 | L3: =IFERROR(INDEX(온라인_반찬!$C$2:$J$587,MATCH($D3,온라인_반찬!$C$2:$C$587,0),8),"") -> 0 | M3: *웨지감자 : 25g / 30g | O3: *어묵채구이:12g / 15g | S3: 한입새우튀김 : 30g / 35g / 45g (소스15g)
C4: 국 | D4: 소고기무국 | E4: 150 | G4: =IFERROR(INDEX(온라인_반찬!$C$2:$H$594,MATCH($D4,온라인_반찬!$C$2:$C$594,0),6),"") -> 무(국산)18.3%, 소고기(호주산)10.7%, 양파, 대파, 마늘, 정제수, 소금, 멸치육수농축액, 국간장, 후추 | H4: =IFERROR(INDEX(온라인_반찬!$D$2:$J$587,MATCH($D4,온라인_반찬!$C$2:$C$587,0),6),"") -> .5.16. | I4: 2026-01-05 09:30~ | J4: 2361 | K4: 361195 | L4: =IFERROR(INDEX(온라인_반찬!$C$2:$J$587,MATCH($D4,온라인_반찬!$C$2:$C$587,0),8),"") -> 0 | M4: *꼬마돈까스: 25g, 중구청 35g | P4: *족발:45g / 55g | S4: *갈비만두 : 성분표기 인당1개 / 식수 인당1.5개
C5: 메인 | D5: 생선까스 | F5: 1 | G5: =IFERROR(INDEX(온라인_반찬!$C$2:$H$594,MATCH($D5,온라인_반찬!$C$2:$C$594,0),6),"") -> 생선통살까스 [민대구(한국산)50%, 빵가루, 정제수 ,쇼트닝, 소금]95%, 대두유 | H5: =IFERROR(INDEX(온라인_반찬!$D$2:$J$587,MATCH($D5,온라인_반찬!$C$2:$C$587,0),6),"") -> 1.5. | I5: 2026-01-05 09:30~ | J5: 2361 | K5: 2696.6 | L5: =IFERROR(INDEX(온라인_반찬!$C$2:$J$587,MATCH($D5,온라인_반찬!$C$2:$C$587,0),8),"") -> 이츠웰 흰살생선까스 | M5: *오징어볼탕수 : 35g / 45g/ 70g 소스 : 20g | S5: *생선통살탕수 : 40g / 50g / 교사 70g, 소스 25g 개당 12g
D6: & 타르타르소스 | E6: 10 | G6: =IFERROR(INDEX(온라인_반찬!$C$2:$H$594,MATCH($D6,온라인_반찬!$C$2:$C$594,0),6),"") -> 타르타르소스(시판용)85%, 마요네즈10%, 파인애플(청크)5% | H6: =IFERROR(INDEX(온라인_반찬!$D$2:$J$587,MATCH($D6,온라인_반찬!$C$2:$C$587,0),6),"") -> .1.5.19. | I6: 2026-01-05 09:30~ | J6: 2361 | K6: 25260 | L6: =IFERROR(INDEX(온라인_반찬!$C$2:$J$587,MATCH($D6,온라인_반찬!$C$2:$C$587,0),8),"") -> 타르타르드레싱(쉐프솔루션), 파인애플 청크(이츠웰)
C7: 반찬1 | D7: 라구숏파스타 | E7: 35 | G7: =IFERROR(INDEX(온라인_반찬!$C$2:$H$594,MATCH($D7,온라인_반찬!$C$2:$C$594,0),6),"") -> 푸실리(듀럼밀:터키산)60%, 양파, 피망, 양송이, 라구소스{토마토페이스트(토마토:미국산), 소고기(호주산),돼지고기(국산)], 올리브유, 파슬리가루 | H7: =IFERROR(INDEX(온라인_반찬!$D$2:$J$587,MATCH($D7,온라인_반찬!$C$2:$C$587,0),6),"") -> .5.6.10.12.15.16. | I7: 2026-01-05 09:30~ | J7: 2361 | K7: 92377.5 | L7: =IFERROR(INDEX(온라인_반찬!$C$2:$J$587,MATCH($D7,온라인_반찬!$C$2:$C$587,0),8),"") -> 미트소스(이츠웰) | M7: *표고강정 : 30g(35g) | P7: *훈제오리 : 40g / 50g | S7: *해물전:1000680205(삼성웰스토리)
C8: 반찬2 | D8: 단호박샐러드 | E8: 40 | G8: =IFERROR(INDEX(온라인_반찬!$C$2:$H$594,MATCH($D8,온라인_반찬!$C$2:$C$594,0),6),"") -> 단호박(중국산)66.6%, 샐러드베이스13.8%[난황(국내산), 대두유(대두:외국산), 양조식초 등], 당근(중국산), 물엿, 정제수, 가쓰오브시엑기스, 설탕 등 | H8: =IFERROR(INDEX(온라인_반찬!$D$2:$J$587,MATCH($D8,온라인_반찬!$C$2:$C$587,0),6),"") -> .1.5. | I8: 2026-01-05 09:30~ | J8: 2361 | K8: 92212.5 | L8: =IFERROR(INDEX(온라인_반찬!$C$2:$J$587,MATCH($D8,온라인_반찬!$C$2:$C$587,0),8),"") -> 단호박샐러드(이츠웰) | M8: *탕수육40g(중구청50g) ,소스25g | P8: *마카로니.콘샐러드 : 30g | S8: *통등심돈까스:50g / 소스 25g
C9: 반찬3 | D9: 배추김치 | E9: 25 | G9: =IFERROR(INDEX(온라인_반찬!$C$2:$H$594,MATCH($D9,온라인_반찬!$C$2:$C$594,0),6),"") -> 절임배추64.0%[배추(국산),무(국산),종가김치전용풀(쌀:국산)], 토마토페이스트(토마토:미국산)2.7%,[멸치액젓, 양파,다시마농축액,고춧가루,마늘,대파,새우액젓,김치유산균발효액,생강양념,호화쌀혼합분말]국산 | H9: =IFERROR(INDEX(온라인_반찬!$D$2:$J$587,MATCH($D9,온라인_반찬!$C$2:$C$587,0),6),"") -> .9.12. | I9: 2026-01-05 09:30~ | J9: 2361 | K9: 63120 | L9: =IFERROR(INDEX(온라인_반찬!$C$2:$J$587,MATCH($D9,온라인_반찬!$C$2:$C$587,0),8),"") -> 토마토김치(종가집) | M9: *건두부무침 : 25g / 35g | P9: *파르펠레냉파스타:30g | S9: *족발부추무침 : 45g, 55g
C10: 보존식 | G10: 포도클럽 : 백김치 ( 67명 / 1,963g ) 서빙고초 병설 : 도시락김 ( 6명 / 6봉 ) | J10: 1 | K10: 0.25
B11: 글로벌 리더스 . 석식 | C11: 밥 | D11: 친환경현미쌀밥 | E11: 150 | G11: =IFERROR(INDEX(온라인_반찬!$C$2:$H$594,MATCH($D11,온라인_반찬!$C$2:$C$594,0),6),"") -> 쌀(국산)90%, 현미(국산.친환경)5%, 정제수 | H11: =IFERROR(INDEX(온라인_반찬!$D$2:$J$587,MATCH($D11,온라인_반찬!$C$2:$C$587,0),6),"") -> 0 | I11: 2026-01-05 14:30~ | J11: 72 | K11: 7800 | L11: =IFERROR(INDEX(온라인_반찬!$C$2:$J$587,MATCH($D11,온라인_반찬!$C$2:$C$587,0),8),"") -> 0 | M11: *영양찜닭:85g / 95g | P11: *소고기가지볶음 : 30g | S11: *춘장닭불고기 : 70g / 80g
C12: 국 | D12: 얼큰소고기무국 | E12: 160 | G12: =IFERROR(INDEX(온라인_반찬!$C$2:$H$594,MATCH($D12,온라인_반찬!$C$2:$C$594,0),6),"") -> 무(국산)18.3%, 소고기(호주산)10.7%, 양파, 대파, 마늘, 정제수, 소금, 고춧가루, 멸치육수농축액, 국간장, 후추 | H12: =IFERROR(INDEX(온라인_반찬!$D$2:$J$587,MATCH($D12,온라인_반찬!$C$2:$C$587,0),6),"") -> .5.16. | I12: 2026-01-05 14:30~ | J12: 72 | K12: 8160 | L12: =IFERROR(INDEX(온라인_반찬!$C$2:$J$587,MATCH($D12,온라인_반찬!$C$2:$C$587,0),8),"") -> 0 | M12: *미트볼 : 개당10g | P12: *삼색소고기소보로 : 50g / 70g | S12: *훈제오리잡채 : 55g / 70g
C13: 메인 | D13: 순살치킨 | E13: 80 | G13: =IFERROR(INDEX(온라인_반찬!$C$2:$H$594,MATCH($D13,온라인_반찬!$C$2:$C$594,0),6),"") -> 순살치킨[닭고기(닭다리살:브라질산)64.76%,밀가루(밀:호주산,미국산),옥수수전분(옥수수:외국산), 대두유] | H13: =IFERROR(INDEX(온라인_반찬!$D$2:$J$587,MATCH($D13,온라인_반찬!$C$2:$C$587,0),6),"") -> .1.2.5.6.15.16. | I13: 2026-01-05 14:30~ | J13: 72 | K13: 6504 | L13: =IFERROR(INDEX(온라인_반찬!$C$2:$J$587,MATCH($D13,온라인_반찬!$C$2:$C$587,0),8),"") -> 순살치킨가라아게(하림)
C14: 반찬1 | D14: 라구숏파스타 | E14: 40 | G14: =IFERROR(INDEX(온라인_반찬!$C$2:$H$594,MATCH($D14,온라인_반찬!$C$2:$C$594,0),6),"") -> 푸실리(듀럼밀:터키산)60%, 양파, 피망, 양송이, 라구소스{토마토페이스트(토마토:미국산), 소고기(호주산),돼지고기(국산)], 올리브유, 파슬리가루 | H14: =IFERROR(INDEX(온라인_반찬!$D$2:$J$587,MATCH($D14,온라인_반찬!$C$2:$C$587,0),6),"") -> .5.6.10.12.15.16. | I14: 2026-01-05 14:30~ | J14: 72 | K14: 2960 | L14: =IFERROR(INDEX(온라인_반찬!$C$2:$J$587,MATCH($D14,온라인_반찬!$C$2:$C$587,0),8),"") -> 미트소스(이츠웰)
C15: 반찬2 | D15: 단호박샐러드 | E15: 40 | G15: =IFERROR(INDEX(온라인_반찬!$C$2:$H$594,MATCH($D15,온라인_반찬!$C$2:$C$594,0),6),"") -> 단호박(중국산)66.6%, 샐러드베이스13.8%[난황(국내산), 대두유(대두:외국산), 양조식초 등], 당근(중국산), 물엿, 정제수, 가쓰오브시엑기스, 설탕 등 | H15: =IFERROR(INDEX(온라인_반찬!$D$2:$J$587,MATCH($D15,온라인_반찬!$C$2:$C$587,0),6),"") -> .1.5. | I15: 2026-01-05 14:30~ | J15: 72 | K15: 2960 | L15: =IFERROR(INDEX(온라인_반찬!$C$2:$J$587,MATCH($D15,온라인_반찬!$C$2:$C$587,0),8),"") -> 단호박샐러드(이츠웰)
C16: 반찬3 | D16: 배추김치 | E16: 35 | G16: =IFERROR(INDEX(온라인_반찬!$C$2:$H$594,MATCH($D16,온라인_반찬!$C$2:$C$594,0),6),"") -> 절임배추64.0%[배추(국산),무(국산),종가김치전용풀(쌀:국산)], 토마토페이스트(토마토:미국산)2.7%,[멸치액젓, 양파,다시마농축액,고춧가루,마늘,대파,새우액젓,김치유산균발효액,생강양념,호화쌀혼합분말]국산 | H16: =IFERROR(INDEX(온라인_반찬!$D$2:$J$587,MATCH($D16,온라인_반찬!$C$2:$C$587,0),6),"") -> .9.12. | I16: 2026-01-05 14:30~ | J16: 72 | K16: 2220 | L16: =IFERROR(INDEX(온라인_반찬!$C$2:$J$587,MATCH($D16,온라인_반찬!$C$2:$C$587,0),8),"") -> 토마토김치(종가집)
C17: 신당꿈 특식 | D17: 훈제오리볶음 | E17: 80 | G17: =IFERROR(INDEX(온라인_반찬!$C$2:$H$594,MATCH($D17,온라인_반찬!$C$2:$C$594,0),6),"") -> 훈제오리{(오리육97.26%, 자일리톨, 소금, 대두단백, 양파분, 마늘분, 생강분, 로즈마리분말, 참기름, 후추)중국산)70%, 새송이버섯(국산), 양파, 당근, 파, 마늘, 굴소스, 소금, 참기름, 참깨 | H17: =IFERROR(INDEX(온라인_반찬!$D$2:$J$587,MATCH($D17,온라인_반찬!$C$2:$C$587,0),6),"") -> .1.5.6.10.18.21. | I17: 2026-01-05 14:30~ | J17: 28 | K17: 2580 | L17: =IFERROR(INDEX(온라인_반찬!$C$2:$J$587,MATCH($D17,온라인_반찬!$C$2:$C$587,0),8),"") -> 훈제오리(에스에프)
C18: 보존식 | J18: 1 | K18: 0.25
B19: 강서폴리 소풍 | C19: 밥 | G19: =IFERROR(INDEX(온라인_반찬!$C$2:$H$594,MATCH($D19,온라인_반찬!$C$2:$C$594,0),6),"") | H19: =IFERROR(INDEX(온라인_반찬!$D$2:$J$587,MATCH($D19,온라인_반찬!$C$2:$C$587,0),6),"") | I19: 2026-01-05 09:30~ | L19: =IFERROR(INDEX(온라인_반찬!$C$2:$J$587,MATCH($D19,온라인_반찬!$C$2:$C$587,0),8),"")
C20: 반찬1 | G20: =IFERROR(INDEX(온라인_반찬!$C$2:$H$594,MATCH($D20,온라인_반찬!$C$2:$C$594,0),6),"") | H20: =IFERROR(INDEX(온라인_반찬!$D$2:$J$587,MATCH($D20,온라인_반찬!$C$2:$C$587,0),6),"") | I20: 2026-01-05 09:30~ | L20: =IFERROR(INDEX(온라인_반찬!$C$2:$J$587,MATCH($D20,온라인_반찬!$C$2:$C$587,0),8),"")
G21: =IFERROR(INDEX(온라인_반찬!$C$2:$H$594,MATCH($D21,온라인_반찬!$C$2:$C$594,0),6),"") | H21: =IFERROR(INDEX(온라인_반찬!$D$2:$J$587,MATCH($D21,온라인_반찬!$C$2:$C$587,0),6),"") | I21: 2026-01-05 09:30~ | L21: =IFERROR(INDEX(온라인_반찬!$C$2:$J$587,MATCH($D21,온라인_반찬!$C$2:$C$587,0),8),"")
C22: 반찬2 | G22: =IFERROR(INDEX(온라인_반찬!$C$2:$H$594,MATCH($D22,온라인_반찬!$C$2:$C$594,0),6),"") | H22: =IFERROR(INDEX(온라인_반찬!$D$2:$J$587,MATCH($D22,온라인_반찬!$C$2:$C$587,0),6),"") | I22: 2026-01-05 09:30~ | L22: =IFERROR(INDEX(온라인_반찬!$C$2:$J$587,MATCH($D22,온라인_반찬!$C$2:$C$587,0),8),"")
C23: 반찬3 | G23: =IFERROR(INDEX(온라인_반찬!$C$2:$H$594,MATCH($D23,온라인_반찬!$C$2:$C$594,0),6),"") | H23: =IFERROR(INDEX(온라인_반찬!$D$2:$J$587,MATCH($D23,온라인_반찬!$C$2:$C$587,0),6),"") | I23: 2026-01-05 09:30~ | L23: =IFERROR(INDEX(온라인_반찬!$C$2:$J$587,MATCH($D23,온라인_반찬!$C$2:$C$587,0),8),"")
C24: 반찬4 | G24: =IFERROR(INDEX(온라인_반찬!$C$2:$H$594,MATCH($D24,온라인_반찬!$C$2:$C$594,0),6),"") | H24: =IFERROR(INDEX(온라인_반찬!$D$2:$J$587,MATCH($D24,온라인_반찬!$C$2:$C$587,0),6),"") | I24: 2026-01-05 09:30~ | L24: =IFERROR(INDEX(온라인_반찬!$C$2:$J$587,MATCH($D24,온라인_반찬!$C$2:$C$587,0),8),"")
C25: 보존식 | F25: 1 | J25: 1 | K25: 0.25

Sheet 01-06
B1: 2026-01-06(화) | M1: *한입해쉬브라운 : 9g(개당) | P1: *양송이떡갈비 : 1.5ea, 1.75, 2 | S1: *양배추당근라페 : 20g / 30g
B2: 출고일 | C2: 구분 | D2: 품명 | E2: 중량(g) | F2: 수량(장) | G2: 자재사용내역 | H2: 알러지 표기 | I2: 배송시점 | J2: 제공인원 | K2: 총생산량(Kg) | L2: 메 모 | M2: *샐러드 채소 : 15g, 20g ,25g | P2: *야채고기말이 : 1.1, 1.5, 1.5 | S2: *고구마튀김35g / 45g
B3: 중식 | C3: 밥 | D3: 친환경귀리쌀밥 | E3: 140 | G3: =IFERROR(INDEX(온라인_반찬!$C$2:$H$594,MATCH($D3,온라인_반찬!$C$2:$C$594,0),6),"") -> 쌀(국산)90%, 귀리(국산.친환경)5%, 정제수 | H3: =IFERROR(INDEX(온라인_반찬!$D$2:$J$587,MATCH($D3,온라인_반찬!$C$2:$C$587,0),6),"") -> 0 | I3: 2026-01-06 09:30~ | J3: 2488 | K3: 376305 | L3: =IFERROR(INDEX(온라인_반찬!$C$2:$J$587,MATCH($D3,온라인_반찬!$C$2:$C$587,0),8),"") -> 0 | M3: *웨지감자 : 25g / 30g | O3: *어묵채구이:12g / 15g | S3: 한입새우튀김 : 30g / 35g / 45g (소스15g)
C4: 국 | D4: 황태계란국 | E4: 150 | G4: =IFERROR(INDEX(온라인_반찬!$C$2:$H$594,MATCH($D4,온라인_반찬!$C$2:$C$594,0),6),"") -> 계란(국산)10%, 황태채(러시아산)5%, 양파, 파, 마늘, 정제수, 참기름, 국간장, 소금 | H4: =IFERROR(INDEX(온라인_반찬!$D$2:$J$587,MATCH($D4,온라인_반찬!$C$2:$C$587,0),6),"") -> .1.5.21. | I4: 2026-01-06 09:30~ | J4: 2488 | K4: 384645 | L4: =IFERROR(INDEX(온라인_반찬!$C$2:$J$587,MATCH($D4,온라인_반찬!$C$2:$C$587,0),8),"") -> 0 | M4: *꼬마돈까스: 25g, 중구청 35g | P4: *족발:45g / 55g | S4: *갈비만두 : 성분표기 인당1개 / 식수 인당1.5개
