Workbook
Name 급식국: #REF!
Name 급식밥: #REF!
Name 김치: 급식_반찬!$C$27:$C$28
Name 반찬1: 레시피북!$C$127:$C$292
Name 반찬2: 레시피북!$C$293:$C$393
Name 반찬3: 레시피북!$C$379:$C$430
Name 반찬4: 레시피북!$C$345:$C$495
Name 온라인국: 레시피북!$C$2:$C$90

Sheet 글로벌리더스&석식식단표
A1: 08월 식단표
A2: 요일 | B2: 월 | D2: 화 | F2: 수 | H2: 목 | J2: 금 | L2: 칠리새우 | M2: 국물떡볶이
A3: 날짜 | B3: 46237 | D3: 46238 | F3: 46239 | H3: 46240 | J3: 46241 | L3: 불고기샐러드&오리엔탈드레싱 | M3: 크로와상샌드위치
A4: 주차 | B4: 메뉴 | C4: 알레르기표기 | D4: 메뉴 | E4: 알레르기표기 | F4: 메뉴 | G4: 알레르기표기 | H4: 메뉴 | I4: 알레르기표기 | J4: 메뉴 | K4: 알레르기표기 | L4: 크리스피쌀핫도그 | M4: 닭봉떡간장조림
A5: 1주 | B5: 친환경찰보리쌀밥 | C5: =IFERROR(INDEX(레시피북!$C$2:$I$611,MATCH($B5,레시피북!$C$2:$C$611,0),7),"") -> 0 | D5: 친환경귀리쌀밥 | E5: =IFERROR(INDEX(레시피북!$C$2:$I$611,MATCH($D5,레시피북!$C$2:$C$611,0),7),"") -> 0 | F5: 친환경찰흑미쌀밥 | G5: =IFERROR(INDEX(레시피북!$C$2:$I$611,MATCH($F5,레시피북!$C$2:$C$611,0),7),"") -> 0 | H5: 흰쌀밥 | I5: =IFERROR(INDEX(레시피북!$C$2:$I$611,MATCH($H5,레시피북!$C$2:$C$611,0),7),"") -> 0 | J5: 친환경찰보리쌀밥 | K5: =IFERROR(INDEX(레시피북!$C$2:$I$611,MATCH($J5,레시피북!$C$2:$C$611,0),7),"") -> 0 | L5: 닭날개오븐구이 | M5: 레몬크림탕수육
B6: 유니짜장덮밥소스 | C6: =IFERROR(INDEX(레시피북!$C$2:$I$611,MATCH($B6,레시피북!$C$2:$C$611,0),7),"") -> .2.5.6.10.15.16. | D6: 닭살떡조림 | E6: =IFERROR(INDEX(레시피북!$C$2:$I$611,MATCH($D6,레시피북!$C$2:$C$611,0),7),"") -> .5.15.21. | F6: 제육두루치기 | G6: =IFERROR(INDEX(레시피북!$C$2:$I$611,MATCH($F6,레시피북!$C$2:$C$611,0),7),"") -> .5.6.10.21. | H6: 소고기양배추볶음 | I6: =IFERROR(INDEX(레시피북!$C$2:$I$611,MATCH($H6,레시피북!$C$2:$C$611,0),7),"") -> .5.16.21. | J6: 돼지갈비양념찜 | K6: =IFERROR(INDEX(레시피북!$C$2:$I$611,MATCH($J6,레시피북!$C$2:$C$611,0),7),"") -> .5.6.10.19.21. | L6: 마라떡볶이 | M6: 삼겹살소금구이
B7: 계란후라이 | C7: =IFERROR(INDEX(레시피북!$C$2:$I$611,MATCH($B7,레시피북!$C$2:$C$611,0),7),"") -> .1.5.18. | D7: 햄에그롤 | E7: =IFERROR(INDEX(레시피북!$C$2:$I$611,MATCH($D7,레시피북!$C$2:$C$611,0),7),"") -> .1.2.5.6.10.16. | F7: 명엽채조림 | G7: =IFERROR(INDEX(레시피북!$C$2:$I$611,MATCH($F7,레시피북!$C$2:$C$611,0),7),"") -> .1.5.21. | H7: 저염표고강정 | I7: =IFERROR(INDEX(레시피북!$C$2:$I$611,MATCH($H7,레시피북!$C$2:$C$611,0),7),"") -> .1.5.6.21. | J7: 메추리알파프리카볶음 | K7: =IFERROR(INDEX(레시피북!$C$2:$I$611,MATCH($J7,레시피북!$C$2:$C$611,0),7),"") -> .1.5.6.12.21. | L7: 임연수구이 | M7: 칠리탕수육
B8: 숙주나물 | C8: =IFERROR(INDEX(레시피북!$C$2:$I$611,MATCH($B8,레시피북!$C$2:$C$611,0),7),"") -> .5.21. | D8: 콩나물청경채무침 | E8: =IFERROR(INDEX(레시피북!$C$2:$I$611,MATCH($D8,레시피북!$C$2:$C$611,0),7),"") -> .21. | F8: 호박새우젓볶음 | G8: =IFERROR(INDEX(레시피북!$C$2:$I$611,MATCH($F8,레시피북!$C$2:$C$611,0),7),"") -> .5.9.21. | H8: 콘버터 | I8: =IFERROR(INDEX(레시피북!$C$2:$I$611,MATCH($H8,레시피북!$C$2:$C$611,0),7),"") -> .1.2.5.16. | J8: 도시락김 | K8: =IFERROR(INDEX(레시피북!$C$2:$I$611,MATCH($J8,레시피북!$C$2:$C$611,0),7),"") -> .21. | L8: 삼치데리야끼구이 | M8: 프리미엄떡갈비
B9: 배추김치 | C9: =IFERROR(INDEX(레시피북!$C$2:$I$611,MATCH($B9,레시피북!$C$2:$C$611,0),7),"") -> .9.12. | D9: 깍두기 | E9: =IFERROR(INDEX(레시피북!$C$2:$I$611,MATCH($D9,레시피북!$C$2:$C$611,0),7),"") -> .6.9. | F9: 백김치 | G9: =IFERROR(INDEX(레시피북!$C$2:$I$611,MATCH($F9,레시피북!$C$2:$C$611,0),7),"") -> 0 | H9: 깍두기 | I9: =IFERROR(INDEX(레시피북!$C$2:$I$611,MATCH($H9,레시피북!$C$2:$C$611,0),7),"") -> .6.9. | J9: 배추김치 | K9: =IFERROR(INDEX(레시피북!$C$2:$I$611,MATCH($J9,레시피북!$C$2:$C$611,0),7),"") -> .9.12. | L9: 족발냉채 | M9: 로제순살치킨떡볶이
B10: 두부탕국 | C10: =IFERROR(INDEX(레시피북!$C$2:$I$611,MATCH($B10,레시피북!$C$2:$C$611,0),7),"") -> .5. | D10: 우삼겹된장찌개 | E10: =IFERROR(INDEX(레시피북!$C$2:$I$611,MATCH($D10,레시피북!$C$2:$C$611,0),7),"") -> .5.16. | F10: 들깨미역국 | G10: =IFERROR(INDEX(레시피북!$C$2:$I$611,MATCH($F10,레시피북!$C$2:$C$611,0),7),"") -> .5.9.21.22. | H10: 근대된장국 | I10: =IFERROR(INDEX(레시피북!$C$2:$I$611,MATCH($H10,레시피북!$C$2:$C$611,0),7),"") -> .5. | J10: 맑은아귀국 | K10: =IFERROR(INDEX(레시피북!$C$2:$I$611,MATCH($J10,레시피북!$C$2:$C$611,0),7),"") -> .5. | L10: 차돌숙주볶음 | M10: 훈제닭샐러드
C11: =IFERROR(INDEX(레시피북!$C$2:$I$611,MATCH($B11,레시피북!$C$2:$C$611,0),7),"") | E11: =IFERROR(INDEX(레시피북!$C$2:$I$611,MATCH($D11,레시피북!$C$2:$C$611,0),7),"") | I11: =IFERROR(INDEX(레시피북!$C$2:$I$611,MATCH($H11,레시피북!$C$2:$C$611,0),7),"") | K11: =IFERROR(INDEX(레시피북!$C$2:$I$611,MATCH($J11,레시피북!$C$2:$C$611,0),7),"") | L11: 쉬림프콥샐러드
L12: 모짜렐라치즈볼
A13: 날짜 | B13: 46244 | D13: 46245 | F13: 46246 | H13: 46247 | J13: 46248 | L13: 보쌈수육
A14: 주차 | B14: 메뉴 | C14: 알레르기표기 | D14: 메뉴 | E14: 알레르기표기 | F14: 메뉴 | G14: 알레르기표기 | H14: 메뉴 | I14: 알레르기표기 | J14: 메뉴 | K14: 알레르기표기 | L14: 왕새우튀김
A15: 2주 | B15: 친환경찰보리쌀밥 | C15: =IFERROR(INDEX(레시피북!$C$2:$I$611,MATCH($B15,레시피북!$C$2:$C$611,0),7),"") -> 0 | D15: 친환경귀리쌀밥 | E15: =IFERROR(INDEX(레시피북!$C$2:$I$611,MATCH($D15,레시피북!$C$2:$C$611,0),7),"") -> 0 | F15: 친환경찰흑미쌀밥 | G15: =IFERROR(INDEX(레시피북!$C$2:$I$611,MATCH($F15,레시피북!$C$2:$C$611,0),7),"") -> 0 | H15: 흰쌀밥 | I15: =IFERROR(INDEX(레시피북!$C$2:$I$611,MATCH($H15,레시피북!$C$2:$C$611,0),7),"") -> 0 | J15: 친환경찰보리쌀밥 | K15: =IFERROR(INDEX(레시피북!$C$2:$I$611,MATCH($J15,레시피북!$C$2:$C$611,0),7),"") -> 0 | L15: 케이준샐러드&허니머스터드D
B16: 갈릭햄버거스테이크 | C16: =IFERROR(INDEX(레시피북!$C$2:$I$611,MATCH($B16,레시피북!$C$2:$C$611,0),7),"") -> .1.5.6.10.16.18. | D16: 중식소고기볶음 | E16: =IFERROR(INDEX(레시피북!$C$2:$I$611,MATCH($D16,레시피북!$C$2:$C$611,0),7),"") -> .5.16.21. | F16: 돈채부추볶음 | G16: =IFERROR(INDEX(레시피북!$C$2:$I$611,MATCH($F16,레시피북!$C$2:$C$611,0),7),"") -> .5.6.10.21. | H16: 매콤영양찜닭 | I16: .5.6.15.21. | J16: 미트볼우스터소스조림 | K16: =IFERROR(INDEX(레시피북!$C$2:$I$611,MATCH($J16,레시피북!$C$2:$C$611,0),7),"") -> .1.2.5.6.10.12.15.16. | L16: 눈꽃치즈치킨
B17: 꽈리고추계란장조림 | C17: =IFERROR(INDEX(레시피북!$C$2:$I$611,MATCH($B17,레시피북!$C$2:$C$611,0),7),"") -> .1.5. | D17: 매콤볼어묵조림 | E17: .5.6.21. | F17: 팝콘치킨 | G17: =IFERROR(INDEX(레시피북!$C$2:$I$611,MATCH($F17,레시피북!$C$2:$C$611,0),7),"") -> .1.5.6.12.15.16.18. | H17: 소세지케찹볶음 | I17: =IFERROR(INDEX(레시피북!$C$2:$I$611,MATCH($H17,레시피북!$C$2:$C$611,0),7),"") | J17: 불고기누들떡잡채 | K17: =IFERROR(INDEX(레시피북!$C$2:$I$611,MATCH($J17,레시피북!$C$2:$C$611,0),7),"") -> .5.6.16.21. | L17: 콩나물해물찜
B18: 하와이안마카로니SD | C18: =IFERROR(INDEX(레시피북!$C$2:$I$611,MATCH($B18,레시피북!$C$2:$C$611,0),7),"") -> .1.5.6.19. | D18: 치커리오이무침 | E18: =IFERROR(INDEX(레시피북!$C$2:$I$611,MATCH($D18,레시피북!$C$2:$C$611,0),7),"") -> .5.21. | F18: 마늘쫑멸치볶음 | G18: =IFERROR(INDEX(레시피북!$C$2:$I$611,MATCH($F18,레시피북!$C$2:$C$611,0),7),"") -> .5.21. | H18: 올방개묵무침 | I18: =IFERROR(INDEX(레시피북!$C$2:$I$611,MATCH($H18,레시피북!$C$2:$C$611,0),7),"") -> .5.21. | J18: 비트무생채 | K18: =IFERROR(INDEX(레시피북!$C$2:$I$611,MATCH($J18,레시피북!$C$2:$C$611,0),7),"") -> 0 | L18: 소떡꼬치
B19: 배추김치 | C19: =IFERROR(INDEX(레시피북!$C$2:$I$611,MATCH($B19,레시피북!$C$2:$C$611,0),7),"") -> .9.12. | D19: 깍두기 | E19: =IFERROR(INDEX(레시피북!$C$2:$I$611,MATCH($D19,레시피북!$C$2:$C$611,0),7),"") -> .6.9. | F19: 열무김치 | G19: =IFERROR(INDEX(레시피북!$C$2:$I$611,MATCH($F19,레시피북!$C$2:$C$611,0),7),"") -> .9. | H19: 깍두기 | I19: =IFERROR(INDEX(레시피북!$C$2:$I$611,MATCH($H19,레시피북!$C$2:$C$611,0),7),"") -> .6.9. | J19: 배추김치 | K19: =IFERROR(INDEX(레시피북!$C$2:$I$611,MATCH($J19,레시피북!$C$2:$C$611,0),7),"") -> .9.12. | L19: 보쌈수육
B20: 유부미소국 | C20: =IFERROR(INDEX(레시피북!$C$2:$I$611,MATCH($B20,레시피북!$C$2:$C$611,0),7),"") -> .5. | D20: 오징어콩나물국 | E20: =IFERROR(INDEX(레시피북!$C$2:$I$611,MATCH($D20,레시피북!$C$2:$C$611,0),7),"") -> .5.17. | F20: 순두부계란탕 | G20: =IFERROR(INDEX(레시피북!$C$2:$I$611,MATCH($F20,레시피북!$C$2:$C$611,0),7),"") -> .1.5. | H20: 소고기장국 | I20: =IFERROR(INDEX(레시피북!$C$2:$I$611,MATCH($H20,레시피북!$C$2:$C$611,0),7),"") -> .5.16. | J20: 돈육고추장찌개 | K20: =IFERROR(INDEX(레시피북!$C$2:$I$611,MATCH($J20,레시피북!$C$2:$C$611,0),7),"") -> .5.6.10. | L20: 고등어카레구이
C21: =IFERROR(INDEX(레시피북!$C$2:$I$611,MATCH($B21,레시피북!$C$2:$C$611,0),7),"") | E21: =IFERROR(INDEX(레시피북!$C$2:$I$611,MATCH($D21,레시피북!$C$2:$C$611,0),7),"") | G21: =IFERROR(INDEX(레시피북!$C$2:$I$611,MATCH($F21,레시피북!$C$2:$C$611,0),7),"") | I21: =IFERROR(INDEX(레시피북!$C$2:$I$611,MATCH($H21,레시피북!$C$2:$C$611,0),7),"") | K21: =IFERROR(INDEX(레시피북!$C$2:$I$611,MATCH($J21,레시피북!$C$2:$C$611,0),7),"") | L21: 라코타치즈샐러드&발사믹D
L22: 전복버터구이
A23: 날짜 | B23: 46251 | D23: 46252 | F23: 46253 | H23: 46254 | J23: 46255 | L23: 잠봉샐러드&키위드레싱
A24: 주차 | B24: 메뉴 | C24: 알레르기표기 | D24: 메뉴 | E24: 알레르기표기 | F24: 메뉴 | G24: 알레르기표기 | H24: 메뉴 | I24: 알레르기표기 | J24: 메뉴 | K24: 알레르기표기 | L24: 불고기피자
A25: 3주 | B25: ♣대체공휴일♣ | D25: 친환경찰보리쌀밥 | E25: =IFERROR(INDEX(레시피북!$C$2:$I$611,MATCH($D25,레시피북!$C$2:$C$611,0),7),"") -> 0 | F25: 친환경귀리쌀밥 | G25: =IFERROR(INDEX(레시피북!$C$2:$I$611,MATCH($F25,레시피북!$C$2:$C$611,0),7),"") -> 0 | H25: 흰쌀밥 | I25: =IFERROR(INDEX(레시피북!$C$2:$I$611,MATCH($H25,레시피북!$C$2:$C$611,0),7),"") -> 0 | J25: 친환경찰보리쌀밥 | K25: =IFERROR(INDEX(레시피북!$C$2:$I$611,MATCH($J25,레시피북!$C$2:$C$611,0),7),"") -> 0 | L25: 우삼겹떡볶이
D26: 코코넛커리소스 | E26: =IFERROR(INDEX(레시피북!$C$2:$I$611,MATCH($D26,레시피북!$C$2:$C$611,0),7),"") -> .2.5.6.12.15.16.18. | F26: 매콤양념불백 | G26: =IFERROR(INDEX(레시피북!$C$2:$I$611,MATCH($F26,레시피북!$C$2:$C$611,0),7),"") -> .5.6.10.19.21. | H26: 소고기우엉조림 | I26: =IFERROR(INDEX(레시피북!$C$2:$I$611,MATCH($H26,레시피북!$C$2:$C$611,0),7),"") -> .5.10.21. | J26: 허니양념치킨 | K26: =IFERROR(INDEX(레시피북!$C$2:$I$611,MATCH($J26,레시피북!$C$2:$C$611,0),7),"") -> .1.2.5.6.12.15.16.21. | L26: 새우감바스&바게트
D27: 새우튀김 | E27: =IFERROR(INDEX(레시피북!$C$2:$I$611,MATCH($D27,레시피북!$C$2:$C$611,0),7),"") -> .1.5.6.9. | F27: 채소계란찜 | G27: =IFERROR(INDEX(레시피북!$C$2:$I$611,MATCH($F27,레시피북!$C$2:$C$611,0),7),"") -> .1.2. | H27: 문어볼오븐구이 | I27: =IFERROR(INDEX(레시피북!$C$2:$I$611,MATCH($H27,레시피북!$C$2:$C$611,0),7),"") -> .1.5.6. | J27: 감자크림뇨끼 | K27: =IFERROR(INDEX(레시피북!$C$2:$I$611,MATCH($J27,레시피북!$C$2:$C$611,0),7),"") -> .1.2.5.6.10.15.16.
D28: 보코치니샐러드 | E28: =IFERROR(INDEX(레시피북!$C$2:$I$611,MATCH($D28,레시피북!$C$2:$C$611,0),7),"") -> .2.4.12. | F28: 고사리당근나물 | G28: =IFERROR(INDEX(레시피북!$C$2:$I$611,MATCH($F28,레시피북!$C$2:$C$611,0),7),"") -> .5.21. | H28: 오색콩나물냉채 | I28: =IFERROR(INDEX(레시피북!$C$2:$I$611,MATCH($H28,레시피북!$C$2:$C$611,0),7),"") -> .1.2.5.6.8.12.21. | J28: 과일샐러드 | K28: =IFERROR(INDEX(레시피북!$C$2:$I$611,MATCH($J28,레시피북!$C$2:$C$611,0),7),"") -> .1.12.19.
D29: 배추김치 | E29: =IFERROR(INDEX(레시피북!$C$2:$I$611,MATCH($D29,레시피북!$C$2:$C$611,0),7),"") -> .9.12. | F29: 깍두기 | G29: =IFERROR(INDEX(레시피북!$C$2:$I$611,MATCH($F29,레시피북!$C$2:$C$611,0),7),"") -> .6.9. | H29: 깍두기 | I29: =IFERROR(INDEX(레시피북!$C$2:$I$611,MATCH($H29,레시피북!$C$2:$C$611,0),7),"") -> .6.9. | J29: 배추김치 | K29: =IFERROR(INDEX(레시피북!$C$2:$I$611,MATCH($J29,레시피북!$C$2:$C$611,0),7),"") -> .9.12.
D30: 양배추두부된장국 | E30: =IFERROR(INDEX(레시피북!$C$2:$I$611,MATCH($D30,레시피북!$C$2:$C$611,0),7),"") -> .5. | F30: 황태무채국 | G30: =IFERROR(INDEX(레시피북!$C$2:$I$611,MATCH($F30,레시피북!$C$2:$C$611,0),7),"") -> .5. | H30: 얼갈이된장국 | I30: =IFERROR(INDEX(레시피북!$C$2:$I$611,MATCH($H30,레시피북!$C$2:$C$611,0),7),"") -> .5. | J30: 소고기미역국 | K30: =IFERROR(INDEX(레시피북!$C$2:$I$611,MATCH($J30,레시피북!$C$2:$C$611,0),7),"") -> .5.9.16.
E31: =IFERROR(INDEX(레시피북!$C$2:$I$611,MATCH($D31,레시피북!$C$2:$C$611,0),7),"") | G31: =IFERROR(INDEX(레시피북!$C$2:$I$611,MATCH($F31,레시피북!$C$2:$C$611,0),7),"") | I31: =IFERROR(INDEX(레시피북!$C$2:$I$611,MATCH($H31,레시피북!$C$2:$C$611,0),7),"") | K31: =IFERROR(INDEX(레시피북!$C$2:$I$611,MATCH($J31,레시피북!$C$2:$C$611,0),7),"")
C32: =IFERROR(INDEX(레시피북!$C$2:$I$611,MATCH($B32,레시피북!$C$2:$C$611,0),7),"")
A33: 날짜 | B33: 46258 | D33: 46259 | F33: 46260 | H33: 46261 | J33: 46262
A34: 주차 | B34: 메뉴 | C34: 알레르기표기 | D34: 메뉴 | E34: 알레르기표기 | F34: 메뉴 | G34: 알레르기표기 | H34: 메뉴 | I34: 알레르기표기 | J34: 메뉴 | K34: 알레르기표기
A35: 4주 | B35: 친환경찰보리쌀밥 | C35: =IFERROR(INDEX(레시피북!$C$2:$I$611,MATCH($B35,레시피북!$C$2:$C$611,0),7),"") -> 0 | D35: 친환경귀리쌀밥 | E35: =IFERROR(INDEX(레시피북!$C$2:$I$611,MATCH($D35,레시피북!$C$2:$C$611,0),7),"") -> 0 | F35: 친환경찰흑미쌀밥 | G35: =IFERROR(INDEX(레시피북!$C$2:$I$611,MATCH($F35,레시피북!$C$2:$C$611,0),7),"") -> 0 | H35: 흰쌀밥 | I35: =IFERROR(INDEX(레시피북!$C$2:$I$611,MATCH($H35,레시피북!$C$2:$C$611,0),7),"") -> 0 | J35: 친환경찰보리쌀밥 | K35: =IFERROR(INDEX(레시피북!$C$2:$I$611,MATCH($J35,레시피북!$C$2:$C$611,0),7),"") -> 0
B36: 목화솜탕수육 | C36: =IFERROR(INDEX(레시피북!$C$2:$I$611,MATCH($B36,레시피북!$C$2:$C$611,0),7),"") -> .1.5.6.10. | D36: 매콤치즈닭갈비 | E36: .2.5.6.15.21. | F36: 폭찹스테이크 | G36: =IFERROR(INDEX(레시피북!$C$2:$I$611,MATCH($F36,레시피북!$C$2:$C$611,0),7),"") -> .5.10.12.13.21. | H36: 소고기새송이볶음 | I36: =IFERROR(INDEX(레시피북!$C$2:$I$611,MATCH($H36,레시피북!$C$2:$C$611,0),7),"") -> .5.16.21. | J36: 매콤오삼불고기 | K36: .5.6.10.17.21.
B37: & 탕수소스 | C37: =IFERROR(INDEX(레시피북!$C$2:$I$611,MATCH($B37,레시피북!$C$2:$C$611,0),7),"") -> .5. | D37: 오믈렛 | E37: =IFERROR(INDEX(레시피북!$C$2:$I$611,MATCH($D37,레시피북!$C$2:$C$611,0),7),"") -> .1.2.5.6.15.16.18. | F37: 양념멸치볶음 | G37: =IFERROR(INDEX(레시피북!$C$2:$I$611,MATCH($F37,레시피북!$C$2:$C$611,0),7),"") -> .5.6.21. | H37: 스팸케찹조림 | I37: =IFERROR(INDEX(레시피북!$C$2:$I$611,MATCH($H37,레시피북!$C$2:$C$611,0),7),"") -> .5.10.12.21. | J37: 숫자치킨너겟 | K37: =IFERROR(INDEX(레시피북!$C$2:$I$611,MATCH($J37,레시피북!$C$2:$C$611,0),7),"") -> .1.2.5.6.15.16.
B38: 메추리알짜장볶이 | C38: =IFERROR(INDEX(레시피북!$C$2:$I$611,MATCH($B38,레시피북!$C$2:$C$611,0),7),"") -> .1.5.6.10.15.16. | D38: 김자반 | E38: =IFERROR(INDEX(레시피북!$C$2:$I$611,MATCH($D38,레시피북!$C$2:$C$611,0),7),"") -> .5.21.22. | F38: 코울슬로 | G38: =IFERROR(INDEX(레시피북!$C$2:$I$611,MATCH($F38,레시피북!$C$2:$C$611,0),7),"") -> .1.5.16. | H38: 검은콩해바라기씨조림 | I38: =IFERROR(INDEX(레시피북!$C$2:$I$611,MATCH($H38,레시피북!$C$2:$C$611,0),7),"") -> .5.21. | J38: 라디치오샐러드(오리엔탈소스) | K38: =IFERROR(INDEX(레시피북!$C$2:$I$611,MATCH($J38,레시피북!$C$2:$C$611,0),7),"")
B39: 오이부추무침 | C39: =IFERROR(INDEX(레시피북!$C$2:$I$611,MATCH($B39,레시피북!$C$2:$C$611,0),7),"") -> .5.21. | D39: 깍두기 | E39: =IFERROR(INDEX(레시피북!$C$2:$I$611,MATCH($D39,레시피북!$C$2:$C$611,0),7),"") -> .6.9. | F39: 열무김치 | G39: =IFERROR(INDEX(레시피북!$C$2:$I$611,MATCH($F39,레시피북!$C$2:$C$611,0),7),"") -> .9. | H39: 깍두기 | I39: =IFERROR(INDEX(레시피북!$C$2:$I$611,MATCH($H39,레시피북!$C$2:$C$611,0),7),"") -> .6.9. | J39: 배추김치 | K39: =IFERROR(INDEX(레시피북!$C$2:$I$611,MATCH($J39,레시피북!$C$2:$C$611,0),7),"") -> .9.12.
B40: 배추김치 | C40: =IFERROR(INDEX(레시피북!$C$2:$I$611,MATCH($B40,레시피북!$C$2:$C$611,0),7),"") -> .9.12. | D40: 소고기무국 | E40: =IFERROR(INDEX(레시피북!$C$2:$I$611,MATCH($D40,레시피북!$C$2:$C$611,0),7),"") -> .5.16. | F40: 게살계란탕 | G40: =IFERROR(INDEX(레시피북!$C$2:$I$611,MATCH($F40,레시피북!$C$2:$C$611,0),7),"") -> .1.2.5.8.21. | H40: 논우렁살된장찌개 | I40: =IFERROR(INDEX(레시피북!$C$2:$I$611,MATCH($H40,레시피북!$C$2:$C$611,0),7),"") -> .5. | J40: 맑은미역국 | K40: =IFERROR(INDEX(레시피북!$C$2:$I$611,MATCH($J40,레시피북!$C$2:$C$611,0),7),"") -> .5.9.
...

Sheet 유아식단표
A1: 08월 식단표
A2: 요일 | B2: 월 | D2: 화 | F2: 수 | H2: 목 | J2: 금
B3: 46237 | D3: 46238 | F3: 46239 | H3: 46240 | J3: 46241
A4: 주차 | B4: 메뉴 | C4: 알레르기표기 | D4: 메뉴 | E4: 알레르기표기 | F4: 메뉴 | G4: 알레르기표기 | H4: 메뉴 | I4: 알레르기표기 | J4: 메뉴 | K4: 알레르기표기 | L4: 메뉴 | M4: 알레르기표기
A5: 2주 | B5: 친환경찰보리쌀밥 | C5: =IFERROR(INDEX(레시피북!$C$2:$I$611,MATCH($B5,레시피북!$C$2:$C$611,0),7),"") -> 0 | D5: 친환경귀리쌀밥 | E5: =IFERROR(INDEX(레시피북!$C$2:$I$611,MATCH($D5,레시피북!$C$2:$C$611,0),7),"") -> 0 | F5: 친환경찰흑미쌀밥 | G5: =IFERROR(INDEX(레시피북!$C$2:$I$611,MATCH($F5,레시피북!$C$2:$C$611,0),7),"") -> 0 | H5: 흰쌀밥 | I5: =IFERROR(INDEX(레시피북!$C$2:$I$611,MATCH($H5,레시피북!$C$2:$C$611,0),7),"") -> 0 | J5: 친환경찰보리쌀밥 | K5: =IFERROR(INDEX(레시피북!$C$2:$I$611,MATCH($J5,레시피북!$C$2:$C$611,0),7),"") -> 0
B6: 유니짜장덮밥소스 | C6: =IFERROR(INDEX(레시피북!$C$2:$I$611,MATCH($B6,레시피북!$C$2:$C$611,0),7),"") -> .2.5.6.10.15.16. | D6: 닭살떡조림 | E6: =IFERROR(INDEX(레시피북!$C$2:$I$611,MATCH($D6,레시피북!$C$2:$C$611,0),7),"") -> .5.15.21. | F6: 미소된장제육 | G6: =IFERROR(INDEX(레시피북!$C$2:$I$611,MATCH($F6,레시피북!$C$2:$C$611,0),7),"") -> .5.10.21. | H6: 소고기양배추볶음 | I6: =IFERROR(INDEX(레시피북!$C$2:$I$611,MATCH($H6,레시피북!$C$2:$C$611,0),7),"") -> .5.16.21. | J6: 돼지갈비양념찜 | K6: =IFERROR(INDEX(레시피북!$C$2:$I$611,MATCH($J6,레시피북!$C$2:$C$611,0),7),"") -> .5.6.10.19.21.
B7: 계란후라이 | C7: =IFERROR(INDEX(레시피북!$C$2:$I$611,MATCH($B7,레시피북!$C$2:$C$611,0),7),"") -> .1.5.18. | D7: 햄에그롤 | E7: =IFERROR(INDEX(레시피북!$C$2:$I$611,MATCH($D7,레시피북!$C$2:$C$611,0),7),"") -> .1.2.5.6.10.16. | F7: 명엽채조림 | G7: =IFERROR(INDEX(레시피북!$C$2:$I$611,MATCH($F7,레시피북!$C$2:$C$611,0),7),"") -> .1.5.21. | H7: 저염표고강정 | I7: =IFERROR(INDEX(레시피북!$C$2:$I$611,MATCH($H7,레시피북!$C$2:$C$611,0),7),"") -> .1.5.6.21. | J7: 메추리알파프리카볶음 | K7: =IFERROR(INDEX(레시피북!$C$2:$I$611,MATCH($J7,레시피북!$C$2:$C$611,0),7),"") -> .1.5.6.12.21.
B8: 숙주나물 | C8: =IFERROR(INDEX(레시피북!$C$2:$I$611,MATCH($B8,레시피북!$C$2:$C$611,0),7),"") -> .5.21. | D8: 콩나물청경채무침 | E8: =IFERROR(INDEX(레시피북!$C$2:$I$611,MATCH($D8,레시피북!$C$2:$C$611,0),7),"") -> .21. | F8: 애호박새우젓볶음 | G8: =IFERROR(INDEX(레시피북!$C$2:$I$611,MATCH($F8,레시피북!$C$2:$C$611,0),7),"") | H8: 콘버터 | I8: =IFERROR(INDEX(레시피북!$C$2:$I$611,MATCH($H8,레시피북!$C$2:$C$611,0),7),"") -> .1.2.5.16. | J8: 도시락김 | K8: =IFERROR(INDEX(레시피북!$C$2:$I$611,MATCH($J8,레시피북!$C$2:$C$611,0),7),"") -> .21.
B9: 배추김치 | C9: =IFERROR(INDEX(레시피북!$C$2:$I$611,MATCH($B9,레시피북!$C$2:$C$611,0),7),"") -> .9.12. | D9: 깍두기 | E9: =IFERROR(INDEX(레시피북!$C$2:$I$611,MATCH($D9,레시피북!$C$2:$C$611,0),7),"") -> .6.9. | F9: 백김치 | G9: =IFERROR(INDEX(레시피북!$C$2:$I$611,MATCH($F9,레시피북!$C$2:$C$611,0),7),"") -> 0 | H9: 깍두기 | I9: =IFERROR(INDEX(레시피북!$C$2:$I$611,MATCH($H9,레시피북!$C$2:$C$611,0),7),"") -> .6.9. | J9: 배추김치 | K9: =IFERROR(INDEX(레시피북!$C$2:$I$611,MATCH($J9,레시피북!$C$2:$C$611,0),7),"") -> .9.12.
B10: 두부탕국 | C10: =IFERROR(INDEX(레시피북!$C$2:$I$611,MATCH($B10,레시피북!$C$2:$C$611,0),7),"") -> .5. | D10: 우삼겹된장찌개 | E10: =IFERROR(INDEX(레시피북!$C$2:$I$611,MATCH($D10,레시피북!$C$2:$C$611,0),7),"") -> .5.16. | F10: 들깨미역국 | G10: =IFERROR(INDEX(레시피북!$C$2:$I$611,MATCH($F10,레시피북!$C$2:$C$611,0),7),"") -> .5.9.21.22. | H10: 근대된장국 | I10: =IFERROR(INDEX(레시피북!$C$2:$I$611,MATCH($H10,레시피북!$C$2:$C$611,0),7),"") -> .5. | J10: 맑은아귀국 | K10: =IFERROR(INDEX(레시피북!$C$2:$I$611,MATCH($J10,레시피북!$C$2:$C$611,0),7),"") -> .5.
C11: =IFERROR(INDEX(레시피북!$C$2:$I$611,MATCH($B11,레시피북!$C$2:$C$611,0),7),"") | E11: =IFERROR(INDEX(레시피북!$C$2:$I$611,MATCH($D11,레시피북!$C$2:$C$611,0),7),"") | G11: =IFERROR(INDEX(레시피북!$C$2:$I$611,MATCH($F11,레시피북!$C$2:$C$611,0),7),"") | I11: =IFERROR(INDEX(레시피북!$C$2:$I$611,MATCH($H11,레시피북!$C$2:$C$611,0),7),"") | K11: =IFERROR(INDEX(레시피북!$C$2:$I$611,MATCH($J11,레시피북!$C$2:$C$611,0),7),"")
C12: =IFERROR(INDEX(레시피북!$C$2:$I$611,MATCH($B12,레시피북!$C$2:$C$611,0),7),"") | G12: =IFERROR(INDEX(레시피북!$C$2:$I$611,MATCH($F12,레시피북!$C$2:$C$611,0),7),"") | K12: =IFERROR(INDEX(레시피북!$C$2:$I$611,MATCH($J12,레시피북!$C$2:$C$611,0),7),"")
A13: 날짜 | B13: 46244 | D13: 46245 | F13: 46246 | H13: 46247 | J13: 46248
A14: 주차 | B14: 메뉴 | C14: 알레르기표기 | D14: 메뉴 | E14: 알레르기표기 | F14: 메뉴 | G14: 알레르기표기 | H14: 메뉴 | I14: 알레르기표기 | J14: 메뉴 | K14: 알레르기표기 | L14: 메뉴 | M14: 알레르기표기 | N14: 메뉴 | O14: 알레르기표기
A15: 3주 | B15: 친환경찰보리쌀밥 | C15: =IFERROR(INDEX(레시피북!$C$2:$I$611,MATCH($B15,레시피북!$C$2:$C$611,0),7),"") -> 0 | D15: 친환경귀리쌀밥 | E15: =IFERROR(INDEX(레시피북!$C$2:$I$611,MATCH($D15,레시피북!$C$2:$C$611,0),7),"") -> 0 | F15: 친환경찰흑미쌀밥 | G15: =IFERROR(INDEX(레시피북!$C$2:$I$611,MATCH($F15,레시피북!$C$2:$C$611,0),7),"") -> 0 | H15: 흰쌀밥 | I15: =IFERROR(INDEX(레시피북!$C$2:$I$611,MATCH($H15,레시피북!$C$2:$C$611,0),7),"") -> 0 | J15: 친환경찰보리쌀밥 | K15: =IFERROR(INDEX(레시피북!$C$2:$I$611,MATCH($J15,레시피북!$C$2:$C$611,0),7),"") -> 0
B16: 갈릭햄버거스테이크 | C16: =IFERROR(INDEX(레시피북!$C$2:$I$611,MATCH($B16,레시피북!$C$2:$C$611,0),7),"") -> .1.5.6.10.16.18. | D16: 중식소고기볶음 | E16: =IFERROR(INDEX(레시피북!$C$2:$I$611,MATCH($D16,레시피북!$C$2:$C$611,0),7),"") -> .5.16.21. | F16: 돈채부추볶음 | G16: =IFERROR(INDEX(레시피북!$C$2:$I$611,MATCH($F16,레시피북!$C$2:$C$611,0),7),"") -> .5.6.10.21. | H16: 영양찜닭 | I16: =IFERROR(INDEX(레시피북!$C$2:$I$611,MATCH($H16,레시피북!$C$2:$C$611,0),7),"") -> .5.6.15.21. | J16: 미트볼우스터소스조림 | K16: =IFERROR(INDEX(레시피북!$C$2:$I$611,MATCH($J16,레시피북!$C$2:$C$611,0),7),"") -> .1.2.5.6.10.12.15.16.
B17: 계란장조림 | C17: =IFERROR(INDEX(레시피북!$C$2:$I$611,MATCH($B17,레시피북!$C$2:$C$611,0),7),"") -> .1.5. | D17: 볼어묵조림 | E17: =IFERROR(INDEX(레시피북!$C$2:$I$611,MATCH($D17,레시피북!$C$2:$C$611,0),7),"") -> .5.6.21. | F17: 팝콘치킨 | G17: =IFERROR(INDEX(레시피북!$C$2:$I$611,MATCH($F17,레시피북!$C$2:$C$611,0),7),"") -> .1.5.6.12.15.16.18. | H17: 소세지케찹볶음 | I17: =IFERROR(INDEX(레시피북!$C$2:$I$611,MATCH($H17,레시피북!$C$2:$C$611,0),7),"") | J17: 불고기누들떡잡채 | K17: =IFERROR(INDEX(레시피북!$C$2:$I$611,MATCH($J17,레시피북!$C$2:$C$611,0),7),"") -> .5.6.16.21.
B18: 하와이안마카로니SD | C18: =IFERROR(INDEX(레시피북!$C$2:$I$611,MATCH($B18,레시피북!$C$2:$C$611,0),7),"") -> .1.5.6.19. | D18: 치커리오이무침 | E18: =IFERROR(INDEX(레시피북!$C$2:$I$611,MATCH($D18,레시피북!$C$2:$C$611,0),7),"") -> .5.21. | F18: 마늘쫑멸치볶음 | G18: =IFERROR(INDEX(레시피북!$C$2:$I$611,MATCH($F18,레시피북!$C$2:$C$611,0),7),"") -> .5.21. | H18: 올방개묵무침 | I18: =IFERROR(INDEX(레시피북!$C$2:$I$611,MATCH($H18,레시피북!$C$2:$C$611,0),7),"") -> .5.21. | J18: 비트무생채 | K18: =IFERROR(INDEX(레시피북!$C$2:$I$611,MATCH($J18,레시피북!$C$2:$C$611,0),7),"") -> 0
B19: 배추김치 | C19: =IFERROR(INDEX(레시피북!$C$2:$I$611,MATCH($B19,레시피북!$C$2:$C$611,0),7),"") -> .9.12. | D19: 깍두기 | E19: =IFERROR(INDEX(레시피북!$C$2:$I$611,MATCH($D19,레시피북!$C$2:$C$611,0),7),"") -> .6.9. | F19: 백김치 | G19: =IFERROR(INDEX(레시피북!$C$2:$I$611,MATCH($F19,레시피북!$C$2:$C$611,0),7),"") -> 0 | H19: 깍두기 | I19: =IFERROR(INDEX(레시피북!$C$2:$I$611,MATCH($H19,레시피북!$C$2:$C$611,0),7),"") -> .6.9. | J19: 배추김치 | K19: =IFERROR(INDEX(레시피북!$C$2:$I$611,MATCH($J19,레시피북!$C$2:$C$611,0),7),"") -> .9.12.
B20: 유부미소국 | C20: =IFERROR(INDEX(레시피북!$C$2:$I$611,MATCH($B20,레시피북!$C$2:$C$611,0),7),"") -> .5. | D20: 오징어콩나물국 | E20: =IFERROR(INDEX(레시피북!$C$2:$I$611,MATCH($D20,레시피북!$C$2:$C$611,0),7),"") -> .5.17. | F20: 순두부계란탕 | G20: =IFERROR(INDEX(레시피북!$C$2:$I$611,MATCH($F20,레시피북!$C$2:$C$611,0),7),"") -> .1.5. | H20: 소고기장국 | I20: =IFERROR(INDEX(레시피북!$C$2:$I$611,MATCH($H20,레시피북!$C$2:$C$611,0),7),"") -> .5.16. | J20: 순살삼계탕 | K20: =IFERROR(INDEX(레시피북!$C$2:$I$611,MATCH($J20,레시피북!$C$2:$C$611,0),7),"") -> .5.15.
C21: =IFERROR(INDEX(레시피북!$C$2:$I$611,MATCH($B21,레시피북!$C$2:$C$611,0),7),"") | E21: =IFERROR(INDEX(레시피북!$C$2:$I$611,MATCH($D21,레시피북!$C$2:$C$611,0),7),"") | G21: =IFERROR(INDEX(레시피북!$C$2:$I$611,MATCH($F21,레시피북!$C$2:$C$611,0),7),"") | I21: =IFERROR(INDEX(레시피북!$C$2:$I$611,MATCH($H21,레시피북!$C$2:$C$611,0),7),"") | K21: =IFERROR(INDEX(레시피북!$C$2:$I$611,MATCH($J21,레시피북!$C$2:$C$611,0),7),"")
C22: =IFERROR(INDEX(레시피북!$C$2:$I$611,MATCH($B22,레시피북!$C$2:$C$611,0),7),"") | G22: =IFERROR(INDEX(레시피북!$C$2:$I$611,MATCH($F22,레시피북!$C$2:$C$611,0),7),"") | K22: =IFERROR(INDEX(레시피북!$C$2:$I$611,MATCH($J22,레시피북!$C$2:$C$611,0),7),"")
A23: 날짜 | B23: 46251 | D23: 46252 | F23: 46253 | H23: 46254 | J23: 46255
A24: 주차 | B24: 메뉴 | C24: 알레르기표기 | D24: 메뉴 | E24: 알레르기표기 | F24: 메뉴 | G24: 알레르기표기 | H24: 메뉴 | I24: 알레르기표기 | J24: 메뉴 | K24: 알레르기표기
A25: 4주 | B25: ♣대체공휴일♣ | D25: 친환경귀리쌀밥 | E25: =IFERROR(INDEX(레시피북!$C$2:$I$611,MATCH($D25,레시피북!$C$2:$C$611,0),7),"") -> 0 | F25: 친환경찰흑미쌀밥 | G25: =IFERROR(INDEX(레시피북!$C$2:$I$611,MATCH($F25,레시피북!$C$2:$C$611,0),7),"") -> 0 | H25: 흰쌀밥 | I25: =IFERROR(INDEX(레시피북!$C$2:$I$611,MATCH($H25,레시피북!$C$2:$C$611,0),7),"") -> 0 | J25: 친환경찰보리쌀밥 | K25: =IFERROR(INDEX(레시피북!$C$2:$I$611,MATCH($J25,레시피북!$C$2:$C$611,0),7),"") -> 0
D26: 코코넛커리소스 | E26: =IFERROR(INDEX(레시피북!$C$2:$I$611,MATCH($D26,레시피북!$C$2:$C$611,0),7),"") -> .2.5.6.12.15.16.18. | F26: 돈갈비양념구이 | G26: =IFERROR(INDEX(레시피북!$C$2:$I$611,MATCH($F26,레시피북!$C$2:$C$611,0),7),"") -> .5.6.10.21. | H26: 소고기우엉조림 | I26: =IFERROR(INDEX(레시피북!$C$2:$I$611,MATCH($H26,레시피북!$C$2:$C$611,0),7),"") -> .5.10.21. | J26: 허니양념치킨 | K26: =IFERROR(INDEX(레시피북!$C$2:$I$611,MATCH($J26,레시피북!$C$2:$C$611,0),7),"") -> .1.2.5.6.12.15.16.21.
D27: 새우튀김 | E27: =IFERROR(INDEX(레시피북!$C$2:$I$611,MATCH($D27,레시피북!$C$2:$C$611,0),7),"") -> .1.5.6.9. | F27: 채소계란찜 | G27: =IFERROR(INDEX(레시피북!$C$2:$I$611,MATCH($F27,레시피북!$C$2:$C$611,0),7),"") -> .1.2. | H27: 문어볼오븐구이 | I27: =IFERROR(INDEX(레시피북!$C$2:$I$611,MATCH($H27,레시피북!$C$2:$C$611,0),7),"") -> .1.5.6. | J27: 감자크림뇨끼 | K27: =IFERROR(INDEX(레시피북!$C$2:$I$611,MATCH($J27,레시피북!$C$2:$C$611,0),7),"") -> .1.2.5.6.10.15.16.
D28: 보코치니샐러드 | E28: =IFERROR(INDEX(레시피북!$C$2:$I$611,MATCH($D28,레시피북!$C$2:$C$611,0),7),"") -> .2.4.12. | F28: 고사리당근나물 | G28: =IFERROR(INDEX(레시피북!$C$2:$I$611,MATCH($F28,레시피북!$C$2:$C$611,0),7),"") -> .5.21. | H28: 오색콩나물냉채 | I28: =IFERROR(INDEX(레시피북!$C$2:$I$611,MATCH($H28,레시피북!$C$2:$C$611,0),7),"") -> .1.2.5.6.8.12.21. | J28: 과일샐러드 | K28: =IFERROR(INDEX(레시피북!$C$2:$I$611,MATCH($J28,레시피북!$C$2:$C$611,0),7),"") -> .1.12.19.
D29: 깍두기 | E29: =IFERROR(INDEX(레시피북!$C$2:$I$611,MATCH($D29,레시피북!$C$2:$C$611,0),7),"") -> .6.9. | F29: 백김치 | G29: =IFERROR(INDEX(레시피북!$C$2:$I$611,MATCH($F29,레시피북!$C$2:$C$611,0),7),"") -> 0 | H29: 깍두기 | I29: =IFERROR(INDEX(레시피북!$C$2:$I$611,MATCH($H29,레시피북!$C$2:$C$611,0),7),"") -> .6.9. | J29: 배추김치 | K29: =IFERROR(INDEX(레시피북!$C$2:$I$611,MATCH($J29,레시피북!$C$2:$C$611,0),7),"") -> .9.12.
D30: 양배추두부된장국 | E30: =IFERROR(INDEX(레시피북!$C$2:$I$611,MATCH($D30,레시피북!$C$2:$C$611,0),7),"") -> .5. | F30: 황태무채국 | G30: =IFERROR(INDEX(레시피북!$C$2:$I$611,MATCH($F30,레시피북!$C$2:$C$611,0),7),"") -> .5. | H30: 얼갈이된장국 | I30: =IFERROR(INDEX(레시피북!$C$2:$I$611,MATCH($H30,레시피북!$C$2:$C$611,0),7),"") -> .5. | J30: 소고기미역국 | K30: =IFERROR(INDEX(레시피북!$C$2:$I$611,MATCH($J30,레시피북!$C$2:$C$611,0),7),"") -> .5.9.16. | M30: 0
E31: =IFERROR(INDEX(레시피북!$C$2:$I$611,MATCH($D31,레시피북!$C$2:$C$611,0),7),"") | G31: =IFERROR(INDEX(레시피북!$C$2:$I$611,MATCH($F31,레시피북!$C$2:$C$611,0),7),"") | I31: =IFERROR(INDEX(레시피북!$C$2:$I$611,MATCH($H31,레시피북!$C$2:$C$611,0),7),"") | K31: =IFERROR(INDEX(레시피북!$C$2:$I$611,MATCH($J31,레시피북!$C$2:$C$611,0),7),"")
G32: =IFERROR(INDEX(레시피북!$C$2:$I$611,MATCH($F32,레시피북!$C$2:$C$611,0),7),"") | K32: =IFERROR(INDEX(레시피북!$C$2:$I$611,MATCH($J32,레시피북!$C$2:$C$611,0),7),"")
A33: 날짜 | B33: 46258 | D33: 46259 | F33: 46260 | H33: 46261 | J33: 46262
A34: 주차 | C34: 알레르기표기 | D34: 메뉴 | E34: 알레르기표기 | F34: 메뉴 | G34: 알레르기표기 | H34: 메뉴 | I34: 알레르기표기 | J34: 메뉴 | K34: 알레르기표기
A35: 5주 | B35: 친환경찰보리쌀밥 | C35: =IFERROR(INDEX(레시피북!$C$2:$I$611,MATCH($B35,레시피북!$C$2:$C$611,0),7),"") -> 0 | D35: 친환경귀리쌀밥 | E35: =IFERROR(INDEX(레시피북!$C$2:$I$611,MATCH($D35,레시피북!$C$2:$C$611,0),7),"") -> 0 | F35: 친환경찰흑미쌀밥 | G35: =IFERROR(INDEX(레시피북!$C$2:$I$611,MATCH($F35,레시피북!$C$2:$C$611,0),7),"") -> 0 | H35: 흰쌀밥 | I35: =IFERROR(INDEX(레시피북!$C$2:$I$611,MATCH($H35,레시피북!$C$2:$C$611,0),7),"") -> 0 | J35: 친환경찰보리쌀밥 | K35: =IFERROR(INDEX(레시피북!$C$2:$I$611,MATCH($J35,레시피북!$C$2:$C$611,0),7),"") -> 0
B36: 목화솜탕수육 | C36: =IFERROR(INDEX(레시피북!$C$2:$I$611,MATCH($B36,레시피북!$C$2:$C$611,0),7),"") -> .1.5.6.10. | D36: 치즈닭갈비 | E36: =IFERROR(INDEX(레시피북!$C$2:$I$611,MATCH($D36,레시피북!$C$2:$C$611,0),7),"") -> .2.5.6.15.21. | F36: 폭찹스테이크 | G36: =IFERROR(INDEX(레시피북!$C$2:$I$611,MATCH($F36,레시피북!$C$2:$C$611,0),7),"") -> .5.10.12.13.21. | H36: 소고기새송이볶음 | I36: =IFERROR(INDEX(레시피북!$C$2:$I$611,MATCH($H36,레시피북!$C$2:$C$611,0),7),"") -> .5.16.21. | J36: 오삼불고기 | K36: =IFERROR(INDEX(레시피북!$C$2:$I$611,MATCH($J36,레시피북!$C$2:$C$611,0),7),"") -> .5.6.10.17.21.
B37: & 탕수소스 | C37: =IFERROR(INDEX(레시피북!$C$2:$I$611,MATCH($B37,레시피북!$C$2:$C$611,0),7),"") -> .5. | D37: 오믈렛 | E37: =IFERROR(INDEX(레시피북!$C$2:$I$611,MATCH($D37,레시피북!$C$2:$C$611,0),7),"") -> .1.2.5.6.15.16.18. | F37: 크랜베리멸치볶음 | G37: =IFERROR(INDEX(레시피북!$C$2:$I$611,MATCH($F37,레시피북!$C$2:$C$611,0),7),"") -> .5.21. | H37: 스팸케찹조림 | I37: =IFERROR(INDEX(레시피북!$C$2:$I$611,MATCH($H37,레시피북!$C$2:$C$611,0),7),"") -> .5.10.12.21. | J37: 숫자치킨너겟 | K37: =IFERROR(INDEX(레시피북!$C$2:$I$611,MATCH($J37,레시피북!$C$2:$C$611,0),7),"") -> .1.2.5.6.15.16.
B38: 메추리알짜장볶이 | C38: =IFERROR(INDEX(레시피북!$C$2:$I$611,MATCH($B38,레시피북!$C$2:$C$611,0),7),"") -> .1.5.6.10.15.16. | D38: 김자반 | E38: =IFERROR(INDEX(레시피북!$C$2:$I$611,MATCH($D38,레시피북!$C$2:$C$611,0),7),"") -> .5.21.22. | F38: 코울슬로 | G38: =IFERROR(INDEX(레시피북!$C$2:$I$611,MATCH($F38,레시피북!$C$2:$C$611,0),7),"") -> .1.5.16. | H38: 검은콩해바라기씨조림 | I38: =IFERROR(INDEX(레시피북!$C$2:$I$611,MATCH($H38,레시피북!$C$2:$C$611,0),7),"") -> .5.21. | J38: 라디치오샐러드 | K38: =IFERROR(INDEX(레시피북!$C$2:$I$611,MATCH($J38,레시피북!$C$2:$C$611,0),7),"") -> 0
B39: 오이부추무침 | C39: =IFERROR(INDEX(레시피북!$C$2:$I$611,MATCH($B39,레시피북!$C$2:$C$611,0),7),"") -> .5.21. | D39: 깍두기 | E39: =IFERROR(INDEX(레시피북!$C$2:$I$611,MATCH($D39,레시피북!$C$2:$C$611,0),7),"") -> .6.9. | F39: 백김치 | G39: =IFERROR(INDEX(레시피북!$C$2:$I$611,MATCH($F39,레시피북!$C$2:$C$611,0),7),"") -> 0 | H39: 깍두기 | I39: =IFERROR(INDEX(레시피북!$C$2:$I$611,MATCH($H39,레시피북!$C$2:$C$611,0),7),"") -> .6.9. | J39: & 오리엔탈드레싱 | K39: =IFERROR(INDEX(레시피북!$C$2:$I$611,MATCH($J39,레시피북!$C$2:$C$611,0),7),"") -> .5.6.13.21.
B40: 배추김치 | C40: =IFERROR(INDEX(레시피북!$C$2:$I$611,MATCH($B40,레시피북!$C$2:$C$611,0),7),"") -> .9.12. | D40: 소고기무국 | E40: =IFERROR(INDEX(레시피북!$C$2:$I$611,MATCH($D40,레시피북!$C$2:$C$611,0),7),"") -> .5.16. | F40: 게살계란탕 | G40: =IFERROR(INDEX(레시피북!$C$2:$I$611,MATCH($F40,레시피북!$C$2:$C$611,0),7),"") -> .1.2.5.8.21. | H40: 논우렁살된장찌개 | I40: =IFERROR(INDEX(레시피북!$C$2:$I$611,MATCH($H40,레시피북!$C$2:$C$611,0),7),"") -> .5. | J40: 배추김치 | K40: =IFERROR(INDEX(레시피북!$C$2:$I$611,MATCH($J40,레시피북!$C$2:$C$611,0),7),"") -> .9.12.
...

Sheet 레시피북
A1: No. | B1: 품목 | C1: 품명 | D1: 온라인(g) | E1: 급식(g) | F1: 온라인 중/대(EA) | G1: 급식(EA) | H1: 자재사용내역 | I1: 알러지표기 | K1: 상품코드 | L1: 출고량 (g 또는 수량) | M1: 로스율 (5%) | N1: 총생산량 (g 또는 수량) | O1: 급식 (g) | P1: 중 (g) | Q1: 대 (g) | R1: 단위 | S1: 급식 (EA) | T1: 중 (EA) | U1: 대 (EA) | V1: 단위 | W1: 상품코드 | X1: 상품명 M10 | Y1: 구매단위 (g) | Z1: 구매단위 (EA) | AA1: 발주 1인량 | AB1: (중) 1인량 | AC1: (대) 1인량 | AD1: 자재 Mix% | AE1: 상품코드 | AF1: 상품명 S10 | AG1: 발주 1인량 | AH1: (중) 1인량 | AI1: (대) 1인량 | AJ1: 자재 Mix% | AK1: 상품코드 | AL1: 상품명 S20 | AM1: 발주 1인량 | AN1: (중) 1인량 | AO1: (대) 1인량 | AP1: 자재 Mix%
A2: 1 | C2: 유부다시국 | H2: 유부[(대두:캐나다, 호주, 미국등), 대두유(대두:미국,프바질, 파라과이등)]21%, 건더기스프{볶음참께(인도산), 정제염(국산), 김조각(국산), 가쓰오브시(필리핀산)등]5%, 정제수, 마늘, 가스오우동소스, 소금 | I2: .5.21. | J2: 가스오우동소스(면사랑), 유부(이츠웰 슬라이스유부)30g / 35g
A3: 2 | C3: 올갱이미역국 | H3: 불린미역(국산)21%, 다슬기(국내산)2%, 마늘, 정제수, 국간장, 참치액, 소금 | I3: .5.9. | J3: 28g / 30g
A4: 3 | C4: 북어콩나물국 | H4: 콩나물(콩:외국산)16% , 북어채(러시아산)5%, 두부(콩:미국,호주,캐나다등), 대파, 마늘, 참기름, 정제수, 소금 | I4: .5. | J4: 25g / 28g | L4: 23450 | M4: 1172.5 | N4: 24622.5 | O4: =E4 -> 0 | P4: =D4 -> 0 | Q4: =D4 -> 0 | R4: g | S4: =E4 -> 0 | T4: =D4 -> 0 | U4: =D4 -> 0 | W4: 192872 | X4: =IFERROR(INDEX([1]Sheet1!$A$2:$X$1948,MATCH($W$2:$W$270,[1]Sheet1!$G$2:$G$1948,0),8),"") -> 소이원 콩나물(곱슬이_단채 4Kg/BOX) | Y4: 4000 | AA4: 25 | AB4: =T4*AD4 -> #DIV/0! | AC4: =U4*AD4 -> #DIV/0! | AD4: =AA4/E4 -> #DIV/0! | AE4: 313570 | AF4: =IFERROR(INDEX([1]Sheet1!$A$2:$X$1948,MATCH($AE$2:$AE$270,[1]Sheet1!$G$2:$G$1948,0),8),"") -> 프레시웨이 북어채(1Kg/EA) | AG4: 5 | AH4: =P4*AJ4 -> #DIV/0! | AI4: =Q4*AJ4 -> #DIV/0! | AJ4: =AG4/$E4 -> #DIV/0! | AL4: =IFERROR(INDEX([1]Sheet1!$A$2:$X$1948,MATCH($AK$2:$AK$270,[1]Sheet1!$G$2:$G$1948,0),8),"") -> 0 | AM4: 5 | AN4: =P4*AP4 -> #DIV/0! | AO4: =Q4*AP4 -> #DIV/0! | AP4: =AM4/$E4 -> #DIV/0!
A5: 4 | C5: 모둠어묵국 | H5: 무(국산)15%, 모둠어묵(어육:수입산)10%, 파, 마늘, 국간장, 멸치육수농축액, 정제수, 소금 | I5: .5.6. | J5: 40g / 45g종합어묵(사조대림)
A6: 5 | C6: 근대된장국 | H6: 근대(국산)22.8%, 양파(국산), 정제수, 된장, 대파, 마늘, 멸치육수농축액, 소금 | I6: .5. | J6: 40g / 45g | L6: 21960 | M6: 1098 | N6: 23058 | O6: =E6 -> 0 | P6: =D6 -> 0 | Q6: =D6 -> 0 | R6: g | S6: =E6 -> 0 | T6: =D6 -> 0 | U6: =D6 -> 0 | W6: 223306 | X6: =IFERROR(INDEX([1]Sheet1!$A$2:$X$1948,MATCH($W$2:$W$270,[1]Sheet1!$G$2:$G$1948,0),8),"") -> 냉동근대(IQF 1Kg/EA) | Y6: 1000 | AA6: 35 | AB6: =T6*AD6 -> #DIV/0! | AC6: =U6*AD6 -> #DIV/0! | AD6: =AA6/E6 -> #DIV/0! | AE6: 138570 | AF6: =IFERROR(INDEX([1]Sheet1!$A$2:$X$1948,MATCH($AE$2:$AE$270,[1]Sheet1!$G$2:$G$1948,0),8),"") -> 면사랑 멸치육수(1.8L_보급형 1.8Kg/EA) | AH6: =P6*AJ6 -> #DIV/0! | AI6: =Q6*AJ6 -> #DIV/0! | AJ6: =AG6/$E6 -> #DIV/0! | AL6: =IFERROR(INDEX([1]Sheet1!$A$2:$X$1948,MATCH($AK$2:$AK$270,[1]Sheet1!$G$2:$G$1948,0),8),"") -> 0
A7: 6 | C7: 오징어무국 | H7: 무(국산)20%, 오징어(미국산, 국산)5%, 양파, 대파, 마늘, 정제수, 멸치육수농축액, 국간장, 소금 | I7: .5.17. | J7: 40g / 50g
A8: 7 | C8: 얼큰오징어무국 | H8: 무(국산)20%, 오징어(미국산, 국산)5%, 양파, 대파, 마늘, 정제수, 멸치육수농축액, 국간장, 고춧가루, 소금 | I8: .5.17. | J8: 40g / 50g
A9: 8 | C9: 소고기샤브국 | H9: 소고기(호주산)12%, 알배추(국산)7%, 느타리(국산), 청경채(국산), 대파, 마늘, 간장, 정제수, 소금 | I9: .5.16. | J9: 40g / 45g
A10: 9 | C10: 우삼겹된장찌개 | H10: 모둠채소(호박, 양파, 새송이:국산)20%, 두부(콩:미국,호주,캐나다등)8%, 소고기(미국산)3%, 파, 마늘, 된장, 멸치육수농축액, 정제수, 소금 | I10: .5.16. | J10: 50g / 60g | O10: =E10 -> 0 | P10: =D10 -> 0 | Q10: =D10 -> 0 | R10: g | S10: =E10 -> 0 | T10: =D10 -> 0 | U10: =D10 -> 0 | W10: 204623 | X10: =IFERROR(INDEX([1]Sheet1!$A$2:$X$1948,MATCH($W$2:$W$270,[1]Sheet1!$G$2:$G$1948,0),8),"") -> 애호박(특품 인큐베이터 KG) | Y10: 1000 | AA10: 30 | AB10: =T10*AD10 -> #DIV/0! | AC10: =U10*AD10 -> #DIV/0! | AD10: =AA10/E10 -> #DIV/0! | AE10: 168257 | AF10: =IFERROR(INDEX([1]Sheet1!$A$2:$X$1948,MATCH($AE$2:$AE$270,[1]Sheet1!$G$2:$G$1948,0),8),"") -> 명품 판두부(찌개용 3Kg/EA) | AG10: 15 | AH10: =P10*AJ10 -> #DIV/0! | AI10: =Q10*AJ10 -> #DIV/0! | AJ10: =AG10/$E10 -> #DIV/0! | AL10: =IFERROR(INDEX([1]Sheet1!$A$2:$X$1948,MATCH($AK$2:$AK$270,[1]Sheet1!$G$2:$G$1948,0),8),"") -> 0
A11: 10 | C11: 채소계란국 | H11: 계란(국산)13%, 채소[양파, 당근, 부추:국산]10%, 정제수, 멸치육수농축액, 대파, 마늘, 소금 | I11: .1.5. | L11: 600 | M11: 30 | N11: 630 | O11: =E11 -> 0 | P11: =D11 -> 0 | Q11: =D11 -> 0 | R11: g | S11: =E11 -> 0 | T11: =D11 -> 0 | U11: =D11 -> 0 | W11: 193090 | X11: =IFERROR(INDEX([1]Sheet1!$A$2:$X$1948,MATCH($W$2:$W$270,[1]Sheet1!$G$2:$G$1948,0),8),"") -> 냉동감자(절단_3~4cm 1Kg/EA) | Y11: 1000 | AA11: 22 | AB11: =T11*AD11 -> #DIV/0! | AC11: =U11*AD11 -> #DIV/0! | AD11: =AA11/E11 -> #DIV/0! | AE11: 204623 | AF11: =IFERROR(INDEX([1]Sheet1!$A$2:$X$1948,MATCH($AE$2:$AE$270,[1]Sheet1!$G$2:$G$1948,0),8),"") -> 애호박(특품 인큐베이터 KG) | AH11: =P11*AJ11 -> #DIV/0! | AI11: =Q11*AJ11 -> #DIV/0! | AJ11: =AG11/$E11 -> #DIV/0! | AK11: 420010 | AL11: =IFERROR(INDEX([1]Sheet1!$A$2:$X$1948,MATCH($AK$2:$AK$270,[1]Sheet1!$G$2:$G$1948,0),8),"") -> 알로팜 계란(왕란_무항생제_68g*30입 2.04Kg/EA)
A12: 11 | C12: 순살동태국 | H12: 순살동태(러시아산)7.2%, 무(국산)13%,두부, 쑥갓, 양파, 대파, 마늘, 멸치육수농축액, 국간장, 소금 | I12: .5.9.10. | J12: 40g / 50g
A13: 12 | C13: 소고기미역국 | H13: 불린미역(미역:국산)18.3%, 소고기(호주산)5%, 마늘, 정제수, 밥새우, 멸치육수농축액, 소금, 국간장 | I13: .5.9.16. | J13: 40g / 50g 멸치육수농축액(면사랑)
A14: 13 | C14: 소고기무국 | H14: 무(국산)18.3%, 소고기(호주산)10.7%, 양파, 대파, 마늘, 정제수, 소금, 멸치육수농축액, 국간장, 후추 | I14: .5.16. | J14: 40g | L14: 16590 | M14: 829.5 | N14: 17419.5 | O14: =E14 -> 0 | P14: =D14 -> 0 | Q14: =D14 -> 0 | R14: g | S14: =E14 -> 0 | T14: =D14 -> 0 | U14: =D14 -> 0 | W14: 145349 | X14: =IFERROR(INDEX([1]Sheet1!$A$2:$X$1948,MATCH($W$2:$W$270,[1]Sheet1!$G$2:$G$1948,0),8),"") -> 이츠웰 사골엑기스(1Kg/EA) | Y14: 1000 | AB14: =T14*AD14 -> #DIV/0! | AC14: =U14*AD14 -> #DIV/0! | AD14: =AA14/E14 -> #DIV/0! | AE14: 424285 | AF14: =IFERROR(INDEX([1]Sheet1!$A$2:$X$1948,MATCH($AE$2:$AE$270,[1]Sheet1!$G$2:$G$1948,0),8),"") -> 소양지(3*2*0.3cm_저지방 키즈용_국거리용 KG) | AH14: =P14*AJ14 -> #DIV/0! | AI14: =Q14*AJ14 -> #DIV/0! | AJ14: =AG14/$E14 -> #DIV/0! | AK14: 204418 | AL14: =IFERROR(INDEX([1]Sheet1!$A$2:$X$1948,MATCH($AK$2:$AK$270,[1]Sheet1!$G$2:$G$1948,0),8),"") -> 무우(특품 9~12개입 18Kg/BOX)
A15: 14 | C15: 얼큰소고기무국 | H15: 무(국산)18.3%, 소고기(호주산)10.7%, 양파, 대파, 마늘, 정제수, 소금, 고춧가루, 멸치육수농축액, 국간장, 후추 | I15: .5.16.
A16: 15 | C16: 맑은순두부국 | H16: 순두부(대두:수입산)15%, 호박, 파, 마늘, 새우젓(새우,소금:국산), 멸치육수농축액, 정제수, 소금 | I16: .5.9.
A17: 16 | C17: 소고기장국 | H17: 열갈이(국산)10%, 소고기(호주산)7%, 무(국산)5%, 콩나물(원료수입산)5%, 정제수, 된장, 대파, 마늘, 국간장, 멸치육수농축액, 소금 | I17: .5.16. | J17: 멸치육수농축액(면사랑) 40g / 45g )
A18: 17 | C18: 두부탕국 | H18: 두부(원료수입산)18%, 무(국산)10%,, 파, 마늘, 정제수, 멸치육수농축액, 국간장, 소금 | I18: .5. | J18: 멸치육수농축액(면사랑) 40g / 45g )
A19: 18 | C19: 맑은미역국 | H19: 불린미역(국산)23%, 정제수, 참기름, 국간장, 밥새우, 멸치육수농축액, 마늘, 소금 | I19: .5.9. | J19: 25g / 30g | L19: 2565 | M19: 128.25 | N19: 2693.25 | O19: =E19 -> 0 | P19: =D19 -> 0 | Q19: =D19 -> 0 | R19: g | S19: =E19 -> 0 | T19: =D19 -> 0 | U19: =D19 -> 0 | W19: 206631 | X19: =IFERROR(INDEX([1]Sheet1!$A$2:$X$1948,MATCH($W$2:$W$270,[1]Sheet1!$G$2:$G$1948,0),8),"") -> 냉동아욱(상품 1Kg/PAC) | Y19: 1000 | AA19: 32 | AB19: =T19*AD19 -> #DIV/0! | AC19: =U19*AD19 -> #DIV/0! | AD19: =AA19/E19 -> #DIV/0! | AE19: 313633 | AF19: =IFERROR(INDEX([1]Sheet1!$A$2:$X$1948,MATCH($AE$2:$AE$270,[1]Sheet1!$G$2:$G$1948,0),8),"") -> 현대푸드 두절건새우(중 1Kg/EA) | AH19: =P19*AJ19 -> #DIV/0! | AI19: =Q19*AJ19 -> #DIV/0! | AJ19: =AG19/$E19 -> #DIV/0! | AL19: =IFERROR(INDEX([1]Sheet1!$A$2:$X$1948,MATCH($AK$2:$AK$270,[1]Sheet1!$G$2:$G$1948,0),8),"") -> 0
A20: 19 | C20: 미소장국 | H20: 두부(콩:미국,호주,캐나다등)18%, 팽이버섯(국산)5%, 실파(국산), 정제수, 미소된장(국산), 멸치육수농축액, 소금 | I20: .5. | J20: 멸치육수농축액(면사랑)
A21: 20 | C21: 맑은콩나물국 | H21: 콩나물(콩:외국산)25%, 정제수, 국간장, 마늘, 대파, 멸치육수농축액, 소금 | I21: .5. | J21: 25g / 28g
A22: 21 | C22: 양배추두부된장국 | H22: 양배추(국내산)20%, 두부(대두:외국산)7%, 정제수, 파, 마늘, 국간장, 멸치육수농축액, 소금 | I22: .5. | J22: 40g / 45g | L22: 1200 | M22: 60 | N22: 1260 | O22: =E22 -> 0 | P22: =D22 -> 0 | Q22: =D22 -> 0 | R22: g | S22: =E22 -> 0 | T22: =D22 -> 0 | U22: =D22 -> 0 | W22: 192872 | X22: =IFERROR(INDEX([1]Sheet1!$A$2:$X$1948,MATCH($W$2:$W$270,[1]Sheet1!$G$2:$G$1948,0),8),"") -> 소이원 콩나물(곱슬이_단채 4Kg/BOX) | AB22: =T22*AD22 -> #DIV/0! | AC22: =U22*AD22 -> #DIV/0! | AD22: =AA22/E22 -> #DIV/0! | AE22: 168257 | AF22: =IFERROR(INDEX([1]Sheet1!$A$2:$X$1948,MATCH($AE$2:$AE$270,[1]Sheet1!$G$2:$G$1948,0),8),"") -> 명품 판두부(찌개용 3Kg/EA) | AH22: =P22*AJ22 -> #DIV/0! | AI22: =Q22*AJ22 -> #DIV/0! | AJ22: =AG22/$E22 -> #DIV/0! | AL22: =IFERROR(INDEX([1]Sheet1!$A$2:$X$1948,MATCH($AK$2:$AK$270,[1]Sheet1!$G$2:$G$1948,0),8),"") -> 0
A23: 23 | C23: 짬뽕국 | H23: 숙주(녹두:외국산)12%, 해산물(대왕오징어:페루산, 홍합.바지락.새우살:중국산)7%, 양파, 청경채, 파, 마늘, 정제수, 고춧가루, 고추기름, 치킨스톡, 소금 | I23: .5.9.15.17.18.
A24: 24 | C24: 감자된장국 | H24: 감자(국산)20%, 두부(대두:외국산)5%, 양파, 파, 마늘, 멸치육수농축액, 된장, 정제수, 소금 | I24: .5.6. | J24: 50g/55g
A25: 25 | C25: 설렁탕 | H25: 소고기(호주산)14.3%, 사골육수 [잡뼈(한우), 사골(한우), 사골액기스 {정제수, 사골농축액17% (사골:호주산) 천일염}, 정제수], 생대파(국산), 후추, 소금 | I25: .5.16. | J25: 8g / 10g | O25: =E25 -> 0 | P25: =D25 -> 0 | Q25: =D25 -> 0 | R25: g | S25: =E25 -> 0 | T25: =D25 -> 0 | U25: =D25 -> 0 | W25: 223307 | X25: =IFERROR(INDEX([1]Sheet1!$A$2:$X$1948,MATCH($W$2:$W$270,[1]Sheet1!$G$2:$G$1948,0),8),"") -> 냉동얼갈이(IQF 1Kg/EA) | Y25: 1000 | AA25: 42 | AB25: =T25*AD25 -> #DIV/0! | AC25: =U25*AD25 -> #DIV/0! | AD25: =AA25/E25 -> #DIV/0! | AE25: 145349 | AF25: =IFERROR(INDEX([1]Sheet1!$A$2:$X$1948,MATCH($AE$2:$AE$270,[1]Sheet1!$G$2:$G$1948,0),8),"") -> 이츠웰 사골엑기스(1Kg/EA) | AH25: =P25*AJ25 -> #DIV/0! | AI25: =Q25*AJ25 -> #DIV/0! | AJ25: =AG25/$E25 -> #DIV/0! | AL25: =IFERROR(INDEX([1]Sheet1!$A$2:$X$1948,MATCH($AK$2:$AK$270,[1]Sheet1!$G$2:$G$1948,0),8),"") -> 0
A26: 26 | C26: 유부미소국 | H26: 유부(원료수입산)10%, 팽이버섯(국산)2%, 미소된장(국내산), 정제수, 멸치육수농축액, 실파, 마늘, 소금 | I26: .5. | J26: 20g / 25g
A27: 27 | C27: 전복소라미역국 | H27: 불린미역(국산)20%, 전복소라다이스[피뿔고동살(불가리아,터키,루마니아등)50%, 논우렁살(베트남산)30%, 전복살(말레이시아,인도네시아,중국 등)20%]5%, 정제수, 밥새우, 멸치육수농축액, 국간장, 참기름, 마늘, 소금 | I27: .5.9.18.21. | J27: 25g / 30g
A28: 28 | C28: 조랭이떡국 | H28: 조랭이떡(쌀:국산)25%, 소고기(호주산)3.5%, 계란(국내산)1%, 대파, 마늘, 국간장, 정제수, 소금 | I28: .1.5.16. | J28: 40g / 45g | O28: =E28 -> 0 | P28: =D28 -> 0 | Q28: =D28 -> 0 | R28: g | S28: =E28 -> 0 | T28: =D28 -> 0 | U28: =D28 -> 0 | W28: 192918 | X28: =IFERROR(INDEX([1]Sheet1!$A$2:$X$1948,MATCH($W$2:$W$270,[1]Sheet1!$G$2:$G$1948,0),8),"") -> 양배추(겉잎제거 KG) | Y28: 1000 | AA28: 35 | AB28: =T28*AD28 -> #DIV/0! | AC28: =U28*AD28 -> #DIV/0! | AD28: =AA28/E28 -> #DIV/0! | AE28: 424285 | AF28: =IFERROR(INDEX([1]Sheet1!$A$2:$X$1948,MATCH($AE$2:$AE$270,[1]Sheet1!$G$2:$G$1948,0),8),"") -> 소양지(3*2*0.3cm_저지방 키즈용_국거리용 KG) | AG28: 16 | AH28: =P28*AJ28 -> #DIV/0! | AI28: =Q28*AJ28 -> #DIV/0! | AJ28: =AG28/$E28 -> #DIV/0! | AL28: =IFERROR(INDEX([1]Sheet1!$A$2:$X$1948,MATCH($AK$2:$AK$270,[1]Sheet1!$G$2:$G$1948,0),8),"") -> 0
A29: 29 | C29: 소고기탕국 | H29: 무(국산)15%, 소고기(호주산)8%, 두부(원료수입산)5%, 양파, 대파, 마늘, 정제수, 멸치육수농축액, 국간장, 소금 | I29: .5.16. | J29: 40g / 45g
A30: 30 | C30: 북어국 | H30: 북어채(러시아산)5%, 두부(원료수입산)12%, 무8%, 양파, 정제수, 대파, 마늘, 참기름, 국간장, 소금 | I30: .5.21. | J30: 40g / 45g | L30: 2535 | M30: 126.75 | N30: 2661.75 | O30: =E30 -> 0 | P30: =D30 -> 0 | Q30: =D30 -> 0 | R30: g | S30: =E30 -> 0 | T30: =D30 -> 0 | U30: =D30 -> 0 | W30: 211037 | X30: =IFERROR(INDEX([1]Sheet1!$A$2:$X$1948,MATCH($W$2:$W$270,[1]Sheet1!$G$2:$G$1948,0),8),"") -> 느타리버섯(실속 균상 2Kg/EA) | Y30: 2000 | AA30: 23 | AB30: =T30*AD30 -> #DIV/0! | AC30: =U30*AD30 -> #DIV/0! | AD30: =AA30/E30 -> #DIV/0! | AE30: 205745 | AF30: =IFERROR(INDEX([1]Sheet1!$A$2:$X$1948,MATCH($AE$2:$AE$270,[1]Sheet1!$G$2:$G$1948,0),8),"") -> 총알새송이버섯(실속 2Kg/BOX) | AG30: 11 | AH30: =P30*AJ30 -> #DIV/0! | AI30: =Q30*AJ30 -> #DIV/0! | AJ30: =AG30/$E30 -> #DIV/0! | AL30: =IFERROR(INDEX([1]Sheet1!$A$2:$X$1948,MATCH($AK$2:$AK$270,[1]Sheet1!$G$2:$G$1948,0),8),"") -> 0
A31: 31 | C31: 순두부된장국 | H31: 순두부(콩:미국,캐나다,호주등)25%, 된장(국산), 파, 마늘, 정제수, 멸치육수농축액, 소금 | I31: .5. | O31: =E31 -> 0 | P31: =D31 -> 0 | Q31: =D31 -> 0 | R31: g | S31: =E31 -> 0 | T31: =D31 -> 0 | U31: =D31 -> 0 | W31: 193090 | X31: =IFERROR(INDEX([1]Sheet1!$A$2:$X$1948,MATCH($W$2:$W$270,[1]Sheet1!$G$2:$G$1948,0),8),"") -> 냉동감자(절단_3~4cm 1Kg/EA) | Y31: 1000 | AA31: 30 | AB31: =T31*AD31 -> #DIV/0! | AC31: =U31*AD31 -> #DIV/0! | AD31: =AA31/E31 -> #DIV/0! | AE31: 204964 | AF31: =IFERROR(INDEX([1]Sheet1!$A$2:$X$1948,MATCH($AE$2:$AE$270,[1]Sheet1!$G$2:$G$1948,0),8),"") -> 냉동표고버섯(슬라이스 1Kg/PAC) | AG31: 13 | AH31: =P31*AJ31 -> #DIV/0! | AI31: =Q31*AJ31 -> #DIV/0! | AJ31: =AG31/$E31 -> #DIV/0! | AL31: =IFERROR(INDEX([1]Sheet1!$A$2:$X$1948,MATCH($AK$2:$AK$270,[1]Sheet1!$G$2:$G$1948,0),8),"") -> 0 | AN31: =P31*AP31 -> #DIV/0! | AO31: =Q31*AP31 -> #DIV/0! | AP31: =AM31/$E31 -> #DIV/0!
A32: 32 | C32: 맑은닭곰탕 | H32: 닭고기(국산)12%, 무(국산)10%, 정제수, 파, 마늘, 소금 | I32: .5.16.
A33: 33 | C33: 숙주닭곰탕 | H33: 닭고기(국내산)12%, 숙주(녹두:외국산), 파, 마늘, 소금, 치킨스톡 | I33: .5.16. | J33: 35g /40g
A34: 34 | C34: 우거지된장국 | H34: 우거지(국산)17%, 두부(원료수입산)10.7%, 양파, 대파, 마늘, 된장, 정제수, 멸치육수농축액, 소금 | I34: .5.
A35: 35 | C35: 대파계란탕 | H35: 계란(국산)20%, 대파(국산)2%, 마늘, 멸치육수농축액, 정제수, 소금 | I35: .1.5. | J35: 멸치육수농축액(면사랑)
A36: 36 | C36: 게살계란탕 | H36: 계란(국산)18.7%, 게살(국산)3.5%, 팽이버섯, 파, 마늘, 멸치육수농축액, 정제수, 녹말가루, 소금, 참기름 | I36: .1.2.5.8.21.
A37: 37 | C37: 논우렁살된장찌개 | H37: 논우렁살(우렁:베트남산), 모둠채소(호박, 양파, 감자:국산)25%, 두부(콩:미국,호주,캐나다등)8%, 파, 마늘, 된장, 멸치육수농축액, 정제수, 소금 | I37: .5. | J37: 50g / 60g
A38: 38 | C38: 순두부된장찌개 | H38: 모둠채소(호박, 양파, 감자:국산)20%, 순두부(콩:미국,호주,캐나다등)12%, 파, 마늘, 된장, 멸치육수농축액, 정제수, 소금 | I38: .5. | J38: 50g / 60g
C39: 된장찌개 | H39: 모둠채소(호박, 양파, 감자:국산)20%, 두부(콩:미국,호주,캐나다등)12%, 파, 마늘, 된장, 멸치육수농축액, 정제수, 소금 | I39: .5. | J39: 50g / 60g
A40: 37 | C40: 호박잎된장찌개 | H40: 호박잎(국내산)5%, 모둠채소(호박, 양파, 감자:국산)20%, 두부(콩:미국,호주,캐나다등)8%, 파, 마늘, 된장, 멸치육수농축액, 정제수, 소금 | I40: .5.
...

Sheet 08-03
B1: 2026-08-03(월) | M1: *한입해쉬브라운 : 9g(개당) | P1: *양송이떡갈비 : 1.5ea, 1.75, 2 | S1: *양배추당근라페 : 20g / 30g
B2: 출고일 | C2: 구분 | D2: 품명 | E2: 중량(g) | F2: 수량(장) | G2: 자재사용내역 | H2: 알러지 표기 | I2: 배송시점 | J2: 제공인원 | K2: 총생산량(Kg) | L2: 메 모 | M2: *샐러드 채소 : 15g, 20g ,25g | P2: *야채고기말이 : 1.1, 1.5, 1.5 | S2: *고구마튀김35g / 45g
B3: 중식 | C3: 밥 | D3: 친환경찰현미쌀밥 | E3: 140 | G3: =IFERROR(INDEX(레시피북!$C$2:$H$618,MATCH($D3,레시피북!$C$2:$C$618,0),6),"") -> 쌀(국산)90%, 현미(국산.친환경)5%, 정제수 | H3: =IFERROR(INDEX(레시피북!$D$2:$J$611,MATCH($D3,레시피북!$C$2:$C$611,0),6),"") -> 0 | I3: 2026-08-03 09:30~ | J3: 2605 | K3: 386710 | L3: =IFERROR(INDEX(레시피북!$C$2:$J$611,MATCH($D3,레시피북!$C$2:$C$611,0),8),"") -> 0 | M3: *웨지감자 : 25g / 30g | O3: *어묵채구이:12g / 15g | S3: 한입새우튀김 : 30g / 40g / 50g (소스15g)
C4: 국 | D4: 두부탕국 | E4: 150 | G4: =IFERROR(INDEX(레시피북!$C$2:$H$618,MATCH($D4,레시피북!$C$2:$C$618,0),6),"") -> 두부(원료수입산)18%, 무(국산)10%,, 파, 마늘, 정제수, 멸치육수농축액, 국간장, 소금 | H4: =IFERROR(INDEX(레시피북!$D$2:$J$611,MATCH($D4,레시피북!$C$2:$C$611,0),6),"") -> .5. | I4: 2026-08-03 09:30~ | J4: 2605 | K4: 392590 | L4: =IFERROR(INDEX(레시피북!$C$2:$J$611,MATCH($D4,레시피북!$C$2:$C$611,0),8),"") -> 멸치육수농축액(면사랑) 40g / 45g ) | M4: *꼬마돈까스: 25g, 중구청 35g | P4: *족발:45g / 55g | S4: *갈비만두 : 성분표기 인당1개 / 식수 인당1.5개
C5: 메인 | D5: 유니짜장덮밥소스 | E5: 110 | G5: =IFERROR(INDEX(레시피북!$C$2:$H$618,MATCH($D5,레시피북!$C$2:$C$618,0),6),"") -> 돼지고기(국내산)14.9%, 모둠채소[양배추, 양파, 감자, 당근]25%, 대파, 마늘, 대두유 ,춘장, 짜장분말, 정제수, 전분 | H5: =IFERROR(INDEX(레시피북!$D$2:$J$611,MATCH($D5,레시피북!$C$2:$C$611,0),6),"") -> .2.5.6.10.15.16. | I5: 2026-08-03 09:30~ | J5: 2605 | K5: 326595 | L5: =IFERROR(INDEX(레시피북!$C$2:$J$611,MATCH($D5,레시피북!$C$2:$C$611,0),8),"") -> 짜장분말(오뚜기), 춘장(신송식품) | M5: *오징어볼탕수 : 35g / 45g/ 70g 소스 : 20g | S5: *생선통살탕수 : 40g / 50g / 교사 70g, 소스 25g 개당 12g
C6: 반찬1 | D6: 계란후라이 | F6: 1 | G6: =IFERROR(INDEX(레시피북!$C$2:$H$618,MATCH($D6,레시피북!$C$2:$C$618,0),6),"") -> 계란(국산)90%, 대두유, 옥수수전분, 정제소금, 설탕 외 | H6: =IFERROR(INDEX(레시피북!$D$2:$J$611,MATCH($D6,레시피북!$C$2:$C$611,0),6),"") -> .1.5.18. | I6: 2026-08-03 09:30~ | J6: 2605 | K6: 2761.8 | L6: =IFERROR(INDEX(레시피북!$C$2:$J$611,MATCH($D6,레시피북!$C$2:$C$611,0),8),"") -> 풍림푸드 | M6: *표고강정 : 30g(35g) | P6: *훈제오리 : 40g / 50g | S6: *해물전:1000680205(삼성웰스토리)
C7: 반찬2 | D7: 숙주나물 | E7: 25 | G7: =IFERROR(INDEX(레시피북!$C$2:$H$618,MATCH($D7,레시피북!$C$2:$C$618,0),6),"") -> 숙주(녹두:외국산)90%, 당근, 마늘, 대파, 참치액, 소금, 참기름, 참깨 | H7: =IFERROR(INDEX(레시피북!$D$2:$J$611,MATCH($D7,레시피북!$C$2:$C$611,0),6),"") -> .5.21. | I7: 2026-08-03 09:30~ | J7: 2605 | K7: 81242.5 | L7: =IFERROR(INDEX(레시피북!$C$2:$J$611,MATCH($D7,레시피북!$C$2:$C$611,0),8),"") -> 0 | M7: *탕수육40g(중구청50g) ,소스25g | P7: *마카로니.콘샐러드 : 30g | S7: *통등심돈까스:50g / 소스 25g
C8: 반찬3 | D8: 배추김치 | E8: 25 | G8: =IFERROR(INDEX(레시피북!$C$2:$H$618,MATCH($D8,레시피북!$C$2:$C$618,0),6),"") -> 절임배추64.0%[배추(국산),무(국산),종가김치전용풀(쌀:국산)], 토마토페이스트(토마토:미국산)2.7%,[멸치액젓, 양파,다시마농축액,고춧가루,마늘,대파,새우액젓,김치유산균발효액,생강양념,호화쌀혼합분말]국산 | H8: =IFERROR(INDEX(레시피북!$D$2:$J$611,MATCH($D8,레시피북!$C$2:$C$611,0),6),"") -> .9.12. | I8: 2026-08-03 09:30~ | J8: 2605 | K8: 70150 | L8: =IFERROR(INDEX(레시피북!$C$2:$J$611,MATCH($D8,레시피북!$C$2:$C$611,0),8),"") -> 토마토김치(종가집) | M8: *건두부무침 : 25g / 35g | P8: *파르펠레냉파스타:30g | S8: *족발부추무침 : 45g, 55g
C9: 보존식 | G9: 포도클럽 : 백김치 | J9: 1 | K9: 0.25
B10: 글로벌 리더스 . 석식 | C10: 밥 | D10: 친환경찰현미쌀밥 | E10: 150 | G10: =IFERROR(INDEX(레시피북!$C$2:$H$618,MATCH($D10,레시피북!$C$2:$C$618,0),6),"") -> 쌀(국산)90%, 현미(국산.친환경)5%, 정제수 | H10: =IFERROR(INDEX(레시피북!$D$2:$J$611,MATCH($D10,레시피북!$C$2:$C$611,0),6),"") -> 0 | I10: 2026-08-03 14:30~ | J10: 48 | K10: 7650 | L10: =IFERROR(INDEX(레시피북!$C$2:$J$611,MATCH($D10,레시피북!$C$2:$C$611,0),8),"") -> 0 | M10: *영양찜닭:85g / 95g | P10: *소고기가지볶음 : 30g | S10: *춘장닭불고기 : 70g / 80g
C11: 국 | D11: 두부탕국 | E11: 160 | G11: =IFERROR(INDEX(레시피북!$C$2:$H$618,MATCH($D11,레시피북!$C$2:$C$618,0),6),"") -> 두부(원료수입산)18%, 무(국산)10%,, 파, 마늘, 정제수, 멸치육수농축액, 국간장, 소금 | H11: =IFERROR(INDEX(레시피북!$D$2:$J$611,MATCH($D11,레시피북!$C$2:$C$611,0),6),"") -> .5. | I11: 2026-08-03 14:30~ | J11: 48 | K11: 7850 | L11: =IFERROR(INDEX(레시피북!$C$2:$J$611,MATCH($D11,레시피북!$C$2:$C$611,0),8),"") -> 멸치육수농축액(면사랑) 40g / 45g ) | M11: *미트볼 : 개당10g | P11: *삼색소고기소보로 : 50g / 70g | S11: *훈제오리잡채 : 55g / 70g
C12: 메인 | D12: 유니짜장덮밥소스 | E12: 120 | G12: =IFERROR(INDEX(레시피북!$C$2:$H$618,MATCH($D12,레시피북!$C$2:$C$618,0),6),"") -> 돼지고기(국내산)14.9%, 모둠채소[양배추, 양파, 감자, 당근]25%, 대파, 마늘, 대두유 ,춘장, 짜장분말, 정제수, 전분 | H12: =IFERROR(INDEX(레시피북!$D$2:$J$611,MATCH($D12,레시피북!$C$2:$C$611,0),6),"") -> .2.5.6.10.15.16. | I12: 2026-08-03 14:30~ | J12: 48 | K12: 6336 | L12: =IFERROR(INDEX(레시피북!$C$2:$J$611,MATCH($D12,레시피북!$C$2:$C$611,0),8),"") -> 짜장분말(오뚜기), 춘장(신송식품)
C13: 반찬1 | D13: 계란후라이 | F13: 1 | G13: =IFERROR(INDEX(레시피북!$C$2:$H$618,MATCH($D13,레시피북!$C$2:$C$618,0),6),"") -> 계란(국산)90%, 대두유, 옥수수전분, 정제소금, 설탕 외 | H13: =IFERROR(INDEX(레시피북!$D$2:$J$611,MATCH($D13,레시피북!$C$2:$C$611,0),6),"") -> .1.5.18. | I13: 2026-08-03 14:30~ | J13: 48 | K13: 52.8 | L13: =IFERROR(INDEX(레시피북!$C$2:$J$611,MATCH($D13,레시피북!$C$2:$C$611,0),8),"") -> 풍림푸드
C14: 반찬2 | D14: 숙주나물 | E14: 40 | G14: =IFERROR(INDEX(레시피북!$C$2:$H$618,MATCH($D14,레시피북!$C$2:$C$618,0),6),"") -> 숙주(녹두:외국산)90%, 당근, 마늘, 대파, 참치액, 소금, 참기름, 참깨 | H14: =IFERROR(INDEX(레시피북!$D$2:$J$611,MATCH($D14,레시피북!$C$2:$C$611,0),6),"") -> .5.21. | I14: 2026-08-03 14:30~ | J14: 48 | K14: 1920 | L14: =IFERROR(INDEX(레시피북!$C$2:$J$611,MATCH($D14,레시피북!$C$2:$C$611,0),8),"") -> 0
C15: 반찬3 | D15: 배추김치 | E15: 35 | G15: =IFERROR(INDEX(레시피북!$C$2:$H$618,MATCH($D15,레시피북!$C$2:$C$618,0),6),"") -> 절임배추64.0%[배추(국산),무(국산),종가김치전용풀(쌀:국산)], 토마토페이스트(토마토:미국산)2.7%,[멸치액젓, 양파,다시마농축액,고춧가루,마늘,대파,새우액젓,김치유산균발효액,생강양념,호화쌀혼합분말]국산 | H15: =IFERROR(INDEX(레시피북!$D$2:$J$611,MATCH($D15,레시피북!$C$2:$C$611,0),6),"") -> .9.12. | I15: 2026-08-03 14:30~ | J15: 48 | K15: 1680 | L15: =IFERROR(INDEX(레시피북!$C$2:$J$611,MATCH($D15,레시피북!$C$2:$C$611,0),8),"") -> 토마토김치(종가집)
C16: 신당꿈 특식 | D16: 칠리새우 | E16: 70 | G16: =IFERROR(INDEX(레시피북!$C$2:$H$618,MATCH($D16,레시피북!$C$2:$C$618,0),6),"") -> 새우[새우(베트남산) 37.33%, 밀(미국산)28.32%, 대두유] 80%,칠리소스[파프리카, 완두콩, 마늘,대두유, 정제수,케첩, 설탕,식초, 전분]20% | H16: =IFERROR(INDEX(레시피북!$D$2:$J$611,MATCH($D16,레시피북!$C$2:$C$611,0),6),"") -> .1.5.6.9.17. | I16: 2026-08-03 14:30~ | J16: 28 | K16: 2320 | L16: =IFERROR(INDEX(레시피북!$C$2:$J$611,MATCH($D16,레시피북!$C$2:$C$611,0),8),"") -> 케찹(오뚜기), 한입깐쇼새우(이츠웰)
C17: 보존식 | J17: 1 | K17: 0.25
B18: 강서폴리 소풍 | C18: 밥 | G18: =IFERROR(INDEX(레시피북!$C$2:$H$618,MATCH($D18,레시피북!$C$2:$C$618,0),6),"") | H18: =IFERROR(INDEX(레시피북!$D$2:$J$611,MATCH($D18,레시피북!$C$2:$C$611,0),6),"") | I18: 2026-08-03 09:30~ | L18: =IFERROR(INDEX(레시피북!$C$2:$J$611,MATCH($D18,레시피북!$C$2:$C$611,0),8),"")
C19: 반찬1 | G19: =IFERROR(INDEX(레시피북!$C$2:$H$618,MATCH($D19,레시피북!$C$2:$C$618,0),6),"") | H19: =IFERROR(INDEX(레시피북!$D$2:$J$611,MATCH($D19,레시피북!$C$2:$C$611,0),6),"") | I19: 2026-08-03 09:30~ | L19: =IFERROR(INDEX(레시피북!$C$2:$J$611,MATCH($D19,레시피북!$C$2:$C$611,0),8),"")
G20: =IFERROR(INDEX(레시피북!$C$2:$H$618,MATCH($D20,레시피북!$C$2:$C$618,0),6),"") | H20: =IFERROR(INDEX(레시피북!$D$2:$J$611,MATCH($D20,레시피북!$C$2:$C$611,0),6),"") | I20: 2026-08-03 09:30~ | L20: =IFERROR(INDEX(레시피북!$C$2:$J$611,MATCH($D20,레시피북!$C$2:$C$611,0),8),"")
C21: 반찬2 | G21: =IFERROR(INDEX(레시피북!$C$2:$H$618,MATCH($D21,레시피북!$C$2:$C$618,0),6),"") | H21: =IFERROR(INDEX(레시피북!$D$2:$J$611,MATCH($D21,레시피북!$C$2:$C$611,0),6),"") | I21: 2026-08-03 09:30~ | L21: =IFERROR(INDEX(레시피북!$C$2:$J$611,MATCH($D21,레시피북!$C$2:$C$611,0),8),"")
C22: 반찬3 | G22: =IFERROR(INDEX(레시피북!$C$2:$H$618,MATCH($D22,레시피북!$C$2:$C$618,0),6),"") | H22: =IFERROR(INDEX(레시피북!$D$2:$J$611,MATCH($D22,레시피북!$C$2:$C$611,0),6),"") | I22: 2026-08-03 09:30~ | L22: =IFERROR(INDEX(레시피북!$C$2:$J$611,MATCH($D22,레시피북!$C$2:$C$611,0),8),"")
C23: 반찬4 | G23: =IFERROR(INDEX(레시피북!$C$2:$H$618,MATCH($D23,레시피북!$C$2:$C$618,0),6),"") | H23: =IFERROR(INDEX(레시피북!$D$2:$J$611,MATCH($D23,레시피북!$C$2:$C$611,0),6),"") | I23: 2026-08-03 09:30~ | L23: =IFERROR(INDEX(레시피북!$C$2:$J$611,MATCH($D23,레시피북!$C$2:$C$611,0),8),"")
C24: 보존식 | F24: 1 | J24: 1 | K24: 0.25

Sheet 08-04
B1: 2026-08-04(화) | M1: *한입해쉬브라운 : 9g(개당) | P1: *양송이떡갈비 : 1.5ea, 1.75, 2 | S1: *양배추당근라페 : 20g / 30g
B2: 출고일 | C2: 구분 | D2: 품명 | E2: 중량(g) | F2: 수량(장) | G2: 자재사용내역 | H2: 알러지 표기 | I2: 배송시점 | J2: 제공인원 | K2: 총생산량(Kg) | L2: 메 모 | M2: *샐러드 채소 : 15g, 20g ,25g | P2: *야채고기말이 : 1.1, 1.5, 1.5 | S2: *고구마튀김35g / 45g
B3: 중식 | C3: 밥 | D3: 친환경귀리쌀밥 | E3: 140 | G3: =IFERROR(INDEX(레시피북!$C$2:$H$618,MATCH($D3,레시피북!$C$2:$C$618,0),6),"") -> 쌀(국산)90%, 귀리(국산.친환경)5%, 정제수 | H3: =IFERROR(INDEX(레시피북!$D$2:$J$611,MATCH($D3,레시피북!$C$2:$C$611,0),6),"") -> 0 | I3: 2026-08-04 09:30~ | J3: 2618 | K3: 386850 | L3: =IFERROR(INDEX(레시피북!$C$2:$J$611,MATCH($D3,레시피북!$C$2:$C$611,0),8),"") -> 0 | M3: *웨지감자 : 25g / 30g | O3: *어묵채구이:12g / 15g | S3: 한입새우튀김 : 30g / 40g / 50g (소스15g)
C4: 국 | D4: 우삼겹된장찌개 | E4: 150 | G4: =IFERROR(INDEX(레시피북!$C$2:$H$618,MATCH($D4,레시피북!$C$2:$C$618,0),6),"") -> 모둠채소(호박, 양파, 새송이:국산)20%, 두부(콩:미국,호주,캐나다등)8%, 소고기(미국산)3%, 파, 마늘, 된장, 멸치육수농축액, 정제수, 소금 | H4: =IFERROR(INDEX(레시피북!$D$2:$J$611,MATCH($D4,레시피북!$C$2:$C$611,0),6),"") -> .5.16. | I4: 2026-08-04 09:30~ | J4: 2618 | K4: 393480 | L4: =IFERROR(INDEX(레시피북!$C$2:$J$611,MATCH($D4,레시피북!$C$2:$C$611,0),8),"") -> 50g / 60g | M4: *꼬마돈까스: 25g, 중구청 35g | P4: *족발:45g / 55g | S4: *갈비만두 : 성분표기 인당1개 / 식수 인당1.5개
C5: 메인 | D5: 닭살떡조림 | E5: 60 | G5: =IFERROR(INDEX(레시피북!$C$2:$H$618,MATCH($D5,레시피북!$C$2:$C$618,0),6),"") -> 닭고기[닭가슴살70%(국산), 닭다리살30%(브라질산)]75%, 모양떡(쌀:수입산)15%, 정제수, 간장, 물엿, 설탕, 후추, 참기름 | H5: =IFERROR(INDEX(레시피북!$D$2:$J$611,MATCH($D5,레시피북!$C$2:$C$611,0),6),"") -> .5.15.21. | I5: 2026-08-04 09:30~ | J5: 2618 | K5: 190020 | L5: =IFERROR(INDEX(레시피북!$C$2:$J$611,MATCH($D5,레시피북!$C$2:$C$611,0),8),"") -> 0 | M5: *오징어볼탕수 : 35g / 45g/ 70g 소스 : 20g | S5: *생선통살탕수 : 40g / 50g / 교사 70g, 소스 25g 개당 12g
C6: 반찬1 | D6: 햄에그롤 | F6: 2 | G6: =IFERROR(INDEX(레시피북!$C$2:$H$618,MATCH($D6,레시피북!$C$2:$C$618,0),6),"") -> 계란(전락액59.6%, 난백액18.41% :국산), 프레스햄[(돼지고기(국산),돈지방(국산), 설탕]16%, 정제소금, 다시마엑기스, 양조간장, 소고기다시 | H6: =IFERROR(INDEX(레시피북!$D$2:$J$611,MATCH($D6,레시피북!$C$2:$C$611,0),6),"") -> .1.2.5.6.10.16. | I6: 2026-08-04 09:30~ | J6: 2618 | K6: 6691.8 | L6: =IFERROR(INDEX(레시피북!$C$2:$J$611,MATCH($D6,레시피북!$C$2:$C$611,0),8),"") -> 풍요한아침 햄에그롤(풍림푸드)/15g / 160원 | M6: *표고강정 : 30g(35g) | P6: *훈제오리 : 40g / 50g | S6: *해물전:1000680205(삼성웰스토리)
C7: 반찬2 | D7: 콩나물청경채무침 | E7: 30 | G7: =IFERROR(INDEX(레시피북!$C$2:$H$618,MATCH($D7,레시피북!$C$2:$C$618,0),6),"") -> 콩나물(원료수입산)90%, 청경채(국산)2%, 마늘, 대파, 참치액, 소금, 참기름, 참깨 | H7: =IFERROR(INDEX(레시피북!$D$2:$J$611,MATCH($D7,레시피북!$C$2:$C$611,0),6),"") -> .21. | I7: 2026-08-04 09:30~ | J7: 2618 | K7: 93610 | L7: =IFERROR(INDEX(레시피북!$C$2:$J$611,MATCH($D7,레시피북!$C$2:$C$611,0),8),"") -> 0 | M7: *탕수육40g(중구청50g) ,소스25g | P7: *마카로니.콘샐러드 : 30g | S7: *통등심돈까스:50g / 소스 25g
C8: 반찬3 | D8: 깍두기 | E8: 25 | G8: =IFERROR(INDEX(레시피북!$C$2:$H$618,MATCH($D8,레시피북!$C$2:$C$618,0),6),"") -> 무(국산)85.2%, 고추가루(국산), 밀가루풀(국산), 파, 마늘, 새우젓 등 양념(국산) | H8: =IFERROR(INDEX(레시피북!$D$2:$J$611,MATCH($D8,레시피북!$C$2:$C$611,0),6),"") -> .6.9. | I8: 2026-08-04 09:30~ | J8: 2618 | K8: 72790 | L8: =IFERROR(INDEX(레시피북!$C$2:$J$611,MATCH($D8,레시피북!$C$2:$C$611,0),8),"") -> 0 | M8: *건두부무침 : 25g / 35g | P8: *파르펠레냉파스타:30g | S8: *족발부추무침 : 45g, 55g
C9: 보존식 | J9: 1 | K9: 0.25
B10: 글로벌 리더스 . 석식 | C10: 밥 | D10: 친환경귀리쌀밥 | E10: 150 | G10: =IFERROR(INDEX(레시피북!$C$2:$H$618,MATCH($D10,레시피북!$C$2:$C$618,0),6),"") -> 쌀(국산)90%, 귀리(국산.친환경)5%, 정제수 | H10: =IFERROR(INDEX(레시피북!$D$2:$J$611,MATCH($D10,레시피북!$C$2:$C$611,0),6),"") -> 0 | I10: 2026-08-04 14:30~ | J10: 49 | K10: 7800 | L10: =IFERROR(INDEX(레시피북!$C$2:$J$611,MATCH($D10,레시피북!$C$2:$C$611,0),8),"") -> 0 | M10: *영양찜닭:85g / 95g | P10: *소고기가지볶음 : 30g | S10: *춘장닭불고기 : 70g / 80g
C11: 국 | D11: 매콤우삼겹된장찌개 | E11: 160 | G11: 모둠채소(호박, 양파, 새송이:국산)20%, 두부(콩:미국,호주,캐나다등)8%, 소고기(미국산)3%, 파, 마늘, 된장, 고춧가루(국내산), 멸치육수농축액, 정제수, 소금 | H11: =IFERROR(INDEX(레시피북!$D$2:$J$611,MATCH($D11,레시피북!$C$2:$C$611,0),6),"") | I11: 2026-08-04 14:30~ | J11: 49 | K11: 8010 | L11: =IFERROR(INDEX(레시피북!$C$2:$J$611,MATCH($D11,레시피북!$C$2:$C$611,0),8),"") | M11: *미트볼 : 개당10g | P11: *삼색소고기소보로 : 50g / 70g | S11: *훈제오리잡채 : 55g / 70g
C12: 메인 | D12: 닭살떡조림 | E12: 80 | G12: =IFERROR(INDEX(레시피북!$C$2:$H$618,MATCH($D12,레시피북!$C$2:$C$618,0),6),"") -> 닭고기[닭가슴살70%(국산), 닭다리살30%(브라질산)]75%, 모양떡(쌀:수입산)15%, 정제수, 간장, 물엿, 설탕, 후추, 참기름 | H12: =IFERROR(INDEX(레시피북!$D$2:$J$611,MATCH($D12,레시피북!$C$2:$C$611,0),6),"") -> .5.15.21. | I12: 2026-08-04 14:30~ | J12: 49 | K12: 4304 | L12: =IFERROR(INDEX(레시피북!$C$2:$J$611,MATCH($D12,레시피북!$C$2:$C$611,0),8),"") -> 0
C13: 반찬1 | D13: 햄에그롤 | F13: 3 | G13: =IFERROR(INDEX(레시피북!$C$2:$H$618,MATCH($D13,레시피북!$C$2:$C$618,0),6),"") -> 계란(전락액59.6%, 난백액18.41% :국산), 프레스햄[(돼지고기(국산),돈지방(국산), 설탕]16%, 정제소금, 다시마엑기스, 양조간장, 소고기다시 | H13: =IFERROR(INDEX(레시피북!$D$2:$J$611,MATCH($D13,레시피북!$C$2:$C$611,0),6),"") -> .1.2.5.6.10.16. | I13: 2026-08-04 14:30~ | J13: 49 | K13: 151.9 | L13: =IFERROR(INDEX(레시피북!$C$2:$J$611,MATCH($D13,레시피북!$C$2:$C$611,0),8),"") -> 풍요한아침 햄에그롤(풍림푸드)/15g / 160원
C14: 반찬2 | D14: 콩나물청경채무침 | E14: 40 | G14: =IFERROR(INDEX(레시피북!$C$2:$H$618,MATCH($D14,레시피북!$C$2:$C$618,0),6),"") -> 콩나물(원료수입산)90%, 청경채(국산)2%, 마늘, 대파, 참치액, 소금, 참기름, 참깨 | H14: =IFERROR(INDEX(레시피북!$D$2:$J$611,MATCH($D14,레시피북!$C$2:$C$611,0),6),"") -> .21. | I14: 2026-08-04 14:30~ | J14: 49 | K14: 1960 | L14: =IFERROR(INDEX(레시피북!$C$2:$J$611,MATCH($D14,레시피북!$C$2:$C$611,0),8),"") -> 0
C15: 반찬3 | D15: 깍두기 | E15: 35 | G15: =IFERROR(INDEX(레시피북!$C$2:$H$618,MATCH($D15,레시피북!$C$2:$C$618,0),6),"") -> 무(국산)85.2%, 고추가루(국산), 밀가루풀(국산), 파, 마늘, 새우젓 등 양념(국산) | H15: =IFERROR(INDEX(레시피북!$D$2:$J$611,MATCH($D15,레시피북!$C$2:$C$611,0),6),"") -> .6.9. | I15: 2026-08-04 14:30~ | J15: 49 | K15: 1715 | L15: =IFERROR(INDEX(레시피북!$C$2:$J$611,MATCH($D15,레시피북!$C$2:$C$611,0),8),"") -> 0
C16: 신당꿈 특식 | D16: 과일 | F16: 1 | G16: 복숭아(국내산) | H16: =IFERROR(INDEX(레시피북!$D$2:$J$611,MATCH($D16,레시피북!$C$2:$C$611,0),6),"") | I16: 2026-08-04 14:30~ | J16: 28 | K16: 30 | L16: =IFERROR(INDEX(레시피북!$C$2:$J$611,MATCH($D16,레시피북!$C$2:$C$611,0),8),"")
C17: 보존식 | J17: 1 | K17: 0.25
B18: 강서폴리 소풍 | C18: 밥 | G18: =IFERROR(INDEX(레시피북!$C$2:$H$618,MATCH($D18,레시피북!$C$2:$C$618,0),6),"") | H18: =IFERROR(INDEX(레시피북!$D$2:$J$611,MATCH($D18,레시피북!$C$2:$C$611,0),6),"") | I18: 2026-08-04 09:30~ | L18: =IFERROR(INDEX(레시피북!$C$2:$J$611,MATCH($D18,레시피북!$C$2:$C$611,0),8),"")
C19: 반찬1 | G19: =IFERROR(INDEX(레시피북!$C$2:$H$618,MATCH($D19,레시피북!$C$2:$C$618,0),6),"") | H19: =IFERROR(INDEX(레시피북!$D$2:$J$611,MATCH($D19,레시피북!$C$2:$C$611,0),6),"") | I19: 2026-08-04 09:30~ | L19: =IFERROR(INDEX(레시피북!$C$2:$J$611,MATCH($D19,레시피북!$C$2:$C$611,0),8),"")
G20: =IFERROR(INDEX(레시피북!$C$2:$H$618,MATCH($D20,레시피북!$C$2:$C$618,0),6),"") | H20: =IFERROR(INDEX(레시피북!$D$2:$J$611,MATCH($D20,레시피북!$C$2:$C$611,0),6),"") | I20: 2026-08-04 09:30~ | L20: =IFERROR(INDEX(레시피북!$C$2:$J$611,MATCH($D20,레시피북!$C$2:$C$611,0),8),"")
C21: 반찬2 | G21: =IFERROR(INDEX(레시피북!$C$2:$H$618,MATCH($D21,레시피북!$C$2:$C$618,0),6),"") | H21: =IFERROR(INDEX(레시피북!$D$2:$J$611,MATCH($D21,레시피북!$C$2:$C$611,0),6),"") | I21: 2026-08-04 09:30~ | L21: =IFERROR(INDEX(레시피북!$C$2:$J$611,MATCH($D21,레시피북!$C$2:$C$611,0),8),"")
C22: 반찬3 | G22: =IFERROR(INDEX(레시피북!$C$2:$H$618,MATCH($D22,레시피북!$C$2:$C$618,0),6),"") | H22: =IFERROR(INDEX(레시피북!$D$2:$J$611,MATCH($D22,레시피북!$C$2:$C$611,0),6),"") | I22: 2026-08-04 09:30~ | L22: =IFERROR(INDEX(레시피북!$C$2:$J$611,MATCH($D22,레시피북!$C$2:$C$611,0),8),"")
C23: 반찬4 | G23: =IFERROR(INDEX(레시피북!$C$2:$H$618,MATCH($D23,레시피북!$C$2:$C$618,0),6),"") | H23: =IFERROR(INDEX(레시피북!$D$2:$J$611,MATCH($D23,레시피북!$C$2:$C$611,0),6),"") | I23: 2026-08-04 09:30~ | L23: =IFERROR(INDEX(레시피북!$C$2:$J$611,MATCH($D23,레시피북!$C$2:$C$611,0),8),"")
C24: 보존식 | F24: 1 | J24: 1 | K24: 0.25

Sheet 08-05
B1: 2026-08-05(수) | M1: *한입해쉬브라운 : 9g(개당) | P1: *양송이떡갈비 : 1.5ea, 1.75, 2 | S1: *양배추당근라페 : 20g / 30g
B2: 출고일 | C2: 구분 | D2: 품명 | E2: 중량(g) | F2: 수량(장) | G2: 자재사용내역 | H2: 알러지 표기 | I2: 배송시점 | J2: 제공인원 | K2: 총생산량(Kg) | L2: 메 모 | M2: *샐러드 채소 : 15g, 20g ,25g | P2: *야채고기말이 : 1.1, 1.5, 1.5 | S2: *고구마튀김35g / 45g
B3: 중식 | C3: 밥 | D3: 친환경찰흑미쌀밥 | E3: 140 | G3: =IFERROR(INDEX(레시피북!$C$2:$H$618,MATCH($D3,레시피북!$C$2:$C$618,0),6),"") -> 쌀(국산)90%, 찰흑미(국산.친환경)5%, 정제수 | H3: =IFERROR(INDEX(레시피북!$D$2:$J$611,MATCH($D3,레시피북!$C$2:$C$611,0),6),"") -> 0 | I3: 2026-08-05 09:30~ | J3: 2764 | K3: 408570 | L3: =IFERROR(INDEX(레시피북!$C$2:$J$611,MATCH($D3,레시피북!$C$2:$C$611,0),8),"") -> 0 | M3: *웨지감자 : 25g / 30g | O3: *어묵채구이:12g / 15g | S3: 한입새우튀김 : 30g / 40g / 50g (소스15g)
C4: 국 | D4: 들깨미역국 | E4: 150 | G4: =IFERROR(INDEX(레시피북!$C$2:$H$618,MATCH($D4,레시피북!$C$2:$C$618,0),6),"") -> 불린미역(국산)23%, 정제수, 거피들깨(중국산), 참기름, 국간장, 밥새우, 멸치육수농축액, 마늘, 소금 | H4: =IFERROR(INDEX(레시피북!$D$2:$J$611,MATCH($D4,레시피북!$C$2:$C$611,0),6),"") -> .5.9.21.22. | I4: 2026-08-05 09:30~ | J4: 2764 | K4: 414150 | L4: =IFERROR(INDEX(레시피북!$C$2:$J$611,MATCH($D4,레시피북!$C$2:$C$611,0),8),"") -> 25g / 30g | M4: *꼬마돈까스: 25g, 중구청 35g | P4: *족발:45g / 55g | S4: *갈비만두 : 성분표기 인당1개 / 식수 인당1.5개
C5: 메인 | D5: 미소된장제육 | E5: 60 | G5: =IFERROR(INDEX(레시피북!$C$2:$H$618,MATCH($D5,레시피북!$C$2:$C$618,0),6),"") -> 돼지고기(국산)80%, 양배추, 양파, 당근, 대파, 마늘, 미소된장[국내생산(대두.쌀:외국산)], 간장, 맛술, 참기름, 후추 | H5: =IFERROR(INDEX(레시피북!$D$2:$J$611,MATCH($D5,레시피북!$C$2:$C$611,0),6),"") -> .5.10.21. | I5: 2026-08-05 09:30~ | J5: 2764 | K5: 200435 | L5: =IFERROR(INDEX(레시피북!$C$2:$J$611,MATCH($D5,레시피북!$C$2:$C$611,0),8),"") -> 미소된장(범일) | M5: *오징어볼탕수 : 35g / 45g/ 70g 소스 : 20g | S5: *생선통살탕수 : 40g / 50g / 교사 70g, 소스 25g 개당 12g
C6: 반찬1 | D6: 명엽채조림 | E6: 20 | G6: =IFERROR(INDEX(레시피북!$C$2:$H$618,MATCH($D6,레시피북!$C$2:$C$618,0),6),"") -> 명엽채(국내산)95%, 마요네즈, 간장, 물엿, 참기름, 참깨 | H6: =IFERROR(INDEX(레시피북!$D$2:$J$611,MATCH($D6,레시피북!$C$2:$C$611,0),6),"") -> .1.5.21. | I6: 2026-08-05 09:30~ | J6: 2764 | K6: 63920 | L6: =IFERROR(INDEX(레시피북!$C$2:$J$611,MATCH($D6,레시피북!$C$2:$C$611,0),8),"") -> 0 | M6: *표고강정 : 30g(35g) | P6: *훈제오리 : 40g / 50g | S6: *해물전:1000680205(삼성웰스토리)
C7: 반찬2 | D7: 호박새우젓볶음 | E7: 30 | G7: =IFERROR(INDEX(레시피북!$C$2:$H$618,MATCH($D7,레시피북!$C$2:$C$618,0),6),"") -> 호박(국산)75%, 당근, 양파, 대파, 마늘, 대두유, 새우젓, 소금, 참기름, 참깨 | H7: =IFERROR(INDEX(레시피북!$D$2:$J$611,MATCH($D7,레시피북!$C$2:$C$611,0),6),"") -> .5.9.21. | I7: 2026-08-05 09:30~ | J7: 2764 | K7: 95230 | L7: =IFERROR(INDEX(레시피북!$C$2:$J$611,MATCH($D7,레시피북!$C$2:$C$611,0),8),"") -> 0 | M7: *탕수육40g(중구청50g) ,소스25g | P7: *마카로니.콘샐러드 : 30g | S7: *통등심돈까스:50g / 소스 25g
C8: 반찬3 | D8: 백김치 | E8: 25 | G8: =IFERROR(INDEX(레시피북!$C$2:$H$618,MATCH($D8,레시피북!$C$2:$C$618,0),6),"") -> 배추(국내산)70&, 무(국내산)10%, 마늘, 생강, 양파, 설탕, 정제수, 소금 | H8: =IFERROR(INDEX(레시피북!$D$2:$J$611,MATCH($D8,레시피북!$C$2:$C$611,0),6),"") -> 0 | I8: 2026-08-05 09:30~ | J8: 2764 | K8: 77415 | L8: =IFERROR(INDEX(레시피북!$C$2:$J$611,MATCH($D8,레시피북!$C$2:$C$611,0),8),"") -> 백김치(정우식품) | M8: *건두부무침 : 25g / 35g | P8: *파르펠레냉파스타:30g | S8: *족발부추무침 : 45g, 55g
C9: 보존식 | G9: 글로벌리더스 : 제육두루치기 | J9: 1 | K9: 0.25
