Workbook
Name 급식국: #REF!
Name 급식밥: #REF!
Name 김치: #REF!
Name 반찬1: #REF!
Name 반찬2: #REF!
Name 반찬3: #REF!
Name 반찬4: #REF!
Name 온라인국: #REF!

Sheet 식단표 (알레르기표기)
A1: 06월 식단표
A2: 요일 | B2: 월 | D2: 화 | F2: 수 | H2: 목 | J2: 금
A3: 날짜 | B3: 46174 | D3: 46175 | F3: 46176 | H3: 46177 | J3: 46178
A4: 주차 | B4: 메뉴 | C4: 알레르기표기 | D4: 메뉴 | E4: 알레르기표기 | F4: 메뉴 | G4: 알레르기표기 | H4: 메뉴 | I4: 알레르기표기 | J4: 메뉴 | K4: 알레르기표기
A5: 1주차 | B5: 친환경현미쌀밥 | C5: 0 | D5: 친환경귀리쌀밥 | E5: 0 | F5: ♣전국지방선거일♣ | H5: 흰쌀밥 | I5: 0 | J5: 친환경찰보리쌀밥 | K5: 0
B6: 통등심돈까스 | C6: 1.2.5.6.10. | D6: 닭살데리야끼조림 | E6: .1.2.5.6.15.21. | H6: 돈채춘장볶음 | I6: .1.2.5.6.10.15.16.21. | J6: 소고기낙지전골 | K6: .5.16.21.
B7: & 브라운소스 | C7: .5.6.12.16.18. | D7: 어묵채구이 | E7: .5.6.21. | H7: 꼬물이만두 | I7: .1.2.5.6.10.16.18.21. | J7: 메추리알조림 | K7: .1.5.21.
B8: 불고기떡볶이 | C8: .5.6.16.21. | D8: 청포묵무침 | E8: .1.5.21. | H8: 참치깍두기볶음 | I8: .5.6.9.21. | J8: 오이미역초무침 | K8: .5.21.
B9: 양배추당근라페 | C9: 0 | D9: 깍두기 | E9: .6.9. | H9: 백김치 | I9: 0 | J9: 배추김치 | K9: .9.12.
B10: 배추김치 | C10: .9.12. | D10: 소고기장국 | E10: .5.16. | H10: 순살동태국 | I10: .5.9.10. | J10: 시금치된장국 | K10: .5.
B11: 팽이미소국 | C11: .5.
A13: 날짜 | B13: 46181 | D13: 46182 | F13: 46183 | H13: 46184 | J13: 46185
A14: 주차 | B14: 메뉴 | C14: 알레르기표기 | D14: 메뉴 | E14: 알레르기표기 | F14: 메뉴 | G14: 알레르기표기 | H14: 메뉴 | I14: 알레르기표기 | J14: 메뉴 | K14: 알레르기표기
A15: 2주차 | B15: 친환경현미쌀밥 | C15: =IFERROR(INDEX([1]온라인_반찬!$C$2:$I$600,MATCH($B15,[1]온라인_반찬!$C$2:$C$600,0),7),"") -> 0 | D15: 친환경귀리쌀밥 | E15: =IFERROR(INDEX([1]온라인_반찬!$C$2:$I$600,MATCH($D15,[1]온라인_반찬!$C$2:$C$600,0),7),"") -> 0 | F15: 친환경찰흑미쌀밥 | G15: =IFERROR(INDEX([1]온라인_반찬!$C$2:$I$600,MATCH($F15,[1]온라인_반찬!$C$2:$C$600,0),7),"") -> 0 | H15: 흰쌀밥 | I15: =IFERROR(INDEX([1]온라인_반찬!$C$2:$I$600,MATCH($H15,[1]온라인_반찬!$C$2:$C$600,0),7),"") -> 0 | J15: 친환경찰보리쌀밥 | K15: =IFERROR(INDEX([1]온라인_반찬!$C$2:$I$600,MATCH($J15,[1]온라인_반찬!$C$2:$C$600,0),7),"") -> 0
B16: 코코넛커리소스 | C16: =IFERROR(INDEX([1]온라인_반찬!$C$2:$I$600,MATCH($B16,[1]온라인_반찬!$C$2:$C$600,0),7),"") -> .2.5.6.12.15.16.18. | D16: 돈갈비양념구이 | E16: =IFERROR(INDEX([1]온라인_반찬!$C$2:$I$600,MATCH($D16,[1]온라인_반찬!$C$2:$C$600,0),7),"") -> .5.6.10.21. | F16: 소고기양배추볶음 | G16: =IFERROR(INDEX([1]온라인_반찬!$C$2:$I$600,MATCH($F16,[1]온라인_반찬!$C$2:$C$600,0),7),"") -> .5.16.18.21. | H16: 토마토닭볶음탕 | I16: =IFERROR(INDEX([1]온라인_반찬!$C$2:$I$600,MATCH($H16,[1]온라인_반찬!$C$2:$C$600,0),7),"") -> .5.6.12.15. | J16: 불고기잡채 | K16: =IFERROR(INDEX([1]온라인_반찬!$C$2:$I$600,MATCH($J16,[1]온라인_반찬!$C$2:$C$600,0),7),"") -> .5.6.21.
B17: 새우튀김 | C17: =IFERROR(INDEX([1]온라인_반찬!$C$2:$I$600,MATCH($B17,[1]온라인_반찬!$C$2:$C$600,0),7),"") -> .1.5.6.9. | D17: 채소계란찜 | E17: =IFERROR(INDEX([1]온라인_반찬!$C$2:$I$600,MATCH($D17,[1]온라인_반찬!$C$2:$C$600,0),7),"") -> .1.2. | F17: 소세지채소볶음 | G17: =IFERROR(INDEX([1]온라인_반찬!$C$2:$I$600,MATCH($F17,[1]온라인_반찬!$C$2:$C$600,0),7),"") -> .5.6.10.12.15.16.21. | H17: 꼬마돈까스 | I17: =IFERROR(INDEX([1]온라인_반찬!$C$2:$I$600,MATCH($H17,[1]온라인_반찬!$C$2:$C$600,0),7),"") -> .1.5.6.10.15. | J17: 어간장두부조림 | K17: .5.6.8.
B18: 보코치니샐러드 | C18: =IFERROR(INDEX([1]온라인_반찬!$C$2:$I$600,MATCH($B18,[1]온라인_반찬!$C$2:$C$600,0),7),"") -> .2.4.12. | D18: 삼색콩나물무침 | E18: =IFERROR(INDEX([1]온라인_반찬!$C$2:$I$600,MATCH($D18,[1]온라인_반찬!$C$2:$C$600,0),7),"") -> .5.21. | F18: 검은콩멸치조림 | G18: =IFERROR(INDEX([1]온라인_반찬!$C$2:$I$600,MATCH($F18,[1]온라인_반찬!$C$2:$C$600,0),7),"") -> .5.21. | H18: 시금치나물 | I18: =IFERROR(INDEX([1]온라인_반찬!$C$2:$I$600,MATCH($H18,[1]온라인_반찬!$C$2:$C$600,0),7),"") -> .5.21. | J18: 도시락김 | K18: =IFERROR(INDEX([1]온라인_반찬!$C$2:$I$600,MATCH($J18,[1]온라인_반찬!$C$2:$C$600,0),7),"") -> .21.
B19: 배추김치 | C19: =IFERROR(INDEX([1]온라인_반찬!$C$2:$I$600,MATCH($B19,[1]온라인_반찬!$C$2:$C$600,0),7),"") -> .9.12. | D19: 깍두기 | E19: =IFERROR(INDEX([1]온라인_반찬!$C$2:$I$600,MATCH($D19,[1]온라인_반찬!$C$2:$C$600,0),7),"") -> .6.9. | F19: 백김치 | G19: =IFERROR(INDEX([1]온라인_반찬!$C$2:$I$600,MATCH($F19,[1]온라인_반찬!$C$2:$C$600,0),7),"") -> 0 | H19: 깍두기 | I19: =IFERROR(INDEX([1]온라인_반찬!$C$2:$I$600,MATCH($H19,[1]온라인_반찬!$C$2:$C$600,0),7),"") -> .6.9. | J19: 배추김치 | K19: =IFERROR(INDEX([1]온라인_반찬!$C$2:$I$600,MATCH($J19,[1]온라인_반찬!$C$2:$C$600,0),7),"") -> .9.12.
B20: 소고기무국 | C20: =IFERROR(INDEX([1]온라인_반찬!$C$2:$I$600,MATCH($B20,[1]온라인_반찬!$C$2:$C$600,0),7),"") -> .5.16. | D20: 황태미역국 | E20: =IFERROR(INDEX([1]온라인_반찬!$C$2:$I$600,MATCH($D20,[1]온라인_반찬!$C$2:$C$600,0),7),"") -> .5.9.21. | F20: 논우렁살된장찌개 | G20: =IFERROR(INDEX([1]온라인_반찬!$C$2:$I$600,MATCH($F20,[1]온라인_반찬!$C$2:$C$600,0),7),"") -> .5. | H20: 모둠어묵국 | I20: =IFERROR(INDEX([1]온라인_반찬!$C$2:$I$600,MATCH($H20,[1]온라인_반찬!$C$2:$C$600,0),7),"") -> .5.6. | J20: 맑은콩나물국 | K20: =IFERROR(INDEX([1]온라인_반찬!$C$2:$I$600,MATCH($J20,[1]온라인_반찬!$C$2:$C$600,0),7),"") -> .5.
C21: =IFERROR(INDEX([1]온라인_반찬!$C$2:$I$600,MATCH($B21,[1]온라인_반찬!$C$2:$C$600,0),7),"") | E21: =IFERROR(INDEX([1]온라인_반찬!$C$2:$I$600,MATCH($D21,[1]온라인_반찬!$C$2:$C$600,0),7),"") | G21: =IFERROR(INDEX([1]온라인_반찬!$C$2:$I$600,MATCH($F21,[1]온라인_반찬!$C$2:$C$600,0),7),"") | I21: =IFERROR(INDEX([1]온라인_반찬!$C$2:$I$600,MATCH($H21,[1]온라인_반찬!$C$2:$C$600,0),7),"") | K21: =IFERROR(INDEX([1]온라인_반찬!$C$2:$I$600,MATCH($J21,[1]온라인_반찬!$C$2:$C$600,0),7),"")
C22: =IFERROR(INDEX([1]온라인_반찬!$C$2:$I$600,MATCH($B22,[1]온라인_반찬!$C$2:$C$600,0),7),"") | G22: =IFERROR(INDEX([1]온라인_반찬!$C$2:$I$600,MATCH($F22,[1]온라인_반찬!$C$2:$C$600,0),7),"") | K22: =IFERROR(INDEX([1]온라인_반찬!$C$2:$I$600,MATCH($J22,[1]온라인_반찬!$C$2:$C$600,0),7),"")
A23: 날짜 | B23: 46188 | D23: 46189 | F23: 46190 | H23: 46191 | J23: 46192
A24: 주차 | B24: 메뉴 | C24: 알레르기표기 | D24: 메뉴 | E24: 알레르기표기 | F24: 메뉴 | G24: 알레르기표기 | H24: 메뉴 | I24: 알레르기표기 | J24: 메뉴 | K24: 알레르기표기
A25: 3주차 | B25: 친환경현미쌀밥 | C25: =IFERROR(INDEX([1]온라인_반찬!$C$2:$I$600,MATCH($B25,[1]온라인_반찬!$C$2:$C$600,0),7),"") -> 0 | D25: 친환경귀리쌀밥 | E25: =IFERROR(INDEX([1]온라인_반찬!$C$2:$I$600,MATCH($D25,[1]온라인_반찬!$C$2:$C$600,0),7),"") -> 0 | F25: 친환경찰흑미쌀밥 | G25: =IFERROR(INDEX([1]온라인_반찬!$C$2:$I$600,MATCH($F25,[1]온라인_반찬!$C$2:$C$600,0),7),"") -> 0 | H25: 흰쌀밥 | I25: =IFERROR(INDEX([1]온라인_반찬!$C$2:$I$600,MATCH($H25,[1]온라인_반찬!$C$2:$C$600,0),7),"") -> 0 | J25: 소고기볶음밥 | K25: =IFERROR(INDEX([1]온라인_반찬!$C$2:$I$600,MATCH($J25,[1]온라인_반찬!$C$2:$C$600,0),7),"") -> .1.5.16.21.
B26: 생선통살튀김 | C26: =IFERROR(INDEX([1]온라인_반찬!$C$2:$I$600,MATCH($B26,[1]온라인_반찬!$C$2:$C$600,0),7),"") -> 1.6. | D26: 돈채피망볶음 | E26: =IFERROR(INDEX([1]온라인_반찬!$C$2:$I$600,MATCH($D26,[1]온라인_반찬!$C$2:$C$600,0),7),"") -> .5.10.21. | F26: 깻잎닭갈비 | G26: =IFERROR(INDEX([1]온라인_반찬!$C$2:$I$600,MATCH($F26,[1]온라인_반찬!$C$2:$C$600,0),7),"") -> .5.6.15.21. | H26: 소고기표고볶음 | I26: =IFERROR(INDEX([1]온라인_반찬!$C$2:$I$600,MATCH($H26,[1]온라인_반찬!$C$2:$C$600,0),7),"") -> .5.16.21. | J26: 스파게티면 | K26: =IFERROR(INDEX([1]온라인_반찬!$C$2:$I$600,MATCH($J26,[1]온라인_반찬!$C$2:$C$600,0),7),"") -> .6.
B27: & 탕수소스 | C27: =IFERROR(INDEX([1]온라인_반찬!$C$2:$I$600,MATCH($B27,[1]온라인_반찬!$C$2:$C$600,0),7),"") -> .5. | D27: 구운어묵볶음 | E27: =IFERROR(INDEX([1]온라인_반찬!$C$2:$I$600,MATCH($D27,[1]온라인_반찬!$C$2:$C$600,0),7),"") -> .2.5.6.10.12.16.21. | F27: 오곡멸치볶음 | G27: =IFERROR(INDEX([1]온라인_반찬!$C$2:$I$600,MATCH($F27,[1]온라인_반찬!$C$2:$C$600,0),7),"") -> .5.6.21. | H27: 고구마전 | I27: =IFERROR(INDEX([1]온라인_반찬!$C$2:$I$600,MATCH($H27,[1]온라인_반찬!$C$2:$C$600,0),7),"") -> .1.6. | J27: & 미트소스 | K27: =IFERROR(INDEX([1]온라인_반찬!$C$2:$I$600,MATCH($J27,[1]온라인_반찬!$C$2:$C$600,0),7),"") -> .1.5.6.10.12.15.
B28: 햄감자채볶음 | C28: =IFERROR(INDEX([1]온라인_반찬!$C$2:$I$600,MATCH($B28,[1]온라인_반찬!$C$2:$C$600,0),7),"") -> .2.5.10.21. | D28: 콘샐러드 | E28: =IFERROR(INDEX([1]온라인_반찬!$C$2:$I$600,MATCH($D28,[1]온라인_반찬!$C$2:$C$600,0),7),"") -> .1.5.16. | F28: 소고기무조림 | G28: =IFERROR(INDEX([1]온라인_반찬!$C$2:$I$600,MATCH($F28,[1]온라인_반찬!$C$2:$C$600,0),7),"") -> .5.16.21. | H28: 김자반 | I28: =IFERROR(INDEX([1]온라인_반찬!$C$2:$I$600,MATCH($H28,[1]온라인_반찬!$C$2:$C$600,0),7),"") -> .5.21.22. | J28: 눈꽃치즈치킨 | K28: =IFERROR(INDEX([1]온라인_반찬!$C$2:$I$600,MATCH($J28,[1]온라인_반찬!$C$2:$C$600,0),7),"") -> .1.2.5.6.15.16.
B29: 참나물오이무침 | C29: =IFERROR(INDEX([1]온라인_반찬!$C$2:$I$600,MATCH($B29,[1]온라인_반찬!$C$2:$C$600,0),7),"") -> .5.21. | D29: 깍두기 | E29: =IFERROR(INDEX([1]온라인_반찬!$C$2:$I$600,MATCH($D29,[1]온라인_반찬!$C$2:$C$600,0),7),"") -> .6.9. | F29: 백김치 | G29: =IFERROR(INDEX([1]온라인_반찬!$C$2:$I$600,MATCH($F29,[1]온라인_반찬!$C$2:$C$600,0),7),"") -> 0 | H29: 깍두기 | I29: =IFERROR(INDEX([1]온라인_반찬!$C$2:$I$600,MATCH($H29,[1]온라인_반찬!$C$2:$C$600,0),7),"") -> .6.9. | J29: 캐릭터찐빵 | K29: =IFERROR(INDEX([1]온라인_반찬!$C$2:$I$600,MATCH($J29,[1]온라인_반찬!$C$2:$C$600,0),7),"") -> .5.17.
B30: 배추김치 | C30: =IFERROR(INDEX([1]온라인_반찬!$C$2:$I$600,MATCH($B30,[1]온라인_반찬!$C$2:$C$600,0),7),"") -> .9.12. | D30: 순두부탕 | E30: =IFERROR(INDEX([1]온라인_반찬!$C$2:$I$600,MATCH($D30,[1]온라인_반찬!$C$2:$C$600,0),7),"") -> .5. | F30: 감자된장국 | G30: =IFERROR(INDEX([1]온라인_반찬!$C$2:$I$600,MATCH($F30,[1]온라인_반찬!$C$2:$C$600,0),7),"") -> .5.6. | H30: 숙주닭곰탕 | I30: =IFERROR(INDEX([1]온라인_반찬!$C$2:$I$600,MATCH($H30,[1]온라인_반찬!$C$2:$C$600,0),7),"") -> .5.16. | J30: 수제피클 | K30: =IFERROR(INDEX([1]온라인_반찬!$C$2:$I$600,MATCH($J30,[1]온라인_반찬!$C$2:$C$600,0),7),"") -> 0
B31: 소고기미역국 | C31: =IFERROR(INDEX([1]온라인_반찬!$C$2:$I$600,MATCH($B31,[1]온라인_반찬!$C$2:$C$600,0),7),"") -> .5.9.16. | E31: =IFERROR(INDEX([1]온라인_반찬!$C$2:$I$600,MATCH($D31,[1]온라인_반찬!$C$2:$C$600,0),7),"") | G31: =IFERROR(INDEX([1]온라인_반찬!$C$2:$I$600,MATCH($F31,[1]온라인_반찬!$C$2:$C$600,0),7),"") | I31: =IFERROR(INDEX([1]온라인_반찬!$C$2:$I$600,MATCH($H31,[1]온라인_반찬!$C$2:$C$600,0),7),"") | J31: 딸기짜요 | K31: =IFERROR(INDEX([1]온라인_반찬!$C$2:$I$600,MATCH($J31,[1]온라인_반찬!$C$2:$C$600,0),7),"") -> .2.
C32: =IFERROR(INDEX([1]온라인_반찬!$C$2:$I$600,MATCH($B32,[1]온라인_반찬!$C$2:$C$600,0),7),"") | G32: =IFERROR(INDEX([1]온라인_반찬!$C$2:$I$600,MATCH($F32,[1]온라인_반찬!$C$2:$C$600,0),7),"") | K32: =IFERROR(INDEX([1]온라인_반찬!$C$2:$I$600,MATCH($J32,[1]온라인_반찬!$C$2:$C$600,0),7),"")
A33: 날짜 | B33: 46195 | D33: 46196 | F33: 46197 | H33: 46198 | J33: 46199
A34: 주차 | B34: 메뉴 | C34: 알레르기표기 | D34: 메뉴 | E34: 알레르기표기 | F34: 메뉴 | G34: 알레르기표기 | H34: 메뉴 | I34: 알레르기표기 | J34: 메뉴 | K34: 알레르기표기
A35: 4주차 | B35: 친환경현미쌀밥 | C35: =IFERROR(INDEX([1]온라인_반찬!$C$2:$I$600,MATCH($B35,[1]온라인_반찬!$C$2:$C$600,0),7),"") -> 0 | D35: 친환경귀리쌀밥 | E35: =IFERROR(INDEX([1]온라인_반찬!$C$2:$I$600,MATCH($D35,[1]온라인_반찬!$C$2:$C$600,0),7),"") -> 0 | F35: 친환경찰흑미쌀밥 | G35: =IFERROR(INDEX([1]온라인_반찬!$C$2:$I$600,MATCH($F35,[1]온라인_반찬!$C$2:$C$600,0),7),"") -> 0 | H35: 흰쌀밥 | I35: =IFERROR(INDEX([1]온라인_반찬!$C$2:$I$600,MATCH($H35,[1]온라인_반찬!$C$2:$C$600,0),7),"") -> 0 | J35: 친환경찰보리쌀밥 | K35: =IFERROR(INDEX([1]온라인_반찬!$C$2:$I$600,MATCH($J35,[1]온라인_반찬!$C$2:$C$600,0),7),"") -> 0
B36: 소고기장조림 | C36: =IFERROR(INDEX([1]온라인_반찬!$C$2:$I$600,MATCH($B36,[1]온라인_반찬!$C$2:$C$600,0),7),"") -> .1.5.16.21. | D36: 닭안심카레조림 | E36: =IFERROR(INDEX([1]온라인_반찬!$C$2:$I$600,MATCH($D36,[1]온라인_반찬!$C$2:$C$600,0),7),"") -> .2.5.6.12.15.16.18. | F36: 미소불고기 | G36: =IFERROR(INDEX([1]온라인_반찬!$C$2:$I$600,MATCH($F36,[1]온라인_반찬!$C$2:$C$600,0),7),"") -> .5.16.21. | H36: 한입새우튀김 | I36: =IFERROR(INDEX([1]온라인_반찬!$C$2:$I$600,MATCH($H36,[1]온라인_반찬!$C$2:$C$600,0),7),"") -> .5.6.9. | J36: 하와이안폭찹 | K36: =IFERROR(INDEX([1]온라인_반찬!$C$2:$I$600,MATCH($J36,[1]온라인_반찬!$C$2:$C$600,0),7),"") -> .5.10.12.13.19.21.
B37: 동그랑땡 | C37: =IFERROR(INDEX([1]온라인_반찬!$C$2:$I$600,MATCH($B37,[1]온라인_반찬!$C$2:$C$600,0),7),"") -> .1.2.5.6.10.12.16. | D37: 베이컨스크램블에그 | E37: =IFERROR(INDEX([1]온라인_반찬!$C$2:$I$600,MATCH($D37,[1]온라인_반찬!$C$2:$C$600,0),7),"") -> .1.2.5.10.18. | F37: 김말이 | G37: =IFERROR(INDEX([1]온라인_반찬!$C$2:$I$600,MATCH($F37,[1]온라인_반찬!$C$2:$C$600,0),7),"") -> .5.6.16. | H37: & 레몬크림소스 | I37: =IFERROR(INDEX([1]온라인_반찬!$C$2:$I$600,MATCH($H37,[1]온라인_반찬!$C$2:$C$600,0),7),"") -> .1.2.5.6.9. | J37: 명란크림숏파스타 | K37: =IFERROR(INDEX([1]온라인_반찬!$C$2:$I$600,MATCH($J37,[1]온라인_반찬!$C$2:$C$600,0),7),"") -> .1.2.5.6.15.16.
B38: 숙주나물 | C38: =IFERROR(INDEX([1]온라인_반찬!$C$2:$I$600,MATCH($B38,[1]온라인_반찬!$C$2:$C$600,0),7),"") -> .5.21. | D38: 애호박버섯볶음 | E38: =IFERROR(INDEX([1]온라인_반찬!$C$2:$I$600,MATCH($D38,[1]온라인_반찬!$C$2:$C$600,0),7),"") -> .5.21. | F38: 건새우마늘쫑볶음 | G38: =IFERROR(INDEX([1]온라인_반찬!$C$2:$I$600,MATCH($F38,[1]온라인_반찬!$C$2:$C$600,0),7),"") -> .5.9.21. | H38: 케찹떡볶이 | I38: =IFERROR(INDEX([1]온라인_반찬!$C$2:$I$600,MATCH($H38,[1]온라인_반찬!$C$2:$C$600,0),7),"") -> .1.5.12. | J38: 도시락김 | K38: =IFERROR(INDEX([1]온라인_반찬!$C$2:$I$600,MATCH($J38,[1]온라인_반찬!$C$2:$C$600,0),7),"") -> .21.
B39: 배추김치 | C39: =IFERROR(INDEX([1]온라인_반찬!$C$2:$I$600,MATCH($B39,[1]온라인_반찬!$C$2:$C$600,0),7),"") -> .9.12. | D39: 깍두기 | E39: =IFERROR(INDEX([1]온라인_반찬!$C$2:$I$600,MATCH($D39,[1]온라인_반찬!$C$2:$C$600,0),7),"") -> .6.9. | F39: 백김치 | G39: =IFERROR(INDEX([1]온라인_반찬!$C$2:$I$600,MATCH($F39,[1]온라인_반찬!$C$2:$C$600,0),7),"") -> 0 | H39: 콥샐러드 | I39: =IFERROR(INDEX([1]온라인_반찬!$C$2:$I$600,MATCH($H39,[1]온라인_반찬!$C$2:$C$600,0),7),"") -> .1.2.5.10.12.19. | J39: 배추김치 | K39: =IFERROR(INDEX([1]온라인_반찬!$C$2:$I$600,MATCH($J39,[1]온라인_반찬!$C$2:$C$600,0),7),"") -> .9.12.
B40: 유부무국 | C40: =IFERROR(INDEX([1]온라인_반찬!$C$2:$I$600,MATCH($B40,[1]온라인_반찬!$C$2:$C$600,0),7),"") -> .5. | D40: 어묵양배추국 | E40: =IFERROR(INDEX([1]온라인_반찬!$C$2:$I$600,MATCH($D40,[1]온라인_반찬!$C$2:$C$600,0),7),"") -> .5. | F40: 채소계란국 | G40: =IFERROR(INDEX([1]온라인_반찬!$C$2:$I$600,MATCH($F40,[1]온라인_반찬!$C$2:$C$600,0),7),"") -> .1.5. | H40: 깍두기 | I40: =IFERROR(INDEX([1]온라인_반찬!$C$2:$I$600,MATCH($H40,[1]온라인_반찬!$C$2:$C$600,0),7),"") -> .6.9. | J40: 호박잎된장찌개 | K40: =IFERROR(INDEX([1]온라인_반찬!$C$2:$I$600,MATCH($J40,[1]온라인_반찬!$C$2:$C$600,0),7),"") -> .5.
C41: =IFERROR(INDEX([1]온라인_반찬!$C$2:$I$600,MATCH($B41,[1]온라인_반찬!$C$2:$C$600,0),7),"") | E41: =IFERROR(INDEX([1]온라인_반찬!$C$2:$I$600,MATCH($D41,[1]온라인_반찬!$C$2:$C$600,0),7),"") | G41: =IFERROR(INDEX([1]온라인_반찬!$C$2:$I$600,MATCH($F41,[1]온라인_반찬!$C$2:$C$600,0),7),"") | H41: 설렁탕 | I41: =IFERROR(INDEX([1]온라인_반찬!$C$2:$I$600,MATCH($H41,[1]온라인_반찬!$C$2:$C$600,0),7),"") -> .5.16. | K41: =IFERROR(INDEX([1]온라인_반찬!$C$2:$I$600,MATCH($J41,[1]온라인_반찬!$C$2:$C$600,0),7),"")
...

Sheet 식단표
A1: 06월 식단표
A2: 요일 | B2: 월 | C2: 화 | D2: 수 | E2: 목 | F2: 금
A3: 날짜 | B3: 46174 | C3: 46175 | D3: 46176 | E3: 46177 | F3: 46178
A4: 1주차 | B4: 친환경현미쌀밥 | C4: 친환경귀리쌀밥 | D4: ♣전국지방선거일♣ | E4: 흰쌀밥 | F4: 친환경찰보리쌀밥
B5: 통등심돈까스(소스) | C5: 닭살데리야끼조림 | E5: 돈채춘장볶음 | F5: 소고기낙지전골
B6: 불고기떡볶이 | C6: 어묵채구이 | E6: 꼬물이만두 | F6: 메추리알조림
B7: 양배추당근라페 | C7: 청포묵무침 | E7: 참치깍두기볶음 | F7: 오이미역초무침
B8: 배추김치 | C8: 깍두기 | E8: 백김치 | F8: 배추김치
B9: 팽이미소국 | C9: 소고기장국 | E9: 순살동태국 | F9: 시금치된장국
A11: 날짜 | B11: 46181 | C11: 46182 | D11: 46183 | E11: 46184 | F11: 46185
A12: 2주차 | B12: 친환경현미쌀밥 | C12: 친환경귀리쌀밥 | D12: 친환경찰흑미쌀밥 | E12: 흰쌀밥 | F12: 친환경찰보리쌀밥
B13: 코코넛커리소스 | C13: 돈갈비양념구이 | D13: 소고기양배추볶음 | E13: 토마토닭볶음탕 | F13: 불고기잡채
B14: 새우튀김 | C14: 채소계란찜 | D14: 소세지채소볶음 | E14: 꼬마돈까스 | F14: 어간장두부조림
B15: 보코치니샐러드 | C15: 삼색콩나물무침 | D15: 검은콩멸치조림 | E15: 시금치나물 | F15: 도시락김
B16: 배추김치 | C16: 깍두기 | D16: 백김치 | E16: 깍두기 | F16: 배추김치
B17: 소고기무국 | C17: 황태미역국 | D17: 논우렁살된장찌개 | E17: 모둠어묵국 | F17: 맑은콩나물국
A19: 날짜 | B19: 46188 | C19: 46189 | D19: 46190 | E19: 46191 | F19: 46192
A20: 3주차 | B20: 친환경현미쌀밥 | C20: 친환경귀리쌀밥 | D20: 친환경찰흑미쌀밥 | E20: 흰쌀밥 | F20: 소고기볶음밥
B21: 생선통살탕수(소스) | C21: 돈채피망볶음 | D21: 깻잎닭갈비 | E21: 소고기표고볶음 | F21: 미트스파게티
B22: 햄감자채볶음 | C22: 구운어묵볶음 | D22: 오곡멸치볶음 | E22: 고구마전 | F22: 눈꽃치즈치킨
B23: 참나물오이무침 | C23: 콘샐러드 | D23: 소고기무조림 | E23: 김자반 | F23: 캐릭터찐빵
B24: 배추김치 | C24: 깍두기 | D24: 백김치 | E24: 깍두기 | F24: 수제피클
B25: 소고기미역국 | C25: 순두부탕 | D25: 감자된장국 | E25: 숙주닭곰탕 | F25: 딸기짜요
A27: 날짜 | B27: 46195 | C27: 46196 | D27: 46197 | E27: 46198 | F27: 46199
A28: 4주차 | B28: 친환경현미쌀밥 | C28: 친환경귀리쌀밥 | D28: 친환경찰흑미쌀밥 | E28: 흰쌀밥 | F28: 친환경찰보리쌀밥
B29: 소고기장조림 | C29: 닭안심카레조림 | D29: 미소불고기 | E29: 한입새우튀김(소스) | F29: 하와이안폭찹
B30: 동그랑땡 | C30: 베이컨스크램블에그 | D30: 김말이 | E30: 케찹떡볶이 | F30: 명란크림숏파스타
B31: 숙주나물 | C31: 애호박버섯볶음 | D31: 건새우마늘쫑볶음 | E31: 콥샐러드 | F31: 도시락김
B32: 배추김치 | C32: 깍두기 | D32: 백김치 | E32: 깍두기 | F32: 배추김치
B33: 유부무국 | C33: 어묵양배추국 | D33: 채소계란국 | E33: 설렁탕 | F33: 호박잎된장찌개
A35: 날짜 | B35: 46202 | C35: 46203
A36: 5주차 | B36: 친환경현미쌀밥 | C36: 친환경귀리쌀밥
B37: 허니돈육강정 | C37: 안동찜닭
B38: 참치마요 | C38: 채소계란전
B39: 콩나물냉채 | C39: 그린샐러드
B40: 배추김치 | C40: 깍두기
B41: 맑은미역국 | C41: 소고기샤브국
A43: 원산지 안내 쌀(국내산),현미(국내산. 친환경), 찰흑미(국내산. 친환경), 찰보리(국산. 친환경), 강황(국내산. 무농약) 소고기(호주산), 돈육(국내산), 목살(폭찹스테이크:미국산), 닭고기(국내산), 닭정육(닭다리살:국내산, 브라질산), 훈제오리(무항생제.국내산) 배추김치(배추:국내산,고춧가루:국내산), 깍두기(무:국내산,고춧가루:국내산), 오징어(원양산), 낙지(베트남산,이도네시아산), 바지락살(중국산), 아귀(국내산), 명태(러시아산), 칵테일새우(베트남산), 솔방울오징어(중국산), 갑오징어(베트남산) 채소류(국내산), 국용채소류(국내산/단,기후변화 등 이슈로 국산 수급이 어려울경우:중국산.베트남산) *위의 메뉴는 재료 수급 사정에 따라 변경 될 수 있습니다 *알레르기 정보 - 1.난류 2.우유 3.메밀 4.견과류(땅콩.아몬드.잣.코코넛등) 5.대두 6.밀 7.고등어 8.게 9.새우 10.돼지고기 11.복숭아 12.토마토 13.아황산류 14.호두 15.닭고기 16.쇠고기 17.오징어 18.조개류(굴.전복.홍합 포함) 19.파인애플 20.키위 21.참깨 22.들깨 영양사 : 천은혜
